Workbook

Sheet Capa Tabela
A1: 2024/5
G3: 14 de Agosto 2024
A4: ACABAMENTOS:
A5: VIDROS:
A7: * Para colocar VIDRO EXTRA CLEAR, ESPELHO PRATA OU ESPELHO BRONZE, acrescentar ao móvel valor descrito na ultima página. * O vidro utilizado nos móveis é comum, pode haver diferença de tonalidade;
A8: * Vidros comum 4mm e extra clear 4mm medida maxima de 3,20x1,30 ou redondos e quadrados de 2,00x2,00
A9: * Vidros comum 6mm medida maxima de 3,59x1,50 ou redondos e quadrados de 2,00x2,00(sob consulta) esta espessura é mais esverdeado que o vidro comum 4mm
A10: OBS: A Nogueira o Carvalho e o Louro Freijó somente são fornecidos em laminados, as bases de madeira maciça serão produzidas em madeira tingida em cor semelhante.
A11: OBS: Os metais presentes nas peças podem ser feitos em qualquer cor de LACA PADRÃO BRILHO OU FOSCO (Informar no pedido)

Sheet Cores Capa
A1: LACAS LISAS BRAZIL | C1: LACAS METALIZADAS BRAZIL | E1: MADEIRAS TINGIDAS | G1: CARVALHOS TINGIDOS | I1: OUTRAS CORES
A2: Areia H109 Brilho / Fosco Branco Brilho / Fosco Cinza Claro H155 Brilho / Fosco Crômo Fosco Fendi N109 Brilho / Fosco Preto Fosco LACA CONCRETO BRAZIL Concreto (Somente s/ Vidro) | C2: Bronze Chumbo N109 Ônix METAIS Aço Cortein New Golden Preto Fosco Ônix Metalizado N109 Metalizado | E2: Imbuia Clara LÂMINAS Carvalho Louro Freijó Nogueira Pau Ferro | G2: Carvalho Claro Carvalho Ebanizado Carvalho Lavado Carvalho Natural CARVALHOS LAQUEADO Albanizado Cinza Claro (H155 Fosco) CARVALHOS METALIZADOS N109 Metalizado Ônix Metalizado | I2: Lacas Especiais Sayerlack
A4: OBS: Lacas especiais Sayerlack Brilho ou Fosca acrescentar 15% sobre a terceira coluna da tabela, se for laca especial metalizada ou perolizada consultar a empresa.

Sheet Garantia

Sheet Mark Up 
A1: Local onde faz a multiplicação nas colunas da tabelas, se precisar dobrar o valor mudar o numero 1 para 2, se precisar triplicar o valor trocar numero 1 para 3 e por assim adiante.
A2: MARK UP | C2: 4.62

Sheet Origem 
A1: 9464-1 | B1: Aparador Alabama (canto garrafa) | C1: 1,40 x 0,45 x 0,76 | D1: 1795 | E1: 1847 | F1: 2025 | G1: X | H1: 0
A2: 9464-2 | B2: Aparador Alabama (canto garrafa) | C2: 1,60 x 0,45 x 0,76 | D2: 1842 | E2: 1916 | F2: 2107 | G2: X | H2: 0
A3: 9464-3 | B3: Aparador Alabama (canto garrafa) | C3: 1,80 x 0,45 x 0,76 | D3: 2017 | E3: 2117 | F3: 2366 | G3: X | H3: 0
A4: 9464-4 | B4: Aparador Alabama (canto garrafa) | C4: 2,00 x 0,45 x 0,76 | D4: 2133 | E4: 2221 | F4: 2433 | G4: X | H4: 0
A5: 9464-5 | B5: Aparador Alabama (canto garrafa) | C5: 2,20 x 0,45 x 0,76 | D5: 2243 | E5: 2342 | F5: 2557 | G5: X | H5: 0
A6: 4064-2 | B6: Aparador Aurora (3 gavetas marchetadas); pés metal | C6: 1,66 x 0,45 x 0,80 | D6: 3206 | E6: 3833 | F6: 4251 | G6: 4476 | H6: 0
A7: 4064-3 | B7: Aparador Aurora (3 gaveta marchetadas) pés metal | C7: 1,86 x 0,45 x 0,80 | D7: 3526 | E7: 3992 | F7: 4555 | G7: 4813 | H7: 0
A8: 4064-4 | B8: Aparador Aurora (3 gavetas marchetadas) pés metal | C8: 2,06 x 0,45 x 0,80 | D8: 3673 | E8: 4311 | F8: 5150 | G8: 5260 | H8: 0
A9: 4065-2 | B9: Aparador Aurora (c/ bandeja), pés metal | C9: 1,66 x 0,45 x 0,76 | D9: 2494 | E9: 2873 | F9: 3204 | G9: 3413 | H9: 0
A10: 4065-3 | B10: Aparador Aurora (c/ bandeja), pés metal | C10: 1,86 x 0,45 x 0,76 | D10: 2718 | E10: 3083 | F10: 3519 | G10: 3760 | H10: 0
A11: 4065-4 | B11: Aparador Aurora (c/ bandeja), pés metal | C11: 2,06 x 0,45 x 0,76 | D11: 2966 | E11: 3377 | F11: 3866 | G11: 4136 | H11: 0
A12: 10984-1 | B12: Aparador Baden ,tp e bandeja canto garrafa, pés metal (se laca brilho somente c/ VD) | C12: 1,40 x 0,39 x 0,75 | D12: 2067 | E12: 2273 | F12: 2583 | G12: 2726 | H12: 0
A13: 10984-2 | B13: Aparador Baden ,tp e bandeja canto garrafa, pés metal (se laca brilho somente c/ VD) | C13: 1,60 x 0,39 x 0,75 | D13: 2219 | E13: 2356 | F13: 2708 | G13: 2888 | H13: 0
A14: 10984-3 | B14: Aparador Baden ,tp e bandeja canto garrafa, pés metal (se laca brilho somente c/ VD) | C14: 1,80 x 0,39 x 0,75 | D14: 2300 | E14: 2515 | F14: 2962 | G14: 3118 | H14: 0
A15: 10984-4 | B15: Aparador Baden ,tp e bandeja canto garrafa, pés metal (se laca brilho somente c/ VD) | C15: 2,00 x 0,39 x 0,75 | D15: 2391 | E15: 2695 | F15: 3148 | G15: 3370 | H15: 0
A16: 11620-1 | B16: Aparador Bari TP.(Garrafal) | C16: 1,40 x 0,45 x 0,76 | D16: 1844 | E16: 1887 | F16: 1979 | G16: X | H16: 0
A17: 11620-2 | B17: Aparador Bari TP.(Garrafal) | C17: 1,60 x 0,45 x 0,76 | D17: 1953 | E17: 2015 | F17: 2221 | G17: X | H17: 0
A18: 11620-3 | B18: Aparador Bari TP.(Garrafal) | C18: 1,80 x 0,45 x 0,76 | D18: 2128 | E18: 2188 | F18: 2406 | G18: X | H18: 0
A19: 11640-2 | B19: Aparador Bogotá ,TP.Canto Garrafa; C/ MARCHETARIA | C19: 1,60 x 0,45 x 0,76 | D19: X | E19: 2139 | F19: 2364 | G19: 2722 | H19: 0
A20: 11640-3 | B20: Aparador Bogotá ,TP.Canto Garrafa; C/ MARCHETARIA | C20: 1,80 x 0,45 x 0,76 | D20: X | E20: 2244 | F20: 2479 | G20: 2937 | H20: 0
A21: 11640-4 | B21: Aparador Bogotá ,TP.Canto Garrafa; C/ MARCHETARIA | C21: 2,00 x 0,45 x 0,76 | D21: X | E21: 2333 | F21: 2581 | G21: 3061 | H21: 0
A22: 11641-2 | B22: Aparador Bogotá ,TP.Canto Garrafa; S/ MARCHETARIA | C22: 1,60 x 0,45 x 0,76 | D22: 1822 | E22: 2035 | F22: 2226 | G22: 2636 | H22: 0
A23: 11641-3 | B23: Aparador Bogotá ,TP.Canto Garrafa; S/ MARCHETARIA | C23: 1,80 x 0,45 x 0,76 | D23: 1933 | E23: 2129 | F23: 2335 | G23: 2767 | H23: 0
A24: 11641-4 | B24: Aparador Bogotá ,TP.Canto Garrafa; S/ MARCHETARIA | C24: 2,00 x 0,45 x 0,76 | D24: 2020 | E24: 2210 | F24: 2421 | G24: 2875 | H24: 0
A25: 9554-1 | B25: Aparador Copenhague (tmp oblongo) (se laca brilho somente c/ VD) | C25: 1,41 x 0,46 x 0,76 | D25: 2540 | E25: 2913 | F25: 3285 | G25: 3595 | H25: 0
A26: 9554-2 | B26: Aparador Copenhague (tmp oblongo) (se laca brilho somente c/ VD) | C26: 1,61 x 0,46 x 0,76 | D26: 2719 | E26: 3237 | F26: 3445 | G26: 3799 | H26: 0
A27: 9554-3 | B27: Aparador Copenhague (tmp oblongo) (se laca brilho somente c/ VD) | C27: 1,81 x 0,46 x 0,76 | D27: 2873 | E27: 3407 | F27: 3621 | G27: 3987 | H27: 0
A28: 4594-2 | B28: Aparador Ellos (canto garrafa), pés metal | C28: 1,35 x 0,35 x 0,76 | D28: 1642 | E28: 1780 | F28: 1980 | G28: 2028 | H28: 0
A29: 4594-3 | B29: Aparador Ellos (canto garrafa), pés metal | C29: 1,60 x 0,35 x 0,76 | D29: 1805 | E29: 1915 | F29: 2146 | G29: 2228 | H29: 0
A30: 4594-4 | B30: Aparador Ellos (canto garrafa), pés metal | C30: 1,80 x 0,35 x 0,76 | D30: 2067 | E30: 2177 | F30: 2384 | G30: 2488 | H30: 0
A31: 11034-1 | B31: Aparador Granada (tp oblongo), pés mad. (se laca brilho somente c/ VD) | C31: 1,46 x 0,45 x 0,76 | D31: 1518 | E31: 1587 | F31: 1914 | G31: 2021 | H31: 0
A32: 11034-2 | B32: Aparador Granada (tp oblongo), pés mad. (se laca brilho somente c/ VD) | C32: 1,66 x 0,45 x 0,76 | D32: 1667 | E32: 1716 | F32: 2037 | G32: 2171 | H32: 0
A33: 11034-3 | B33: Aparador Granada (tp oblongo), pés mad. (se laca brilho somente c/ VD) | C33: 1,86 x 0,45 x 0,76 | D33: 1750 | E33: 1798 | F33: 2152 | G33: 2315 | H33: 0
... A38: 10484-4 | B38: Aparador Madagascar (tp oblongo), pés metal; (com tampo sobreposto) | C38: 1,96 x 0,39 x 0,76 | D38: 2107 | E38: 2307 | F38: 2583 | G38: 2727 | H38: 0
A39: 11294-1 | B39: Aparador Maracatu, c/ 2 gavetas (se laca brilho somente c/ VD) | C39: 1,51 x 0,46 x 0,78 | D39: 2784 | E39: 3015 | F39: 3689 | G39: X | H39: 0
A40: 11294-2 | B40: Aparador Maracatu, c/ 2 gavetas (se laca brilho somente c/ VD) | C40: 1,71 x 0,46 x 0,78 | D40: 3092 | E40: 3331 | F40: 4061 | G40: X | H40: 0
A41: 11294-3 | B41: Aparador Maracatu, c/ 2 gavetas (se laca brilho somente c/ VD) | C41: 1,91 x 0,46 x 0,78 | D41: 3465 | E41: 3699 | F41: 4506 | G41: X | H41: 0
A42: 11294-4 | B42: Aparador Maracatu, c/ 2 gavetas (se laca brilho somente c/ VD) | C42: 2,11 x 0,46 x 0,78 | D42: 3615 | E42: 3912 | F42: 4846 | G42: X | H42: 0
A43: 11740-15 | B43: Aparador Maro, Pés metal,TP Superior c/ VIDRO INCOLOR (8mm) | C43: 2,10 x 0,45 x 0,76 | D43: 3257 | E43: 3360 | F43: 3683 | G43: 4077 | H43: 0
A44: 11740-16 | B44: Aparador Maro, Pés metal,TP Superior c/ VIDRO INCOLOR (8mm) | C44: 2,40 x 0,45 x 0,76 | D44: 3675 | E44: 3821 | F44: 4206 | G44: 4683 | H44: 0
...

Sheet Aparadores
C1: APARADORES | I1: AMBIENTADAS
A2: COLEÇÃO | B2: REF | C2: DESCRIÇÃO | D2: COMP X PROF X ALT | E2: Em caso de cores diferentes Base ou Tampo, utilizar preço de maior valor
E3: COLUNA 1 | F3: COLUNA 2 | G3: COLUNA 3 | H3: COLUNA 4
E4: LACA LISA BRAZIL ( COM OU SEM VIDRO PINTADO) | F4: - CARVALHO CLARO - CARVALHO NATURAL - CARVALHO LAVADO - CARV. EBANIZADO - IMBUIA CLARA * ACRESCENTAR 12% SE COM VIDRO PINTADO | G4: - NOGUEIRA - NOGUEIRA NATURAL - LOURO FREIJÓ - LOURO FREIJÓ NATURAL - LACA METALIZADA BRAZIL - CARV. ÔNIX METALIZADO - CARV. N109 METALIZADO - CARV. ALBANIZADO - CARV. H155 FOSCO - CONCRETO (SOMENTE SEM VIDRO) | H4: - PAU FERRO
E5: OBS. O ACABAMENTO DO METAL NÃO INFLUENCIARÁ NO VALOR DO APARADOR
A6: ALABAMA | B6: 9464-1 | C6: Aparador Alabama (canto garrafa) | D6: 1,40 x 0,45 x 0,76 | E6: =IFERROR(((VLOOKUP(B6,'Origem '!$A$1:$H$1655,4,0)*'Mark Up '!$C$2)),"X") -> 8292.9 | F6: =IFERROR(((VLOOKUP(B6,'Origem '!$A$1:$E$1655,5,0)*'Mark Up '!$C$2)),"X") -> 8533.14 | G6: =IFERROR(((VLOOKUP(B6,'Origem '!$A$1:$F$1655,6,0)*'Mark Up '!$C$2)),"X") -> 9355.5 | H6: =IFERROR(((VLOOKUP(B6,'Origem '!$A$1:$H$1655,7,0)*'Mark Up '!$C$2)),"X") -> X
B7: 9464-2 | C7: Aparador Alabama (canto garrafa) | D7: 1,60 x 0,45 x 0,76 | E7: =IFERROR(((VLOOKUP(B7,'Origem '!$A$1:$H$1655,4,0)*'Mark Up '!$C$2)),"X") -> 8510.04 | F7: =IFERROR(((VLOOKUP(B7,'Origem '!$A$1:$E$1655,5,0)*'Mark Up '!$C$2)),"X") -> 8851.92 | G7: =IFERROR(((VLOOKUP(B7,'Origem '!$A$1:$F$1655,6,0)*'Mark Up '!$C$2)),"X") -> 9734.34 | H7: =IFERROR(((VLOOKUP(B7,'Origem '!$A$1:$H$1655,7,0)*'Mark Up '!$C$2)),"X") -> X
B8: 9464-3 | C8: Aparador Alabama (canto garrafa) | D8: 1,80 x 0,45 x 0,76 | E8: =IFERROR(((VLOOKUP(B8,'Origem '!$A$1:$H$1655,4,0)*'Mark Up '!$C$2)),"X") -> 9318.54 | F8: =IFERROR(((VLOOKUP(B8,'Origem '!$A$1:$E$1655,5,0)*'Mark Up '!$C$2)),"X") -> 9780.54 | G8: =IFERROR(((VLOOKUP(B8,'Origem '!$A$1:$F$1655,6,0)*'Mark Up '!$C$2)),"X") -> 10930.92 | H8: =IFERROR(((VLOOKUP(B8,'Origem '!$A$1:$H$1655,7,0)*'Mark Up '!$C$2)),"X") -> X
B9: 9464-4 | C9: Aparador Alabama (canto garrafa) | D9: 2,00 x 0,45 x 0,76 | E9: =IFERROR(((VLOOKUP(B9,'Origem '!$A$1:$H$1655,4,0)*'Mark Up '!$C$2)),"X") -> 9854.46 | F9: =IFERROR(((VLOOKUP(B9,'Origem '!$A$1:$E$1655,5,0)*'Mark Up '!$C$2)),"X") -> 10261.02 | G9: =IFERROR(((VLOOKUP(B9,'Origem '!$A$1:$F$1655,6,0)*'Mark Up '!$C$2)),"X") -> 11240.46 | H9: =IFERROR(((VLOOKUP(B9,'Origem '!$A$1:$H$1655,7,0)*'Mark Up '!$C$2)),"X") -> X
B10: 9464-5 | C10: Aparador Alabama (canto garrafa) | D10: 2,20 x 0,45 x 0,76 | E10: =IFERROR(((VLOOKUP(B10,'Origem '!$A$1:$H$1655,4,0)*'Mark Up '!$C$2)),"X") -> 10362.66 | F10: =IFERROR(((VLOOKUP(B10,'Origem '!$A$1:$E$1655,5,0)*'Mark Up '!$C$2)),"X") -> 10820.04 | G10: =IFERROR(((VLOOKUP(B10,'Origem '!$A$1:$F$1655,6,0)*'Mark Up '!$C$2)),"X") -> 11813.34 | H10: =IFERROR(((VLOOKUP(B10,'Origem '!$A$1:$H$1655,7,0)*'Mark Up '!$C$2)),"X") -> X
A11: AURORA | B11: 4064-2 | C11: Aparador Aurora (3 gavetas marchetadas); pés metal | D11: 1,66 x 0,45 x 0,80 | E11: =IFERROR(((VLOOKUP(B11,'Origem '!$A$1:$H$1655,4,0)*'Mark Up '!$C$2)),"X") -> 14811.72 | F11: =IFERROR(((VLOOKUP(B11,'Origem '!$A$1:$E$1655,5,0)*'Mark Up '!$C$2)),"X") -> 17708.46 | G11: =IFERROR(((VLOOKUP(B11,'Origem '!$A$1:$F$1655,6,0)*'Mark Up '!$C$2)),"X") -> 19639.62 | H11: =IFERROR(((VLOOKUP(B11,'Origem '!$A$1:$H$1655,7,0)*'Mark Up '!$C$2)),"X") -> 20679.12
B12: 4064-3 | C12: Aparador Aurora (3 gaveta marchetadas) pés metal | D12: 1,86 x 0,45 x 0,80 | E12: =IFERROR(((VLOOKUP(B12,'Origem '!$A$1:$H$1655,4,0)*'Mark Up '!$C$2)),"X") -> 16290.12 | F12: =IFERROR(((VLOOKUP(B12,'Origem '!$A$1:$E$1655,5,0)*'Mark Up '!$C$2)),"X") -> 18443.04 | G12: =IFERROR(((VLOOKUP(B12,'Origem '!$A$1:$F$1655,6,0)*'Mark Up '!$C$2)),"X") -> 21044.1 | H12: =IFERROR(((VLOOKUP(B12,'Origem '!$A$1:$H$1655,7,0)*'Mark Up '!$C$2)),"X") -> 22236.06
B13: 4064-4 | C13: Aparador Aurora (3 gavetas marchetadas) pés metal | D13: 2,06 x 0,45 x 0,80 | E13: =IFERROR(((VLOOKUP(B13,'Origem '!$A$1:$H$1655,4,0)*'Mark Up '!$C$2)),"X") -> 16969.26 | F13: =IFERROR(((VLOOKUP(B13,'Origem '!$A$1:$E$1655,5,0)*'Mark Up '!$C$2)),"X") -> 19916.82 | G13: =IFERROR(((VLOOKUP(B13,'Origem '!$A$1:$F$1655,6,0)*'Mark Up '!$C$2)),"X") -> 23793 | H13: =IFERROR(((VLOOKUP(B13,'Origem '!$A$1:$H$1655,7,0)*'Mark Up '!$C$2)),"X") -> 24301.2
B14: 4065-2 | C14: Aparador Aurora (c/ bandeja), pés metal | D14: 1,66 x 0,45 x 0,76 | E14: =IFERROR(((VLOOKUP(B14,'Origem '!$A$1:$H$1655,4,0)*'Mark Up '!$C$2)),"X") -> 11522.28 | F14: =IFERROR(((VLOOKUP(B14,'Origem '!$A$1:$E$1655,5,0)*'Mark Up '!$C$2)),"X") -> 13273.26 | G14: =IFERROR(((VLOOKUP(B14,'Origem '!$A$1:$F$1655,6,0)*'Mark Up '!$C$2)),"X") -> 14802.48 | H14: =IFERROR(((VLOOKUP(B14,'Origem '!$A$1:$H$1655,7,0)*'Mark Up '!$C$2)),"X") -> 15768.06
B15: 4065-3 | C15: Aparador Aurora (c/ bandeja), pés metal | D15: 1,86 x 0,45 x 0,76 | E15: =IFERROR(((VLOOKUP(B15,'Origem '!$A$1:$H$1655,4,0)*'Mark Up '!$C$2)),"X") -> 12557.16 | F15: =IFERROR(((VLOOKUP(B15,'Origem '!$A$1:$E$1655,5,0)*'Mark Up '!$C$2)),"X") -> 14243.46 | G15: =IFERROR(((VLOOKUP(B15,'Origem '!$A$1:$F$1655,6,0)*'Mark Up '!$C$2)),"X") -> 16257.78 | H15: =IFERROR(((VLOOKUP(B15,'Origem '!$A$1:$H$1655,7,0)*'Mark Up '!$C$2)),"X") -> 17371.2
B16: 4065-4 | C16: Aparador Aurora (c/ bandeja), pés metal | D16: 2,06 x 0,45 x 0,76 | E16: =IFERROR(((VLOOKUP(B16,'Origem '!$A$1:$H$1655,4,0)*'Mark Up '!$C$2)),"X") -> 13702.92 | F16: =IFERROR(((VLOOKUP(B16,'Origem '!$A$1:$E$1655,5,0)*'Mark Up '!$C$2)),"X") -> 15601.74 | G16: =IFERROR(((VLOOKUP(B16,'Origem '!$A$1:$F$1655,6,0)*'Mark Up '!$C$2)),"X") -> 17860.92 | H16: =IFERROR(((VLOOKUP(B16,'Origem '!$A$1:$H$1655,7,0)*'Mark Up '!$C$2)),"X") -> 19108.32
A17: BADEN | B17: 10984-1 | C17: Aparador Baden ,tp e bandeja canto garrafa, pés metal (se laca brilho somente c/ VD) | D17: 1,40 x 0,39 x 0,76 | E17: =IFERROR(((VLOOKUP(B17,'Origem '!$A$1:$H$1655,4,0)*'Mark Up '!$C$2)),"X") -> 9549.54 | F17: =IFERROR(((VLOOKUP(B17,'Origem '!$A$1:$E$1655,5,0)*'Mark Up '!$C$2)),"X") -> 10501.26 | G17: =IFERROR(((VLOOKUP(B17,'Origem '!$A$1:$F$1655,6,0)*'Mark Up '!$C$2)),"X") -> 11933.46 | H17: =IFERROR(((VLOOKUP(B17,'Origem '!$A$1:$H$1655,7,0)*'Mark Up '!$C$2)),"X") -> 12594.12
B18: 10984-2 | C18: Aparador Baden ,tp e bandeja canto garrafa, pés metal (se laca brilho somente c/ VD) | D18: 1,60 x 0,39 x 0,76 | E18: =IFERROR(((VLOOKUP(B18,'Origem '!$A$1:$H$1655,4,0)*'Mark Up '!$C$2)),"X") -> 10251.78 | F18: =IFERROR(((VLOOKUP(B18,'Origem '!$A$1:$E$1655,5,0)*'Mark Up '!$C$2)),"X") -> 10884.72 | G18: =IFERROR(((VLOOKUP(B18,'Origem '!$A$1:$F$1655,6,0)*'Mark Up '!$C$2)),"X") -> 12510.96 | H18: =IFERROR(((VLOOKUP(B18,'Origem '!$A$1:$H$1655,7,0)*'Mark Up '!$C$2)),"X") -> 13342.56
B19: 10984-3 | C19: Aparador Baden ,tp e bandeja canto garrafa, pés metal (se laca brilho somente c/ VD) | D19: 1,80 x 0,39 x 0,76 | E19: =IFERROR(((VLOOKUP(B19,'Origem '!$A$1:$H$1655,4,0)*'Mark Up '!$C$2)),"X") -> 10626 | F19: =IFERROR(((VLOOKUP(B19,'Origem '!$A$1:$E$1655,5,0)*'Mark Up '!$C$2)),"X") -> 11619.3 | G19: =IFERROR(((VLOOKUP(B19,'Origem '!$A$1:$F$1655,6,0)*'Mark Up '!$C$2)),"X") -> 13684.44 | H19: =IFERROR(((VLOOKUP(B19,'Origem '!$A$1:$H$1655,7,0)*'Mark Up '!$C$2)),"X") -> 14405.16
B20: 10984-4 | C20: Aparador Baden ,tp e bandeja canto garrafa, pés metal (se laca brilho somente c/ VD) | D20: 2,00 x 0,39 x 0,76 | E20: =IFERROR(((VLOOKUP(B20,'Origem '!$A$1:$H$1655,4,0)*'Mark Up '!$C$2)),"X") -> 11046.42 | F20: =IFERROR(((VLOOKUP(B20,'Origem '!$A$1:$E$1655,5,0)*'Mark Up '!$C$2)),"X") -> 12450.9 | G20: =IFERROR(((VLOOKUP(B20,'Origem '!$A$1:$F$1655,6,0)*'Mark Up '!$C$2)),"X") -> 14543.76 | H20: =IFERROR(((VLOOKUP(B20,'Origem '!$A$1:$H$1655,7,0)*'Mark Up '!$C$2)),"X") -> 15569.4
A21: BARI | B21: 11620-1 | C21: Aparador Bari pés Mad. | D21: 1,40 x 0,45 x 0,76 | E21: =IFERROR(((VLOOKUP(B21,'Origem '!$A$1:$H$1655,4,0)*'Mark Up '!$C$2)),"X") -> 8519.28 | F21: =IFERROR(((VLOOKUP(B21,'Origem '!$A$1:$E$1655,5,0)*'Mark Up '!$C$2)),"X") -> 8717.94 | G21: =IFERROR(((VLOOKUP(B21,'Origem '!$A$1:$F$1655,6,0)*'Mark Up '!$C$2)),"X") -> 9142.98 | H21: =IFERROR(((VLOOKUP(B21,'Origem '!$A$1:$H$1655,7,0)*'Mark Up '!$C$2)),"X") -> X
B22: 11620-2 | C22: Aparador Bari pés Mad. | D22: 1,60 x 0,45 x 0,76 | E22: =IFERROR(((VLOOKUP(B22,'Origem '!$A$1:$H$1655,4,0)*'Mark Up '!$C$2)),"X") -> 9022.86 | F22: =IFERROR(((VLOOKUP(B22,'Origem '!$A$1:$E$1655,5,0)*'Mark Up '!$C$2)),"X") -> 9309.3 | G22: =IFERROR(((VLOOKUP(B22,'Origem '!$A$1:$F$1655,6,0)*'Mark Up '!$C$2)),"X") -> 10261.02 | H22: =IFERROR(((VLOOKUP(B22,'Origem '!$A$1:$H$1655,7,0)*'Mark Up '!$C$2)),"X") -> X
B23: 11620-3 | C23: Aparador Bari pés Mad. | D23: 1,80 x 0,45 x 0,76 | E23: =IFERROR(((VLOOKUP(B23,'Origem '!$A$1:$H$1655,4,0)*'Mark Up '!$C$2)),"X") -> 9831.36 | F23: =IFERROR(((VLOOKUP(B23,'Origem '!$A$1:$E$1655,5,0)*'Mark Up '!$C$2)),"X") -> 10108.56 | G23: =IFERROR(((VLOOKUP(B23,'Origem '!$A$1:$F$1655,6,0)*'Mark Up '!$C$2)),"X") -> 11115.72 | H23: =IFERROR(((VLOOKUP(B23,'Origem '!$A$1:$H$1655,7,0)*'Mark Up '!$C$2)),"X") -> X
A24: BOGOTÁ | B24: 11640-2 | C24: Aparador Bogotá ,TP.Canto Garrafa; C/ MARCHETARIA | D24: 1,60 x 0,45 x 0,76 | E24: =IFERROR(((VLOOKUP(B24,'Origem '!$A$1:$H$1655,4,0)*'Mark Up '!$C$2)),"X") -> X | F24: =IFERROR(((VLOOKUP(B24,'Origem '!$A$1:$E$1655,5,0)*'Mark Up '!$C$2)),"X") -> 9882.18 | G24: =IFERROR(((VLOOKUP(B24,'Origem '!$A$1:$F$1655,6,0)*'Mark Up '!$C$2)),"X") -> 10921.68 | H24: =IFERROR(((VLOOKUP(B24,'Origem '!$A$1:$H$1655,7,0)*'Mark Up '!$C$2)),"X") -> 12575.64
B25: 11640-3 | C25: Aparador Bogotá ,TP.Canto Garrafa; C/ MARCHETARIA | D25: 1,80 x 0,45 x 0,76 | E25: =IFERROR(((VLOOKUP(B25,'Origem '!$A$1:$H$1655,4,0)*'Mark Up '!$C$2)),"X") -> X | F25: =IFERROR(((VLOOKUP(B25,'Origem '!$A$1:$E$1655,5,0)*'Mark Up '!$C$2)),"X") -> 10367.28 | G25: =IFERROR(((VLOOKUP(B25,'Origem '!$A$1:$F$1655,6,0)*'Mark Up '!$C$2)),"X") -> 11452.98 | H25: =IFERROR(((VLOOKUP(B25,'Origem '!$A$1:$H$1655,7,0)*'Mark Up '!$C$2)),"X") -> 13568.94
B26: 11640-4 | C26: Aparador Bogotá ,TP.Canto Garrafa; C/ MARCHETARIA | D26: 2,00 x 0,45 x 0,76 | E26: =IFERROR(((VLOOKUP(B26,'Origem '!$A$1:$H$1655,4,0)*'Mark Up '!$C$2)),"X") -> X | F26: =IFERROR(((VLOOKUP(B26,'Origem '!$A$1:$E$1655,5,0)*'Mark Up '!$C$2)),"X") -> 10778.46 | G26: =IFERROR(((VLOOKUP(B26,'Origem '!$A$1:$F$1655,6,0)*'Mark Up '!$C$2)),"X") -> 11924.22 | H26: =IFERROR(((VLOOKUP(B26,'Origem '!$A$1:$H$1655,7,0)*'Mark Up '!$C$2)),"X") -> 14141.82
B27: 11641-2 | C27: Aparador Bogotá ,TP.Canto Garrafa; S/ MARCHETARIA | D27: 1,60 x 0,45 x 0,76 | E27: =IFERROR(((VLOOKUP(B27,'Origem '!$A$1:$H$1655,4,0)*'Mark Up '!$C$2)),"X") -> 8417.64 | F27: =IFERROR(((VLOOKUP(B27,'Origem '!$A$1:$E$1655,5,0)*'Mark Up '!$C$2)),"X") -> 9401.7 | G27: =IFERROR(((VLOOKUP(B27,'Origem '!$A$1:$F$1655,6,0)*'Mark Up '!$C$2)),"X") -> 10284.12 | H27: =IFERROR(((VLOOKUP(B27,'Origem '!$A$1:$H$1655,7,0)*'Mark Up '!$C$2)),"X") -> 12178.32
B28: 11641-3 | C28: Aparador Bogotá ,TP.Canto Garrafa; S/ MARCHETARIA | D28: 1,80 x 0,45 x 0,76 | E28: =IFERROR(((VLOOKUP(B28,'Origem '!$A$1:$H$1655,4,0)*'Mark Up '!$C$2)),"X") -> 8930.46 | F28: =IFERROR(((VLOOKUP(B28,'Origem '!$A$1:$E$1655,5,0)*'Mark Up '!$C$2)),"X") -> 9835.98 | G28: =IFERROR(((VLOOKUP(B28,'Origem '!$A$1:$F$1655,6,0)*'Mark Up '!$C$2)),"X") -> 10787.7 | H28: =IFERROR(((VLOOKUP(B28,'Origem '!$A$1:$H$1655,7,0)*'Mark Up '!$C$2)),"X") -> 12783.54
B29: 11641-4 | C29: Aparador Bogotá ,TP.Canto Garrafa; S/ MARCHETARIA | D29: 2,00 x 0,45 x 0,76 | E29: =IFERROR(((VLOOKUP(B29,'Origem '!$A$1:$H$1655,4,0)*'Mark Up '!$C$2)),"X") -> 9332.4 | F29: =IFERROR(((VLOOKUP(B29,'Origem '!$A$1:$E$1655,5,0)*'Mark Up '!$C$2)),"X") -> 10210.2 | G29: =IFERROR(((VLOOKUP(B29,'Origem '!$A$1:$F$1655,6,0)*'Mark Up '!$C$2)),"X") -> 11185.02 | H29: =IFERROR(((VLOOKUP(B29,'Origem '!$A$1:$H$1655,7,0)*'Mark Up '!$C$2)),"X") -> 13282.5
A30: COPENHAGUE | B30: 9554-1 | C30: Aparador Copenhague (tmp oblongo) (se laca brilho somente c/ VD) | D30: 1,41 x 0,46 x 0,76 | E30: =IFERROR(((VLOOKUP(B30,'Origem '!$A$1:$H$1655,4,0)*'Mark Up '!$C$2)),"X") -> 11734.8 | F30: =IFERROR(((VLOOKUP(B30,'Origem '!$A$1:$E$1655,5,0)*'Mark Up '!$C$2)),"X") -> 13458.06 | G30: =IFERROR(((VLOOKUP(B30,'Origem '!$A$1:$F$1655,6,0)*'Mark Up '!$C$2)),"X") -> 15176.7 | H30: =IFERROR(((VLOOKUP(B30,'Origem '!$A$1:$H$1655,7,0)*'Mark Up '!$C$2)),"X") -> 16608.9
B31: 9554-2 | C31: Aparador Copenhague (tmp oblongo) (se laca brilho somente c/ VD) | D31: 1,61 x 0,46 x 0,76 | E31: =IFERROR(((VLOOKUP(B31,'Origem '!$A$1:$H$1655,4,0)*'Mark Up '!$C$2)),"X") -> 12561.78 | F31: =IFERROR(((VLOOKUP(B31,'Origem '!$A$1:$E$1655,5,0)*'Mark Up '!$C$2)),"X") -> 14954.94 | G31: =IFERROR(((VLOOKUP(B31,'Origem '!$A$1:$F$1655,6,0)*'Mark Up '!$C$2)),"X") -> 15915.9 | H31: =IFERROR(((VLOOKUP(B31,'Origem '!$A$1:$H$1655,7,0)*'Mark Up '!$C$2)),"X") -> 17551.38
B32: 9554-3 | C32: Aparador Copenhague (tmp oblongo) (se laca brilho somente c/ VD) | D32: 1,81 x 0,46 x 0,76 | E32: =IFERROR(((VLOOKUP(B32,'Origem '!$A$1:$H$1655,4,0)*'Mark Up '!$C$2)),"X") -> 13273.26 | F32: =IFERROR(((VLOOKUP(B32,'Origem '!$A$1:$E$1655,5,0)*'Mark Up '!$C$2)),"X") -> 15740.34 | G32: =IFERROR(((VLOOKUP(B32,'Origem '!$A$1:$F$1655,6,0)*'Mark Up '!$C$2)),"X") -> 16729.02 | H32: =IFERROR(((VLOOKUP(B32,'Origem '!$A$1:$H$1655,7,0)*'Mark Up '!$C$2)),"X") -> 18419.94
A33: ELLOS | B33: 4594-2 | C33: Aparador Ellos (canto garrafa), pés metal | D33: 1,35 x 0,35 x 0,76 | E33: =IFERROR(((VLOOKUP(B33,'Origem '!$A$1:$H$1655,4,0)*'Mark Up '!$C$2)),"X") -> 7586.04 | F33: =IFERROR(((VLOOKUP(B33,'Origem '!$A$1:$E$1655,5,0)*'Mark Up '!$C$2)),"X") -> 8223.6 | G33: =IFERROR(((VLOOKUP(B33,'Origem '!$A$1:$F$1655,6,0)*'Mark Up '!$C$2)),"X") -> 9147.6 | H33: =IFERROR(((VLOOKUP(B33,'Origem '!$A$1:$H$1655,7,0)*'Mark Up '!$C$2)),"X") -> 9369.36
B34: 4594-3 | C34: Aparador Ellos (canto garrafa), pés metal | D34: 1,60 x 0,35 x 0,76 | E34: =IFERROR(((VLOOKUP(B34,'Origem '!$A$1:$H$1655,4,0)*'Mark Up '!$C$2)),"X") -> 8339.1 | F34: =IFERROR(((VLOOKUP(B34,'Origem '!$A$1:$E$1655,5,0)*'Mark Up '!$C$2)),"X") -> 8847.3 | G34: =IFERROR(((VLOOKUP(B34,'Origem '!$A$1:$F$1655,6,0)*'Mark Up '!$C$2)),"X") -> 9914.52 | H34: =IFERROR(((VLOOKUP(B34,'Origem '!$A$1:$H$1655,7,0)*'Mark Up '!$C$2)),"X") -> 10293.36
B35: 4594-4 | C35: Aparador Ellos (canto garrafa), pés metal | D35: 1,80 x 0,35 x 0,76 | E35: =IFERROR(((VLOOKUP(B35,'Origem '!$A$1:$H$1655,4,0)*'Mark Up '!$C$2)),"X") -> 9549.54 | F35: =IFERROR(((VLOOKUP(B35,'Origem '!$A$1:$E$1655,5,0)*'Mark Up '!$C$2)),"X") -> 10057.74 | G35: =IFERROR(((VLOOKUP(B35,'Origem '!$A$1:$F$1655,6,0)*'Mark Up '!$C$2)),"X") -> 11014.08 | H35: =IFERROR(((VLOOKUP(B35,'Origem '!$A$1:$H$1655,7,0)*'Mark Up '!$C$2)),"X") -> 11494.56
A36: GRANADA | B36: 11034-1 | C36: Aparador Granada (tp oblongo), pés mad. (se laca brilho somente c/ VD) | D36: 1,46 x 0,45 x 0,76 | E36: =IFERROR(((VLOOKUP(B36,'Origem '!$A$1:$H$1655,4,0)*'Mark Up '!$C$2)),"X") -> 7013.16 | F36: =IFERROR(((VLOOKUP(B36,'Origem '!$A$1:$E$1655,5,0)*'Mark Up '!$C$2)),"X") -> 7331.94 | G36: =IFERROR(((VLOOKUP(B36,'Origem '!$A$1:$F$1655,6,0)*'Mark Up '!$C$2)),"X") -> 8842.68 | H36: =IFERROR(((VLOOKUP(B36,'Origem '!$A$1:$H$1655,7,0)*'Mark Up '!$C$2)),"X") -> 9337.02
B37: 11034-2 | C37: Aparador Granada (tp oblongo), pés mad. (se laca brilho somente c/ VD) | D37: 1,66 x 0,45 x 0,76 | E37: =IFERROR(((VLOOKUP(B37,'Origem '!$A$1:$H$1655,4,0)*'Mark Up '!$C$2)),"X") -> 7701.54 | F37: =IFERROR(((VLOOKUP(B37,'Origem '!$A$1:$E$1655,5,0)*'Mark Up '!$C$2)),"X") -> 7927.92 | G37: =IFERROR(((VLOOKUP(B37,'Origem '!$A$1:$F$1655,6,0)*'Mark Up '!$C$2)),"X") -> 9410.94 | H37: =IFERROR(((VLOOKUP(B37,'Origem '!$A$1:$H$1655,7,0)*'Mark Up '!$C$2)),"X") -> 10030.02
B38: 11034-3 | C38: Aparador Granada (tp oblongo), pés mad. (se laca brilho somente c/ VD) | D38: 1,86 x 0,45 x 0,76 | E38: =IFERROR(((VLOOKUP(B38,'Origem '!$A$1:$H$1655,4,0)*'Mark Up '!$C$2)),"X") -> 8085 | F38: =IFERROR(((VLOOKUP(B38,'Origem '!$A$1:$E$1655,5,0)*'Mark Up '!$C$2)),"X") -> 8306.76 | G38: =IFERROR(((VLOOKUP(B38,'Origem '!$A$1:$F$1655,6,0)*'Mark Up '!$C$2)),"X") -> 9942.24 | H38: =IFERROR(((VLOOKUP(B38,'Origem '!$A$1:$H$1655,7,0)*'Mark Up '!$C$2)),"X") -> 10695.3
B39: 11034-4 | C39: Aparador Granada (tp oblongo), pés mad. (se laca brilho somente c/ VD) | D39: 2,06 x 0,45 x 0,76 | E39: =IFERROR(((VLOOKUP(B39,'Origem '!$A$1:$H$1655,4,0)*'Mark Up '!$C$2)),"X") -> 8791.86 | F39: =IFERROR(((VLOOKUP(B39,'Origem '!$A$1:$E$1655,5,0)*'Mark Up '!$C$2)),"X") -> 9092.16 | G39: =IFERROR(((VLOOKUP(B39,'Origem '!$A$1:$F$1655,6,0)*'Mark Up '!$C$2)),"X") -> 10662.96 | H39: =IFERROR(((VLOOKUP(B39,'Origem '!$A$1:$H$1655,7,0)*'Mark Up '!$C$2)),"X") -> 11462.22
A40: MADAGASCAR | B40: 10484-1 | C40: Aparador Madagascar (tp oblongo), pés metal; (com tampo sobreposto) | D40: 1,36 x 0,39 x 0,76 | E40: =IFERROR(((VLOOKUP(B40,'Origem '!$A$1:$H$1655,4,0)*'Mark Up '!$C$2)),"X") -> 8399.16 | F40: =IFERROR(((VLOOKUP(B40,'Origem '!$A$1:$E$1655,5,0)*'Mark Up '!$C$2)),"X") -> 8879.64 | G40: =IFERROR(((VLOOKUP(B40,'Origem '!$A$1:$F$1655,6,0)*'Mark Up '!$C$2)),"X") -> 10076.22 | H40: =IFERROR(((VLOOKUP(B40,'Origem '!$A$1:$H$1655,7,0)*'Mark Up '!$C$2)),"X") -> 10662.96
...

Sheet Buffets
C1: BUFFETS | I1: AMBIENTADAS
A2: COLEÇÃO | B2: REF | C2: DESCRIÇÃO | D2: COMP X PROF X ALT | E2: Em caso de cores diferentes, utilizar preço de maior valor
E3: COLUNA 1 | F3: COLUNA 2 | G3: COLUNA 3 | H3: COLUNA 4
E4: LACA LISA BRAZIL ( COM OU SEM VIDRO PINTADO) | F4: - CARVALHO CLARO - CARVALHO NATURAL - CARVALHO LAVADO - CARV. EBANIZADO - IMBUIA CLARA * ACRESCENTAR 12% SE COM VIDRO PINTADO | G4: - NOGUEIRA - NOGUEIRA NATURAL - LOURO FREIJÓ - LOURO FREIJÓ NATURAL - LACA METALIZADA BRAZIL - CARV. ÔNIX METALIZADO - CARV. N109 METALIZADO - CARV. ALBANIZADO - CARV. H155 FOSCO - CONCRETO (SOMENTE SEM VIDRO) | H4: - PAU FERRO
E5: FUNDO DO BUFFET NO MESMO ACABAMENTO DO MOVEL ACRESCENTAR +5% E INFORMAR NO PEDIDO
E6: OBS. O ACABAMENTO DO METAL NÃO INFLUENCIARÁ NO VALOR DO BUFFET
A7: AURORA | B7: 8990-3 | C7: Buffet Aurora Marchetado (4 portas;1 gav. Int.; 1 prat.), tpo bandeja (se laca somente c/ VD), pés metal | D7: 1,84 x 0,48 x 0,76 | E7: =IFERROR(((VLOOKUP(B7,'Origem '!$A$1:$D$1675,4,0)*'Mark Up '!$C$2)),"X") -> 21205.8 | F7: =IFERROR(((VLOOKUP(B7,'Origem '!$A$1:$E$1675,5,0)*'Mark Up '!$C$2)),"X") -> 25668.72 | G7: =IFERROR(((VLOOKUP(B7,'Origem '!$A$1:$F$1675,6,0)*'Mark Up '!$C$2)),"X") -> 29591.1 | H7: =IFERROR(((VLOOKUP(B7,'Origem '!$A$1:$H$1675,7,0)*'Mark Up '!$C$2)),"X") -> 31679.34
B8: 8990-4 | C8: Buffet Aurora Marchetado (4 portas;1 gav. Int.; 1 prat.), tpo bandeja (se laca somente c/ VD), pés metal | D8: 2,04 x 0,48 x 0,76 | E8: =IFERROR(((VLOOKUP(B8,'Origem '!$A$1:$D$1675,4,0)*'Mark Up '!$C$2)),"X") -> 21968.1 | F8: =IFERROR(((VLOOKUP(B8,'Origem '!$A$1:$E$1675,5,0)*'Mark Up '!$C$2)),"X") -> 27124.02 | G8: =IFERROR(((VLOOKUP(B8,'Origem '!$A$1:$F$1675,6,0)*'Mark Up '!$C$2)),"X") -> 30921.66 | H8: =IFERROR(((VLOOKUP(B8,'Origem '!$A$1:$H$1675,7,0)*'Mark Up '!$C$2)),"X") -> 33615.12
B9: 8990-5 | C9: Buffet Aurora Marchetado (5 portas;1 gav. Int.; 2 prat.), tpo bandeja (se laca somente c/ VD), pés metal | D9: 2,29 x 0,48 x 0,76 | E9: =IFERROR(((VLOOKUP(B9,'Origem '!$A$1:$D$1675,4,0)*'Mark Up '!$C$2)),"X") -> 23562 | F9: =IFERROR(((VLOOKUP(B9,'Origem '!$A$1:$E$1675,5,0)*'Mark Up '!$C$2)),"X") -> 29263.08 | G9: =IFERROR(((VLOOKUP(B9,'Origem '!$A$1:$F$1675,6,0)*'Mark Up '!$C$2)),"X") -> 33254.76 | H9: =IFERROR(((VLOOKUP(B9,'Origem '!$A$1:$H$1675,7,0)*'Mark Up '!$C$2)),"X") -> 36243.9
B10: 8990-7 | C10: Buffet Aurora Marchetado (5 portas;1 gav. Int.; 2 prat.), tpo bandeja (se laca somente c/ VD), pés metal | D10: 2,54 x 0,48 x 0,76 | E10: =IFERROR(((VLOOKUP(B10,'Origem '!$A$1:$D$1675,4,0)*'Mark Up '!$C$2)),"X") -> 25257.54 | F10: =IFERROR(((VLOOKUP(B10,'Origem '!$A$1:$E$1675,5,0)*'Mark Up '!$C$2)),"X") -> 31711.68 | G10: =IFERROR(((VLOOKUP(B10,'Origem '!$A$1:$F$1675,6,0)*'Mark Up '!$C$2)),"X") -> 35814.24 | H10: =IFERROR(((VLOOKUP(B10,'Origem '!$A$1:$H$1675,7,0)*'Mark Up '!$C$2)),"X") -> 39149.88
A11: AURORA | B11: 11800-10 | C11: Buffet Aurora B Marchetado""INTERNO PRETO OU CINZA"" (4 portas;1 gav. Int.; 1 prat.), tpo bandeja (se laca brilho somente c/ VD), pés metal | D11: 1,86 x 0,48 x 0,75 | E11: =IFERROR(((VLOOKUP(B11,'Origem '!$A$1:$D$1675,4,0)*'Mark Up '!$C$2)),"X") -> X | F11: =IFERROR(((VLOOKUP(B11,'Origem '!$A$1:$E$1675,5,0)*'Mark Up '!$C$2)),"X") -> 22411.62 | G11: =IFERROR(((VLOOKUP(B11,'Origem '!$A$1:$F$1675,6,0)*'Mark Up '!$C$2)),"X") -> 25165.14 | H11: =IFERROR(((VLOOKUP(B11,'Origem '!$A$1:$H$1675,7,0)*'Mark Up '!$C$2)),"X") -> 29424.78
B12: 11800-12 | C12: Buffet Aurora B Marchetado""INTERNO PRETO OU CINZA"" (4 portas;1 gav. Int.; 1 prat.), tpo bandeja (se laca brilho somente c/ VD), pés metal | D12: 2,06 x 0,48 x 0,75 | E12: =IFERROR(((VLOOKUP(B12,'Origem '!$A$1:$D$1675,4,0)*'Mark Up '!$C$2)),"X") -> X | F12: =IFERROR(((VLOOKUP(B12,'Origem '!$A$1:$E$1675,5,0)*'Mark Up '!$C$2)),"X") -> 23760.66 | G12: =IFERROR(((VLOOKUP(B12,'Origem '!$A$1:$F$1675,6,0)*'Mark Up '!$C$2)),"X") -> 26310.9 | H12: =IFERROR(((VLOOKUP(B12,'Origem '!$A$1:$H$1675,7,0)*'Mark Up '!$C$2)),"X") -> 30718.38
B13: 11800-14 | C13: Buffet Aurora B Marchetado""INTERNO PRETO OU CINZA"" (5 portas;1 gav. Int.; 1 prat.), tpo bandeja (se laca brilho somente c/ VD), pés metal | D13: 2,31 x 0,48 x 0,75 | E13: =IFERROR(((VLOOKUP(B13,'Origem '!$A$1:$D$1675,4,0)*'Mark Up '!$C$2)),"X") -> X | F13: =IFERROR(((VLOOKUP(B13,'Origem '!$A$1:$E$1675,5,0)*'Mark Up '!$C$2)),"X") -> 25664.1 | G13: =IFERROR(((VLOOKUP(B13,'Origem '!$A$1:$F$1675,6,0)*'Mark Up '!$C$2)),"X") -> 28787.22 | H13: =IFERROR(((VLOOKUP(B13,'Origem '!$A$1:$H$1675,7,0)*'Mark Up '!$C$2)),"X") -> 33721.38
B14: 11800-18 | C14: Buffet Aurora B Marchetado""INTERNO PRETO OU CINZA"" (5 portas;1 gav. Int.; 1 prat.), tpo bandeja (se laca brilho somente c/ VD), pés metal | D14: 2,56 x 0,48 x 0,75 | E14: =IFERROR(((VLOOKUP(B14,'Origem '!$A$1:$D$1675,4,0)*'Mark Up '!$C$2)),"X") -> X | F14: =IFERROR(((VLOOKUP(B14,'Origem '!$A$1:$E$1675,5,0)*'Mark Up '!$C$2)),"X") -> 27391.98 | G14: =IFERROR(((VLOOKUP(B14,'Origem '!$A$1:$F$1675,6,0)*'Mark Up '!$C$2)),"X") -> 30820.02 | H14: =IFERROR(((VLOOKUP(B14,'Origem '!$A$1:$H$1675,7,0)*'Mark Up '!$C$2)),"X") -> 35449.26
A15: BADEN | B15: 10670-10 | C15: Buffet Baden (4 P, 1 Prat Pq, 1 Gav.),pés de metal (se laca brilho somente c/ VD) | D15: 1,80 x 0,48 x 0,76 | E15: =IFERROR(((VLOOKUP(B15,'Origem '!$A$1:$D$1675,4,0)*'Mark Up '!$C$2)),"X") -> 18660.18 | F15: =IFERROR(((VLOOKUP(B15,'Origem '!$A$1:$E$1675,5,0)*'Mark Up '!$C$2)),"X") -> 22892.1 | G15: =IFERROR(((VLOOKUP(B15,'Origem '!$A$1:$F$1675,6,0)*'Mark Up '!$C$2)),"X") -> 26412.54 | H15: =IFERROR(((VLOOKUP(B15,'Origem '!$A$1:$H$1675,7,0)*'Mark Up '!$C$2)),"X") -> 29332.38
B16: 10670-12 | C16: Buffet Baden (4 P, 1 Prat Pq, 1 Gav.),pés de metal (se laca brilho somente c/ VD) | D16: 2,00 x 0,48 x 0,76 | E16: =IFERROR(((VLOOKUP(B16,'Origem '!$A$1:$D$1675,4,0)*'Mark Up '!$C$2)),"X") -> 19200.72 | F16: =IFERROR(((VLOOKUP(B16,'Origem '!$A$1:$E$1675,5,0)*'Mark Up '!$C$2)),"X") -> 24606.12 | G16: =IFERROR(((VLOOKUP(B16,'Origem '!$A$1:$F$1675,6,0)*'Mark Up '!$C$2)),"X") -> 27812.4 | H16: =IFERROR(((VLOOKUP(B16,'Origem '!$A$1:$H$1675,7,0)*'Mark Up '!$C$2)),"X") -> 30750.72
B17: 10670-14 | C17: Buffet Baden (5 P, 2 Prat Pq, 1 Gav.),pés de metal (se laca brilho somente c/ VD) | D17: 2,25 x 0,48 x 0,76 | E17: =IFERROR(((VLOOKUP(B17,'Origem '!$A$1:$D$1675,4,0)*'Mark Up '!$C$2)),"X") -> 20452.74 | F17: =IFERROR(((VLOOKUP(B17,'Origem '!$A$1:$E$1675,5,0)*'Mark Up '!$C$2)),"X") -> 26038.32 | G17: =IFERROR(((VLOOKUP(B17,'Origem '!$A$1:$F$1675,6,0)*'Mark Up '!$C$2)),"X") -> 29623.44 | H17: =IFERROR(((VLOOKUP(B17,'Origem '!$A$1:$H$1675,7,0)*'Mark Up '!$C$2)),"X") -> 32871.3
B18: 10670-18 | C18: Buffet Baden (5 P, 2 Prat Pq, 1 Gav.),pés de metal (se laca brilho somente c/ VD) | D18: 2,50 x 0,48 x 0,76 | E18: =IFERROR(((VLOOKUP(B18,'Origem '!$A$1:$D$1675,4,0)*'Mark Up '!$C$2)),"X") -> 21820.26 | F18: =IFERROR(((VLOOKUP(B18,'Origem '!$A$1:$E$1675,5,0)*'Mark Up '!$C$2)),"X") -> 26722.08 | G18: =IFERROR(((VLOOKUP(B18,'Origem '!$A$1:$F$1675,6,0)*'Mark Up '!$C$2)),"X") -> 30473.52 | H18: =IFERROR(((VLOOKUP(B18,'Origem '!$A$1:$H$1675,7,0)*'Mark Up '!$C$2)),"X") -> 34516.02
A19: CASABLANCA | B19: 8417-0 | C19: Buffet Casablanca (1 gav.int.;1 prat; 4 portas),pés mad. | D19: 1,80 x 0,47 x 0,80 | E19: =IFERROR(((VLOOKUP(B19,'Origem '!$A$1:$D$1675,4,0)*'Mark Up '!$C$2)),"X") -> 18170.46 | F19: =IFERROR(((VLOOKUP(B19,'Origem '!$A$1:$E$1675,5,0)*'Mark Up '!$C$2)),"X") -> 21852.6 | G19: =IFERROR(((VLOOKUP(B19,'Origem '!$A$1:$F$1675,6,0)*'Mark Up '!$C$2)),"X") -> 24615.36 | H19: =IFERROR(((VLOOKUP(B19,'Origem '!$A$1:$H$1675,7,0)*'Mark Up '!$C$2)),"X") -> 25289.88
B20: 8417-1 | C20: Buffet Casablanca (1 gav.int.;1 prat; 4 portas),pés mad. | D20: 2,00 x 0,47 x 0,80 | E20: =IFERROR(((VLOOKUP(B20,'Origem '!$A$1:$D$1675,4,0)*'Mark Up '!$C$2)),"X") -> 19066.74 | F20: =IFERROR(((VLOOKUP(B20,'Origem '!$A$1:$E$1675,5,0)*'Mark Up '!$C$2)),"X") -> 24000.9 | G20: =IFERROR(((VLOOKUP(B20,'Origem '!$A$1:$F$1675,6,0)*'Mark Up '!$C$2)),"X") -> 26546.52 | H20: =IFERROR(((VLOOKUP(B20,'Origem '!$A$1:$H$1675,7,0)*'Mark Up '!$C$2)),"X") -> 27359.64
A21: CHAPLIN | B21: 11820-10 | C21: Buffet Chaplin B ""INTERNO PRETO OU CINZA"" (4 portas;1 gav. Int.; 1 prat.), tpo bandeja (se laca brilho somente c/ VD), pés metal | D21: 1,86 x 0,48 x 0,75 | E21: =IFERROR(((VLOOKUP(B21,'Origem '!$A$1:$D$1675,4,0)*'Mark Up '!$C$2)),"X") -> X | F21: =IFERROR(((VLOOKUP(B21,'Origem '!$A$1:$E$1675,5,0)*'Mark Up '!$C$2)),"X") -> 22046.64 | G21: =IFERROR(((VLOOKUP(B21,'Origem '!$A$1:$F$1675,6,0)*'Mark Up '!$C$2)),"X") -> 24758.58 | H21: =IFERROR(((VLOOKUP(B21,'Origem '!$A$1:$H$1675,7,0)*'Mark Up '!$C$2)),"X") -> 28953.54
B22: 11820-12 | C22: Buffet Chaplin B ""INTERNO PRETO OU CINZA"" (4 portas;1 gav. Int.; 1 prat.), tpo bandeja (se laca brilho somente c/ VD), pés metal | D22: 2,06 x 0,48 x 0,75 | E22: =IFERROR(((VLOOKUP(B22,'Origem '!$A$1:$D$1675,4,0)*'Mark Up '!$C$2)),"X") -> X | F22: =IFERROR(((VLOOKUP(B22,'Origem '!$A$1:$E$1675,5,0)*'Mark Up '!$C$2)),"X") -> 23321.76 | G22: =IFERROR(((VLOOKUP(B22,'Origem '!$A$1:$F$1675,6,0)*'Mark Up '!$C$2)),"X") -> 25821.18 | H22: =IFERROR(((VLOOKUP(B22,'Origem '!$A$1:$H$1675,7,0)*'Mark Up '!$C$2)),"X") -> 30163.98
B23: 11820-14 | C23: Buffet Chaplin B ""INTERNO PRETO OU CINZA"" (5 portas;1 gav. Int.; 1 prat.), tpo bandeja (se laca brilho somente c/ VD), pés metal | D23: 2,31 x 0,48 x 0,75 | E23: =IFERROR(((VLOOKUP(B23,'Origem '!$A$1:$D$1675,4,0)*'Mark Up '!$C$2)),"X") -> X | F23: =IFERROR(((VLOOKUP(B23,'Origem '!$A$1:$E$1675,5,0)*'Mark Up '!$C$2)),"X") -> 25215.96 | G23: =IFERROR(((VLOOKUP(B23,'Origem '!$A$1:$F$1675,6,0)*'Mark Up '!$C$2)),"X") -> 28269.78 | H23: =IFERROR(((VLOOKUP(B23,'Origem '!$A$1:$H$1675,7,0)*'Mark Up '!$C$2)),"X") -> 33125.4
B24: 11820-18 | C24: Buffet Chaplin B ""INTERNO PRETO OU CINZA"" (5 portas;1 gav. Int.; 1 prat.), tpo bandeja (se laca brilho somente c/ VD), pés metal | D24: 2,56 x 0,48 x 0,75 | E24: =IFERROR(((VLOOKUP(B24,'Origem '!$A$1:$D$1675,4,0)*'Mark Up '!$C$2)),"X") -> X | F24: =IFERROR(((VLOOKUP(B24,'Origem '!$A$1:$E$1675,5,0)*'Mark Up '!$C$2)),"X") -> 27904.8 | G24: =IFERROR(((VLOOKUP(B24,'Origem '!$A$1:$F$1675,6,0)*'Mark Up '!$C$2)),"X") -> 30362.64 | H24: =IFERROR(((VLOOKUP(B24,'Origem '!$A$1:$H$1675,7,0)*'Mark Up '!$C$2)),"X") -> 34848.66
A25: DINAMO | B25: 7980-3 | C25: Buffet Dinamo (4 portas, 2 gav.), pés metal | D25: 1,80 x 0,47 x 0,76 | E25: =IFERROR(((VLOOKUP(B25,'Origem '!$A$1:$D$1675,4,0)*'Mark Up '!$C$2)),"X") -> 25345.32 | F25: =IFERROR(((VLOOKUP(B25,'Origem '!$A$1:$E$1675,5,0)*'Mark Up '!$C$2)),"X") -> 27216.42 | G25: =IFERROR(((VLOOKUP(B25,'Origem '!$A$1:$F$1675,6,0)*'Mark Up '!$C$2)),"X") -> 30949.38 | H25: =IFERROR(((VLOOKUP(B25,'Origem '!$A$1:$H$1675,7,0)*'Mark Up '!$C$2)),"X") -> 32118.24
B26: 7980-4 | C26: Buffet Dinamo (4 portas, 2 gav.), pés metal | D26: 2,00 x 0,47 x 0,76 | E26: =IFERROR(((VLOOKUP(B26,'Origem '!$A$1:$D$1675,4,0)*'Mark Up '!$C$2)),"X") -> 26200.02 | F26: =IFERROR(((VLOOKUP(B26,'Origem '!$A$1:$E$1675,5,0)*'Mark Up '!$C$2)),"X") -> 28510.02 | G26: =IFERROR(((VLOOKUP(B26,'Origem '!$A$1:$F$1675,6,0)*'Mark Up '!$C$2)),"X") -> 32303.04 | H26: =IFERROR(((VLOOKUP(B26,'Origem '!$A$1:$H$1675,7,0)*'Mark Up '!$C$2)),"X") -> 33619.74
B27: 7980-7 | C27: Buffet Dinamo (5 portas, 3 gav.), pés metal | D27: 2,50 x 0,47 x 0,76 | E27: =IFERROR(((VLOOKUP(B27,'Origem '!$A$1:$D$1675,4,0)*'Mark Up '!$C$2)),"X") -> 29443.26 | F27: =IFERROR(((VLOOKUP(B27,'Origem '!$A$1:$E$1675,5,0)*'Mark Up '!$C$2)),"X") -> 32871.3 | G27: =IFERROR(((VLOOKUP(B27,'Origem '!$A$1:$F$1675,6,0)*'Mark Up '!$C$2)),"X") -> 37611.42 | H27: =IFERROR(((VLOOKUP(B27,'Origem '!$A$1:$H$1675,7,0)*'Mark Up '!$C$2)),"X") -> 38244.36
A28: GENOVA | B28: 10111-10 | C28: Buffet Genova ,Nicho, Pés de Metal (4 portas, 2 Prat., 1 Gav.) | D28: 1,80 x 0,47 x 0,80 | E28: =IFERROR(((VLOOKUP(B28,'Origem '!$A$1:$D$1675,4,0)*'Mark Up '!$C$2)),"X") -> 23423.4 | F28: =IFERROR(((VLOOKUP(B28,'Origem '!$A$1:$E$1675,5,0)*'Mark Up '!$C$2)),"X") -> 27498.24 | G28: =IFERROR(((VLOOKUP(B28,'Origem '!$A$1:$F$1675,6,0)*'Mark Up '!$C$2)),"X") -> 30519.72 | H28: =IFERROR(((VLOOKUP(B28,'Origem '!$A$1:$H$1675,7,0)*'Mark Up '!$C$2)),"X") -> 31753.26
B29: 10111-12 | C29: Buffet Genova ,Nicho, Pés de Metal (4 portas, 2 Prat., 1 Gav.) | D29: 2,00 x 0,47 x 0,80 | E29: =IFERROR(((VLOOKUP(B29,'Origem '!$A$1:$D$1675,4,0)*'Mark Up '!$C$2)),"X") -> 24194.94 | F29: =IFERROR(((VLOOKUP(B29,'Origem '!$A$1:$E$1675,5,0)*'Mark Up '!$C$2)),"X") -> 28625.52 | G29: =IFERROR(((VLOOKUP(B29,'Origem '!$A$1:$F$1675,6,0)*'Mark Up '!$C$2)),"X") -> 31683.96 | H29: =IFERROR(((VLOOKUP(B29,'Origem '!$A$1:$H$1675,7,0)*'Mark Up '!$C$2)),"X") -> 32631.06
B30: 10111-14 | C30: Buffet Genova ,Nicho, Pés de Metal (5 portas, 3 Prat., 1 Gav.) | D30: 2,25 x 0,47 x 0,80 | E30: =IFERROR(((VLOOKUP(B30,'Origem '!$A$1:$D$1675,4,0)*'Mark Up '!$C$2)),"X") -> 27960.24 | F30: =IFERROR(((VLOOKUP(B30,'Origem '!$A$1:$E$1675,5,0)*'Mark Up '!$C$2)),"X") -> 30912.42 | G30: =IFERROR(((VLOOKUP(B30,'Origem '!$A$1:$F$1675,6,0)*'Mark Up '!$C$2)),"X") -> 35805 | H30: =IFERROR(((VLOOKUP(B30,'Origem '!$A$1:$H$1675,7,0)*'Mark Up '!$C$2)),"X") -> 36456.42
B31: 10111-18 | C31: Buffet Genova ,Nicho, Pés de Metal (5 portas, 3 Prat., 1 Gav.) | D31: 2,50 x 0,47 x 0,80 | E31: =IFERROR(((VLOOKUP(B31,'Origem '!$A$1:$D$1675,4,0)*'Mark Up '!$C$2)),"X") -> 29470.98 | F31: =IFERROR(((VLOOKUP(B31,'Origem '!$A$1:$E$1675,5,0)*'Mark Up '!$C$2)),"X") -> 33836.88 | G31: =IFERROR(((VLOOKUP(B31,'Origem '!$A$1:$F$1675,6,0)*'Mark Up '!$C$2)),"X") -> 38027.22 | H31: =IFERROR(((VLOOKUP(B31,'Origem '!$A$1:$H$1675,7,0)*'Mark Up '!$C$2)),"X") -> 38184.3
B32: 11940-10 | C32: Buffet Genova B ""INTERNO PRETO OU CINZA"" , Nicho, Pés de Metal (4 portas, 2 Prat., 1 Gav.) | D32: 1,82 x 0,47 x 0,80 | E32: =IFERROR(((VLOOKUP(B32,'Origem '!$A$1:$D$1675,4,0)*'Mark Up '!$C$2)),"X") -> X | F32: =IFERROR(((VLOOKUP(B32,'Origem '!$A$1:$E$1675,5,0)*'Mark Up '!$C$2)),"X") -> 25848.9 | G32: =IFERROR(((VLOOKUP(B32,'Origem '!$A$1:$F$1675,6,0)*'Mark Up '!$C$2)),"X") -> 27345.78 | H32: =IFERROR(((VLOOKUP(B32,'Origem '!$A$1:$H$1675,7,0)*'Mark Up '!$C$2)),"X") -> 28269.78
B33: 11940-12 | C33: Buffet Genova B ""INTERNO PRETO OU CINZA"" , Nicho, Pés de Metal (4 portas, 2 Prat., 1 Gav.) | D33: 2,02 x 0,47 x 0,80 | E33: =IFERROR(((VLOOKUP(B33,'Origem '!$A$1:$D$1675,4,0)*'Mark Up '!$C$2)),"X") -> X | F33: =IFERROR(((VLOOKUP(B33,'Origem '!$A$1:$E$1675,5,0)*'Mark Up '!$C$2)),"X") -> 27313.44 | G33: =IFERROR(((VLOOKUP(B33,'Origem '!$A$1:$F$1675,6,0)*'Mark Up '!$C$2)),"X") -> 28953.54 | H33: =IFERROR(((VLOOKUP(B33,'Origem '!$A$1:$H$1675,7,0)*'Mark Up '!$C$2)),"X") -> 29997.66
B34: 11940-14 | C34: Buffet Genova B ""INTERNO PRETO OU CINZA"" , Nicho, Pés de Metal (5 portas, 3 Prat., 1 Gav.) | D34: 2,27 x 0,47 x 0,80 | E34: =IFERROR(((VLOOKUP(B34,'Origem '!$A$1:$D$1675,4,0)*'Mark Up '!$C$2)),"X") -> X | F34: =IFERROR(((VLOOKUP(B34,'Origem '!$A$1:$E$1675,5,0)*'Mark Up '!$C$2)),"X") -> 29595.72 | G34: =IFERROR(((VLOOKUP(B34,'Origem '!$A$1:$F$1675,6,0)*'Mark Up '!$C$2)),"X") -> 31323.6 | H34: =IFERROR(((VLOOKUP(B34,'Origem '!$A$1:$H$1675,7,0)*'Mark Up '!$C$2)),"X") -> 32418.54
B35: 11940-18 | C35: Buffet Genova B ""INTERNO PRETO OU CINZA"" , Nicho, Pés de Metal (5 portas, 3 Prat., 1 Gav.) | D35: 2,52 x 0,47 x 0,80 | E35: =IFERROR(((VLOOKUP(B35,'Origem '!$A$1:$D$1675,4,0)*'Mark Up '!$C$2)),"X") -> X | F35: =IFERROR(((VLOOKUP(B35,'Origem '!$A$1:$E$1675,5,0)*'Mark Up '!$C$2)),"X") -> 30787.68 | G35: =IFERROR(((VLOOKUP(B35,'Origem '!$A$1:$F$1675,6,0)*'Mark Up '!$C$2)),"X") -> 32136.72 | H35: =IFERROR(((VLOOKUP(B35,'Origem '!$A$1:$H$1675,7,0)*'Mark Up '!$C$2)),"X") -> 33744.48
A36: KYOTO | B36: 10141-10 | C36: Buffet Kyoto Porta Marchetada(4 portas) Pux Cava Tp Arredondado Pés de Metal (Somente SEM VD) | D36: 1,88 x 0,45 x 0,76 | E36: =IFERROR(((VLOOKUP(B36,'Origem '!$A$1:$D$1675,4,0)*'Mark Up '!$C$2)),"X") -> 23127.72 | F36: =IFERROR(((VLOOKUP(B36,'Origem '!$A$1:$E$1675,5,0)*'Mark Up '!$C$2)),"X") -> 27655.32 | G36: =IFERROR(((VLOOKUP(B36,'Origem '!$A$1:$F$1675,6,0)*'Mark Up '!$C$2)),"X") -> 30935.52 | H36: =IFERROR(((VLOOKUP(B36,'Origem '!$A$1:$H$1675,7,0)*'Mark Up '!$C$2)),"X") -> 32529.42
B37: 10141-12 | C37: Buffet Kyoto Porta Marchetada(4 portas) Pux Cava Tp Arredondado Pés de Metal (Somente SEM VD) | D37: 2,08 x 0,45 x 0,76 | E37: =IFERROR(((VLOOKUP(B37,'Origem '!$A$1:$D$1675,4,0)*'Mark Up '!$C$2)),"X") -> 24291.96 | F37: =IFERROR(((VLOOKUP(B37,'Origem '!$A$1:$E$1675,5,0)*'Mark Up '!$C$2)),"X") -> 29752.8 | G37: =IFERROR(((VLOOKUP(B37,'Origem '!$A$1:$F$1675,6,0)*'Mark Up '!$C$2)),"X") -> 32649.54 | H37: =IFERROR(((VLOOKUP(B37,'Origem '!$A$1:$H$1675,7,0)*'Mark Up '!$C$2)),"X") -> 35985.18
B38: 10141-15 | C38: Buffet Kyoto Porta Marchetada(5 portas) Pux Cava Tp Arredondado Pés de Metal (Somente SEM VD) | D38: 2,32 x 0,45 x 0,76 | E38: =IFERROR(((VLOOKUP(B38,'Origem '!$A$1:$D$1675,4,0)*'Mark Up '!$C$2)),"X") -> 25645.62 | F38: =IFERROR(((VLOOKUP(B38,'Origem '!$A$1:$E$1675,5,0)*'Mark Up '!$C$2)),"X") -> 31254.3 | G38: =IFERROR(((VLOOKUP(B38,'Origem '!$A$1:$F$1675,6,0)*'Mark Up '!$C$2)),"X") -> 34756.26 | H38: =IFERROR(((VLOOKUP(B38,'Origem '!$A$1:$H$1675,7,0)*'Mark Up '!$C$2)),"X") -> 36733.62
B39: 10141-18 | C39: Buffet Kyoto Porta Marchetada(5 portas) Pux Cava Tp Arredondado Pés de Metal (Somente SEM VD) | D39: 2,58 x 0,45 x 0,76 | E39: =IFERROR(((VLOOKUP(B39,'Origem '!$A$1:$D$1675,4,0)*'Mark Up '!$C$2)),"X") -> 27803.16 | F39: =IFERROR(((VLOOKUP(B39,'Origem '!$A$1:$E$1675,5,0)*'Mark Up '!$C$2)),"X") -> 33037.62 | G39: =IFERROR(((VLOOKUP(B39,'Origem '!$A$1:$F$1675,6,0)*'Mark Up '!$C$2)),"X") -> 36479.52 | H39: =IFERROR(((VLOOKUP(B39,'Origem '!$A$1:$H$1675,7,0)*'Mark Up '!$C$2)),"X") -> 39233.04
B40: 12010-10 | C40: Buffet Kyoto "B" Porta Marchetada "INTERNO PRETO OU CINZA" (4 portas) Pux Cava Tp Arredondado Pés Metal (Somente SEM VD) | D40: 1,88 x 0,45 x 0,76 | E40: =IFERROR(((VLOOKUP(B40,'Origem '!$A$1:$D$1675,4,0)*'Mark Up '!$C$2)),"X") -> X | F40: =IFERROR(((VLOOKUP(B40,'Origem '!$A$1:$E$1675,5,0)*'Mark Up '!$C$2)),"X") -> 26204.64 | G40: =IFERROR(((VLOOKUP(B40,'Origem '!$A$1:$F$1675,6,0)*'Mark Up '!$C$2)),"X") -> 27087.06 | H40: =IFERROR(((VLOOKUP(B40,'Origem '!$A$1:$H$1675,7,0)*'Mark Up '!$C$2)),"X") -> 30016.14
...

Sheet Carrinhos de Chá 
C1: CARRINHOS DE CHÁ | I1: AMBIENTADAS
A2: COLEÇÃO | B2: REF | C2: DESCRIÇÃO | D2: COMP X PROF X ALT | E2: Em caso de cores diferentes Base ou Tampo, utilizar preço de maior valor
E3: COLUNA 1 | F3: COLUNA 2 | G3: COLUNA 3 | H3: COLUNA 4
E4: LACA LISA BRAZIL ( COM OU SEM VIDRO PINTADO) | F4: - CARVALHO CLARO - CARVALHO NATURAL - CARVALHO LAVADO - CARV. EBANIZADO - IMBUIA CLARA * ACRESCENTAR 12% SE COM VIDRO PINTADO | G4: - NOGUEIRA - NOGUEIRA NATURAL - LOURO FREIJÓ - LOURO FREIJÓ NATURAL - LACA METALIZADA BRAZIL - CARV. ÔNIX METALIZADO - CARV. N109 METALIZADO - CARV. ALBANIZADO - CARV. H155 FOSCO - CONCRETO (SOMENTE SEM VIDRO) | H4: - PAU FERRO
E5: OBS. O ACABAMENTO DO METAL NÃO INFLUENCIARÁ NO VALOR DO CARRINHO DE CHÁ
A6: GOLD | B6: 4829-0 | C6: Carrinho de Chá Gold (se laca brilho somente c/ VD) | D6: 1,16 x 0,46 x 0,80 | E6: =IFERROR(((VLOOKUP(B6,'Origem '!$A$1:$D$1665,4,0)*'Mark Up '!$C$2)),"X") -> 10649.1 | F6: =IFERROR(((VLOOKUP(B6,'Origem '!$A$1:$E$1665,5,0)*'Mark Up '!$C$2)),"X") -> 12159.84 | G6: =IFERROR(((VLOOKUP(B6,'Origem '!$A$1:$F$1665,6,0)*'Mark Up '!$C$2)),"X") -> 13518.12 | H6: =IFERROR(((VLOOKUP(B6,'Origem '!$A$1:$H$1665,7,0)*'Mark Up '!$C$2)),"X") -> 14534.52
A7: MACAU | B7: 10249-4 | C7: Carrinho de Chá Macau (se laca brilho, somente c/ VD) | D7: 0,82 x 0,36 x 0,82 | E7: =IFERROR(((VLOOKUP(B7,'Origem '!$A$1:$D$1665,4,0)*'Mark Up '!$C$2)),"X") -> 7793.94 | F7: =IFERROR(((VLOOKUP(B7,'Origem '!$A$1:$E$1665,5,0)*'Mark Up '!$C$2)),"X") -> 8773.38 | G7: =IFERROR(((VLOOKUP(B7,'Origem '!$A$1:$F$1665,6,0)*'Mark Up '!$C$2)),"X") -> 9882.18 | H7: =IFERROR(((VLOOKUP(B7,'Origem '!$A$1:$H$1665,7,0)*'Mark Up '!$C$2)),"X") -> 10621.38
A8: QUIOS | B8: 11760-4 | C8: Carrinho de Chá QUIOS (se laca brilho, somente c/ VD) | D8: 0,80 x 0,36 x 0,82 | E8: =IFERROR(((VLOOKUP(B8,'Origem '!$A$1:$D$1665,4,0)*'Mark Up '!$C$2)),"X") -> 7137.9 | F8: =IFERROR(((VLOOKUP(B8,'Origem '!$A$1:$E$1665,5,0)*'Mark Up '!$C$2)),"X") -> 7909.44 | G8: =IFERROR(((VLOOKUP(B8,'Origem '!$A$1:$F$1665,6,0)*'Mark Up '!$C$2)),"X") -> 8339.1 | H8: =IFERROR(((VLOOKUP(B8,'Origem '!$A$1:$H$1665,7,0)*'Mark Up '!$C$2)),"X") -> 8814.96
A9: VANCOUVER | B9: 10019-18 | C9: Carrinho de Chá Vancouver (se laca brilho somente c/ VD) - (Vidro somente no tampo superior) | D9: 2,12 x 0,56 x 0,80 | E9: =IFERROR(((VLOOKUP(B9,'Origem '!$A$1:$D$1665,4,0)*'Mark Up '!$C$2)),"X") -> 19011.3 | F9: =IFERROR(((VLOOKUP(B9,'Origem '!$A$1:$E$1665,5,0)*'Mark Up '!$C$2)),"X") -> 20503.56 | G9: =IFERROR(((VLOOKUP(B9,'Origem '!$A$1:$F$1665,6,0)*'Mark Up '!$C$2)),"X") -> 23363.34 | H9: =IFERROR(((VLOOKUP(B9,'Origem '!$A$1:$H$1665,7,0)*'Mark Up '!$C$2)),"X") -> 24869.46

Sheet Gaveteiros
C1: GAVETEIROS | I1: AMBIENTADAS
A2: COLEÇÃO | B2: REF | C2: DESCRIÇÃO | D2: COMP X PROF X ALT | E2: Em caso de cores diferentes, utilizar preço de maior valor
E3: COLUNA 1 | F3: COLUNA 2 | G3: COLUNA 3 | H3: COLUNA 4
E4: LACA LISA BRAZIL ( COM OU SEM VIDRO PINTADO) | F4: - CARVALHO CLARO - CARVALHO NATURAL - CARVALHO LAVADO - CARV. EBANIZADO - IMBUIA CLARA * ACRESCENTAR 12% SE COM VIDRO PINTADO | G4: - NOGUEIRA - NOGUEIRA NATURAL - LOURO FREIJÓ - LOURO FREIJÓ NATURAL - LACA METALIZADA BRAZIL - CARV. ÔNIX METALIZADO - CARV. N109 METALIZADO - CARV. ALBANIZADO - CARV. H155 FOSCO - CONCRETO (SOMENTE SEM VIDRO) | H4: - PAU FERRO
E5: OBS. O ACABAMENTO DO METAL NÃO INFLUENCIARÁ NO VALOR DOS GAVETEIROS
A6: CAIRO | B6: 11880-0 | C6: Gaveteiro Cairo (2 gav.;c/ corrediça toque), pés metal | D6: 0,50 x 0,45 x 0,60 | E6: =IFERROR(((VLOOKUP(B6,'Origem '!$A$1:$D$1665,4,0)*'Mark Up '!$C$2)),"X") -> 8089.62 | F6: =IFERROR(((VLOOKUP(B6,'Origem '!$A$1:$E$1665,5,0)*'Mark Up '!$C$2)),"X") -> 10214.82 | G6: =IFERROR(((VLOOKUP(B6,'Origem '!$A$1:$F$1665,6,0)*'Mark Up '!$C$2)),"X") -> 11060.28 | H6: =IFERROR(((VLOOKUP(B6,'Origem '!$A$1:$H$1665,7,0)*'Mark Up '!$C$2)),"X") -> 11854.92
B7: 11880-2 | C7: Gaveteiro Cairo (2 gav.;c/ corrediça toque), pés metal | D7: 0,70 x 0,45 x 0,60 | E7: =IFERROR(((VLOOKUP(B7,'Origem '!$A$1:$D$1665,4,0)*'Mark Up '!$C$2)),"X") -> 9702 | F7: =IFERROR(((VLOOKUP(B7,'Origem '!$A$1:$E$1665,5,0)*'Mark Up '!$C$2)),"X") -> 11425.26 | G7: =IFERROR(((VLOOKUP(B7,'Origem '!$A$1:$F$1665,6,0)*'Mark Up '!$C$2)),"X") -> 12510.96 | H7: =IFERROR(((VLOOKUP(B7,'Origem '!$A$1:$H$1665,7,0)*'Mark Up '!$C$2)),"X") -> 13490.4
A8: LOS ANGELES | B8: 11042-0 | C8: Gaveteiro Los Angeles (2 gav.;c/ pux.cava), pés metal | D8: 0,50 x 0,45 x 0,60 | E8: =IFERROR(((VLOOKUP(B8,'Origem '!$A$1:$D$1665,4,0)*'Mark Up '!$C$2)),"X") -> 6777.54 | F8: =IFERROR(((VLOOKUP(B8,'Origem '!$A$1:$E$1665,5,0)*'Mark Up '!$C$2)),"X") -> 8713.32 | G8: =IFERROR(((VLOOKUP(B8,'Origem '!$A$1:$F$1665,6,0)*'Mark Up '!$C$2)),"X") -> 9549.54 | H8: =IFERROR(((VLOOKUP(B8,'Origem '!$A$1:$H$1665,7,0)*'Mark Up '!$C$2)),"X") -> 9942.24
B9: 11042-2 | C9: Gaveteiro Los Angeles (2 gav.;c/ pux.cava), pés metal | D9: 0,70 x 0,45 x 0,60 | E9: =IFERROR(((VLOOKUP(B9,'Origem '!$A$1:$D$1665,4,0)*'Mark Up '!$C$2)),"X") -> 7701.54 | F9: =IFERROR(((VLOOKUP(B9,'Origem '!$A$1:$E$1665,5,0)*'Mark Up '!$C$2)),"X") -> 10039.26 | G9: =IFERROR(((VLOOKUP(B9,'Origem '!$A$1:$F$1665,6,0)*'Mark Up '!$C$2)),"X") -> 11004.84 | H9: =IFERROR(((VLOOKUP(B9,'Origem '!$A$1:$H$1665,7,0)*'Mark Up '!$C$2)),"X") -> 11531.52
A10: MILETO | B10: 11860-0 | C10: Gaveteiro Mileto C/ MARCHETARIA (2 gav.;c/ pux.cava), pés metal | D10: 0,50 x 0,47 x 0,60 | E10: =IFERROR(((VLOOKUP(B10,'Origem '!$A$1:$D$1665,4,0)*'Mark Up '!$C$2)),"X") -> 7752.36 | F10: =IFERROR(((VLOOKUP(B10,'Origem '!$A$1:$E$1665,5,0)*'Mark Up '!$C$2)),"X") -> 9383.22 | G10: =IFERROR(((VLOOKUP(B10,'Origem '!$A$1:$F$1665,6,0)*'Mark Up '!$C$2)),"X") -> 10173.24 | H10: =IFERROR(((VLOOKUP(B10,'Origem '!$A$1:$H$1665,7,0)*'Mark Up '!$C$2)),"X") -> 10408.86
B11: 11860-2 | C11: Gaveteiro Mileto C/ MARCHETARIA (2 gav.;c/ pux.cava), pés metal | D11: 0,70 x 0,47 x 0,60 | E11: =IFERROR(((VLOOKUP(B11,'Origem '!$A$1:$D$1665,4,0)*'Mark Up '!$C$2)),"X") -> 8911.98 | F11: =IFERROR(((VLOOKUP(B11,'Origem '!$A$1:$E$1665,5,0)*'Mark Up '!$C$2)),"X") -> 10898.58 | G11: =IFERROR(((VLOOKUP(B11,'Origem '!$A$1:$F$1665,6,0)*'Mark Up '!$C$2)),"X") -> 11873.4 | H11: =IFERROR(((VLOOKUP(B11,'Origem '!$A$1:$H$1665,7,0)*'Mark Up '!$C$2)),"X") -> 12192.18
A12: RHONE | B12: 11152-0 | C12: Gaveteiro Rhone (1 gav.;c/ pux.cava), pés metal (se laca brilho somente c/ VD) | D12: 0,54 x 0,47 x 0,60 | E12: =IFERROR(((VLOOKUP(B12,'Origem '!$A$1:$D$1665,4,0)*'Mark Up '!$C$2)),"X") -> 7576.8 | F12: =IFERROR(((VLOOKUP(B12,'Origem '!$A$1:$E$1665,5,0)*'Mark Up '!$C$2)),"X") -> 9064.44 | G12: =IFERROR(((VLOOKUP(B12,'Origem '!$A$1:$F$1665,6,0)*'Mark Up '!$C$2)),"X") -> 10057.74 | H12: =IFERROR(((VLOOKUP(B12,'Origem '!$A$1:$H$1665,7,0)*'Mark Up '!$C$2)),"X") -> 10704.54
B13: 11152-2 | C13: Gaveteiro Rhone (1 gav.;c/ pux.cava), pés metal (se laca brilho somente c/ VD) | D13: 0,74 x 0,47 x 0,60 | E13: =IFERROR(((VLOOKUP(B13,'Origem '!$A$1:$D$1665,4,0)*'Mark Up '!$C$2)),"X") -> 8228.22 | F13: =IFERROR(((VLOOKUP(B13,'Origem '!$A$1:$E$1665,5,0)*'Mark Up '!$C$2)),"X") -> 9868.32 | G13: =IFERROR(((VLOOKUP(B13,'Origem '!$A$1:$F$1665,6,0)*'Mark Up '!$C$2)),"X") -> 11138.82 | H13: =IFERROR(((VLOOKUP(B13,'Origem '!$A$1:$H$1665,7,0)*'Mark Up '!$C$2)),"X") -> 12109.02
A14: SICILIANO | B14: 7261-0 | C14: Gaveteiro Siciliano (1 gav.;c/ pux.cava), pés metal | D14: 0,50 x 0,45 x 0,60 | E14: =IFERROR(((VLOOKUP(B14,'Origem '!$A$1:$D$1665,4,0)*'Mark Up '!$C$2)),"X") -> 6879.18 | F14: =IFERROR(((VLOOKUP(B14,'Origem '!$A$1:$E$1665,5,0)*'Mark Up '!$C$2)),"X") -> 7706.16 | G14: =IFERROR(((VLOOKUP(B14,'Origem '!$A$1:$F$1665,6,0)*'Mark Up '!$C$2)),"X") -> 8413.02 | H14: =IFERROR(((VLOOKUP(B14,'Origem '!$A$1:$H$1665,7,0)*'Mark Up '!$C$2)),"X") -> 8925.84
B15: 7261-2 | C15: Gaveteiro Siciliano (1 gav.;c/ pux.cava), pés metal | D15: 0,70 x 0,45 x 0,60 | E15: =IFERROR(((VLOOKUP(B15,'Origem '!$A$1:$D$1665,4,0)*'Mark Up '!$C$2)),"X") -> 7461.3 | F15: =IFERROR(((VLOOKUP(B15,'Origem '!$A$1:$E$1665,5,0)*'Mark Up '!$C$2)),"X") -> 8500.8 | G15: =IFERROR(((VLOOKUP(B15,'Origem '!$A$1:$F$1665,6,0)*'Mark Up '!$C$2)),"X") -> 9290.82 | H15: =IFERROR(((VLOOKUP(B15,'Origem '!$A$1:$H$1665,7,0)*'Mark Up '!$C$2)),"X") -> 9928.38
A16: SICILIANO | B16: 7262-0 | C16: Gaveteiro Siciliano (2 gav.;c/ pux.cava), pés metal | D16: 0,50 x 0,45 x 0,59 | E16: =IFERROR(((VLOOKUP(B16,'Origem '!$A$1:$D$1665,4,0)*'Mark Up '!$C$2)),"X") -> 7659.96 | F16: =IFERROR(((VLOOKUP(B16,'Origem '!$A$1:$E$1665,5,0)*'Mark Up '!$C$2)),"X") -> 9674.28 | G16: =IFERROR(((VLOOKUP(B16,'Origem '!$A$1:$F$1665,6,0)*'Mark Up '!$C$2)),"X") -> 11046.42 | H16: =IFERROR(((VLOOKUP(B16,'Origem '!$A$1:$H$1665,7,0)*'Mark Up '!$C$2)),"X") -> 11522.28
B17: 7262-2 | C17: Gaveteiro Siciliano (2 gav.;c/ pux.cava), pés metal | D17: 0,70 x 0,45 x 0,59 | E17: =IFERROR(((VLOOKUP(B17,'Origem '!$A$1:$D$1665,4,0)*'Mark Up '!$C$2)),"X") -> 8805.72 | F17: =IFERROR(((VLOOKUP(B17,'Origem '!$A$1:$E$1665,5,0)*'Mark Up '!$C$2)),"X") -> 10852.38 | G17: =IFERROR(((VLOOKUP(B17,'Origem '!$A$1:$F$1665,6,0)*'Mark Up '!$C$2)),"X") -> 12936 | H17: =IFERROR(((VLOOKUP(B17,'Origem '!$A$1:$H$1665,7,0)*'Mark Up '!$C$2)),"X") -> 13416.48
A18: TÓQUIO | B18: 11032-0 | C18: Gaveteiro Tóquio (2 gav.;c/ puxador), pés metal | D18: 0,50 x 0,45 x 0,60 | E18: =IFERROR(((VLOOKUP(B18,'Origem '!$A$1:$D$1665,4,0)*'Mark Up '!$C$2)),"X") -> 6518.82 | F18: =IFERROR(((VLOOKUP(B18,'Origem '!$A$1:$E$1665,5,0)*'Mark Up '!$C$2)),"X") -> 8066.52 | G18: =IFERROR(((VLOOKUP(B18,'Origem '!$A$1:$F$1665,6,0)*'Mark Up '!$C$2)),"X") -> 8828.82 | H18: =IFERROR(((VLOOKUP(B18,'Origem '!$A$1:$H$1665,7,0)*'Mark Up '!$C$2)),"X") -> 9152.22
B19: 11032-2 | C19: Gaveteiro Tóquio (2 gav.;c/ puxador), pés metal | D19: 0,70 x 0,45 x 0,60 | E19: =IFERROR(((VLOOKUP(B19,'Origem '!$A$1:$D$1665,4,0)*'Mark Up '!$C$2)),"X") -> 7031.64 | F19: =IFERROR(((VLOOKUP(B19,'Origem '!$A$1:$E$1665,5,0)*'Mark Up '!$C$2)),"X") -> 9360.12 | G19: =IFERROR(((VLOOKUP(B19,'Origem '!$A$1:$F$1665,6,0)*'Mark Up '!$C$2)),"X") -> 10247.16 | H19: =IFERROR(((VLOOKUP(B19,'Origem '!$A$1:$H$1665,7,0)*'Mark Up '!$C$2)),"X") -> 10709.16
A20: TRENTO | B20: 10742-5 | C20: Gaveteiro Trento (1 gav. c/ pux.), pés mad. (se laca brilho somente c/ VD) | D20: 0,45 Ø 0,61 | E20: =IFERROR(((VLOOKUP(B20,'Origem '!$A$1:$D$1665,4,0)*'Mark Up '!$C$2)),"X") -> 6237 | F20: =IFERROR(((VLOOKUP(B20,'Origem '!$A$1:$E$1665,5,0)*'Mark Up '!$C$2)),"X") -> 7452.06 | G20: =IFERROR(((VLOOKUP(B20,'Origem '!$A$1:$F$1665,6,0)*'Mark Up '!$C$2)),"X") -> 8237.46 | H20: =IFERROR(((VLOOKUP(B20,'Origem '!$A$1:$H$1665,7,0)*'Mark Up '!$C$2)),"X") -> X
B21: 10742-6 | C21: Gaveteiro Trento (1 gav. c/ pux.), pés mad. (se laca brilho somente c/ VD) | D21: 0,54 Ø 0,61 | E21: =IFERROR(((VLOOKUP(B21,'Origem '!$A$1:$D$1665,4,0)*'Mark Up '!$C$2)),"X") -> 6352.5 | F21: =IFERROR(((VLOOKUP(B21,'Origem '!$A$1:$E$1665,5,0)*'Mark Up '!$C$2)),"X") -> 7586.04 | G21: =IFERROR(((VLOOKUP(B21,'Origem '!$A$1:$F$1665,6,0)*'Mark Up '!$C$2)),"X") -> 8473.08 | H21: =IFERROR(((VLOOKUP(B21,'Origem '!$A$1:$H$1665,7,0)*'Mark Up '!$C$2)),"X") -> X

Sheet Complementos
C1: COMPLEMENTOS | I1: AMBIENTADAS
A2: COLEÇÃO | B2: REF | C2: DESCRIÇÃO | D2: COMP X PROF X ALT | E2: Em caso de cores diferentes Base ou Tampo, utilizar preço de maior valor
E3: COLUNA 1 | F3: COLUNA 2 | G3: COLUNA 3 | H3: COLUNA 4
E4: LACA LISA BRAZIL ( COM OU SEM VIDRO PINTADO) | F4: - CARVALHO CLARO - CARVALHO NATURAL - CARVALHO LAVADO - CARV. EBANIZADO - IMBUIA CLARA * ACRESCENTAR 12% SE COM VIDRO PINTADO | G4: - NOGUEIRA - NOGUEIRA NATURAL - LOURO FREIJÓ - LOURO FREIJÓ NATURAL - LACA METALIZADA BRAZIL - CARV. ÔNIX METALIZADO - CARV. N109 METALIZADO - CARV. ALBANIZADO - CARV. H155 FOSCO - CONCRETO (SOMENTE SEM VIDRO) | H4: - PAU FERRO
E5: OBS. O ACABAMENTO DO METAL NÃO INFLUENCIARÁ NO VALOR DO MÓVEL
A6: CARTAGENA | B6: 1410-0 | C6: Cristaleira Cartagena (4 prat;2 luminárias) | D6: 0,82 x 0,37 x 1,82 | E6: =IFERROR(((VLOOKUP(B6,'Origem '!$A$1:$D$1665,4,0)*'Mark Up '!$C$2)),"X") -> 19930.68 | F6: =IFERROR(((VLOOKUP(B6,'Origem '!$A$1:$E$1665,5,0)*'Mark Up '!$C$2)),"X") -> 20674.5 | G6: =IFERROR(((VLOOKUP(B6,'Origem '!$A$1:$F$1665,6,0)*'Mark Up '!$C$2)),"X") -> 24181.08 | H6: =IFERROR(((VLOOKUP(B6,'Origem '!$A$1:$H$1665,7,0)*'Mark Up '!$C$2)),"X") -> 26865.3
B7: 1410-0Sl | C7: Cristaleira Cartagena (4 prat;s/iluminação) | D7: 0,82 x 0,37 x 1,82 | E7: =IFERROR(((VLOOKUP(B7,'Origem '!$A$1:$D$1665,4,0)*'Mark Up '!$C$2)),"X") -> 18775.68 | F7: =IFERROR(((VLOOKUP(B7,'Origem '!$A$1:$E$1665,5,0)*'Mark Up '!$C$2)),"X") -> 20508.18 | G7: =IFERROR(((VLOOKUP(B7,'Origem '!$A$1:$F$1665,6,0)*'Mark Up '!$C$2)),"X") -> 23381.82 | H7: =IFERROR(((VLOOKUP(B7,'Origem '!$A$1:$H$1665,7,0)*'Mark Up '!$C$2)),"X") -> 25982.88
B8: 1410-2SI | C8: Cristaleira Cartagena (2 prat;s/iluminação) | D8: 0,82 x 0,37 x 1,29 | E8: =IFERROR(((VLOOKUP(B8,'Origem '!$A$1:$D$1665,4,0)*'Mark Up '!$C$2)),"X") -> 13952.4 | F8: =IFERROR(((VLOOKUP(B8,'Origem '!$A$1:$E$1665,5,0)*'Mark Up '!$C$2)),"X") -> 15680.28 | G8: =IFERROR(((VLOOKUP(B8,'Origem '!$A$1:$F$1665,6,0)*'Mark Up '!$C$2)),"X") -> 17976.42 | H8: =IFERROR(((VLOOKUP(B8,'Origem '!$A$1:$H$1665,7,0)*'Mark Up '!$C$2)),"X") -> 19972.26
B9: 1411-0 | C9: Cristaleira Cartagena (1 porta/4 prat;1 luminária) | D9: 0,42 x 0,37 x 1,82 | E9: =IFERROR(((VLOOKUP(B9,'Origem '!$A$1:$D$1665,4,0)*'Mark Up '!$C$2)),"X") -> 14548.38 | F9: =IFERROR(((VLOOKUP(B9,'Origem '!$A$1:$E$1665,5,0)*'Mark Up '!$C$2)),"X") -> 15047.34 | G9: =IFERROR(((VLOOKUP(B9,'Origem '!$A$1:$F$1665,6,0)*'Mark Up '!$C$2)),"X") -> 17204.88 | H9: =IFERROR(((VLOOKUP(B9,'Origem '!$A$1:$H$1665,7,0)*'Mark Up '!$C$2)),"X") -> 19112.94
B10: 1411-0Sl | C10: Cristaleira Cartagena (1 porta/4 prat;s/iluminação) | D10: 0,42 x 0,37 x 1,82 | E10: =IFERROR(((VLOOKUP(B10,'Origem '!$A$1:$D$1665,4,0)*'Mark Up '!$C$2)),"X") -> 13781.46 | F10: =IFERROR(((VLOOKUP(B10,'Origem '!$A$1:$E$1665,5,0)*'Mark Up '!$C$2)),"X") -> 14285.04 | G10: =IFERROR(((VLOOKUP(B10,'Origem '!$A$1:$F$1665,6,0)*'Mark Up '!$C$2)),"X") -> 16410.24 | H10: =IFERROR(((VLOOKUP(B10,'Origem '!$A$1:$H$1665,7,0)*'Mark Up '!$C$2)),"X") -> 18230.52
A11: CLAUS | B11: 10440-2 | C11: Bandeja Café Claus, Tp Garrafa (se laca brilho somente c/ VD) | D11: 0,51 x 0,31 x 0,05 | E11: =IFERROR(((VLOOKUP(B11,'Origem '!$A$1:$D$1665,4,0)*'Mark Up '!$C$2)),"X") -> 2079 | F11: =IFERROR(((VLOOKUP(B11,'Origem '!$A$1:$E$1665,5,0)*'Mark Up '!$C$2)),"X") -> 2102.1 | G11: =IFERROR(((VLOOKUP(B11,'Origem '!$A$1:$F$1665,6,0)*'Mark Up '!$C$2)),"X") -> 2577.96 | H11: =IFERROR(((VLOOKUP(B11,'Origem '!$A$1:$H$1665,7,0)*'Mark Up '!$C$2)),"X") -> 2841.3
A12: ESPARTA | B12: 9705-0 | C12: Cabideiro Esparta | D12: 0,40 X 0,40 X 1,70 | E12: =IFERROR(((VLOOKUP(B12,'Origem '!$A$1:$D$1665,4,0)*'Mark Up '!$C$2)),"X") -> 4652.34 | F12: =IFERROR(((VLOOKUP(B12,'Origem '!$A$1:$E$1665,5,0)*'Mark Up '!$C$2)),"X") -> 4786.32 | G12: =IFERROR(((VLOOKUP(B12,'Origem '!$A$1:$F$1665,6,0)*'Mark Up '!$C$2)),"X") -> 5058.9 | H12: =IFERROR(((VLOOKUP(B12,'Origem '!$A$1:$H$1665,7,0)*'Mark Up '!$C$2)),"X") -> X
A13: PARLA | B13: 11070-3 | C13: Banco Parla (tp oblongo chanfrado), pés mad. (somente sem VD) | D13: 1,60 x 0,45 x 0,42 | E13: =IFERROR(((VLOOKUP(B13,'Origem '!$A$1:$D$1665,4,0)*'Mark Up '!$C$2)),"X") -> 5964.42 | F13: =IFERROR(((VLOOKUP(B13,'Origem '!$A$1:$E$1665,5,0)*'Mark Up '!$C$2)),"X") -> 7017.78 | G13: =IFERROR(((VLOOKUP(B13,'Origem '!$A$1:$F$1665,6,0)*'Mark Up '!$C$2)),"X") -> 8172.78 | H13: =IFERROR(((VLOOKUP(B13,'Origem '!$A$1:$H$1665,7,0)*'Mark Up '!$C$2)),"X") -> X
B14: 11070-4 | C14: Banco Parla (tp oblongo chanfrado), pés mad. (somente sem VD) | D14: 1,80 x 0,45 x 0,42 | E14: =IFERROR(((VLOOKUP(B14,'Origem '!$A$1:$D$1665,4,0)*'Mark Up '!$C$2)),"X") -> 6172.32 | F14: =IFERROR(((VLOOKUP(B14,'Origem '!$A$1:$E$1665,5,0)*'Mark Up '!$C$2)),"X") -> 7318.08 | G14: =IFERROR(((VLOOKUP(B14,'Origem '!$A$1:$F$1665,6,0)*'Mark Up '!$C$2)),"X") -> 8547 | H14: =IFERROR(((VLOOKUP(B14,'Origem '!$A$1:$H$1665,7,0)*'Mark Up '!$C$2)),"X") -> X
B15: 11070-5 | C15: Banco Parla (tp oblongo chanfrado), pés mad. (somente sem VD) | D15: 2,00 x 0,45 x 0,42 | E15: =IFERROR(((VLOOKUP(B15,'Origem '!$A$1:$D$1665,4,0)*'Mark Up '!$C$2)),"X") -> 6611.22 | F15: =IFERROR(((VLOOKUP(B15,'Origem '!$A$1:$E$1665,5,0)*'Mark Up '!$C$2)),"X") -> 7877.1 | G15: =IFERROR(((VLOOKUP(B15,'Origem '!$A$1:$F$1665,6,0)*'Mark Up '!$C$2)),"X") -> 8981.28 | H15: =IFERROR(((VLOOKUP(B15,'Origem '!$A$1:$H$1665,7,0)*'Mark Up '!$C$2)),"X") -> X
