Workbook

Sheet Capa Tabela
A4: ACABAMENTOS:
A5: VIDROS:
A7: * Para colocar VIDRO EXTRA CLEAR, ESPELHO PRATA OU ESPELHO BRONZE, acrescentar ao móvel valor descrito na ultima página. * O vidro utilizado nos móveis é comum, pode haver diferença de tonalidade;
A8: * Vidros comum 4mm e extra clear 4mm medida maxima de 3,20x1,30 ou redondos e quadrados de 2,00x2,00
A9: * Vidros comum 6mm medida maxima de 3,59x1,50 ou redondos e quadrados de 2,00x2,00(sob consulta) esta espessura é mais esverdeado que o vidro comum 4mm
A10: OBS: A Nogueira a Canela o Carvalho e o Louro Freijó somente são fornecidos em laminados, as bases de madeira maciça serão produzidas em madeira tingida em cor semelhante.
A11: OBS: Os metais presentes nas peças podem ser feitos em qualquer cor de LACA PADRÃO BRILHO OU FOSCO (Informar no pedido)

Sheet Cores Capa
A1: LACAS LISAS BRAZIL | C1: LACAS METALIZADAS BRAZIL | E1: MADEIRAS TINGIDAS | G1: CARVALHOS TINGIDOS | I1: OUTRAS CORES
A2: Areia H109 Brilho / Fosco Branco Brilho / Fosco Cinza Claro H155 Brilho / Fosco Crômo Fosco Fendi N109 Brilho / Fosco Preto Fosco LACA CONCRETO BRAZIL Concreto (Somente s/ Vidro) | C2: Bronze Chumbo N109 Ônix METAIS Aço Cortein New Golden Preto Fosco Ônix Metalizado N109 Metalizado | E2: Imbuia Clara LÂMINAS Carvalho Canela Louro Freijó Nogueira Pau Ferro | G2: Carvalho Claro Carvalho Ebanizado Carvalho Lavado Carvalho Natural CARVALHOS LAQUEADO Albanizado Cinza Claro (H155 Fosco) CARVALHOS METALIZADOS N109 Metalizado Ônix Metalizado | I2: Lacas Especiais Sayerlack
A4: OBS: Lacas especiais Sayerlack Brilho ou Fosca acrescentar 15% sobre a terceira coluna da tabela, se for laca especial metalizada ou perolizada consultar a empresa.

Sheet Garantia

Sheet Mark Up 
A1: Local onde faz a multiplicação nas colunas da tabelas, se precisar dobrar o valor mudar o numero 1 para 2, se precisar triplicar o valor trocar numero 1 para 3 e por assim adiante.
A2: MARK UP | C2: 4.62

Sheet Origem 
A1: 10040-0 | B1: Mesa Jantar Kobe (Tampo Orgânico) " somente s/VIDRO" | C1: 1,35 Ø 0,76 alt | D1: 2854 | E1: 3270 | F1: 3270 | G1: 3532 | H1: X | J1: =D1-E1 -> -416 | K1: =E1-F1 -> 0 | L1: =F1-G1 -> -262 | M1: =G1-H1 -> #VALUE!
A2: 10040-1 | B2: Mesa Jantar Kobe (Tampo Orgânico) " somente s/VIDRO" | C2: 1,48 Ø 0,76 alt | D2: 3088 | E2: 3565 | F2: 3565 | G2: 3880 | H2: X | J2: =D2-E2 -> -477 | K2: =E2-F2 -> 0 | L2: =F2-G2 -> -315 | M2: =G2-H2 -> #VALUE!
A3: 10040-2 | B3: Mesa Jantar Kobe (Tampo Orgânico) " somente s/VIDRO" | C3: 1,60 Ø 0,76 alt | D3: 3238 | E3: 3802 | F3: 3802 | G3: 4171 | H3: X | J3: =D3-E3 -> -564 | K3: =E3-F3 -> 0 | L3: =F3-G3 -> -369 | M3: =G3-H3 -> #VALUE!
A4: 10040-3 | B4: Mesa Jantar Kobe (Tampo Orgânico) " somente s/VIDRO" | C4: 1,80 Ø 0,76 alt | D4: 3611 | E4: 4203 | F4: 4203 | G4: 4675 | H4: X | J4: =D4-E4 -> -592 | K4: =E4-F4 -> 0 | L4: =F4-G4 -> -472 | M4: =G4-H4 -> #VALUE!
A5: 9940-9 | B5: Mesa Jantar Salta TAMPO CANTO MOEDA | C5: 2,40 x 1,10 x 0,76 | D5: 5889 | E5: 6975 | F5: 7376 | G5: 7527 | H5: 7712 | J5: =D5-E5 -> -1086 | K5: =E5-F5 -> -401 | L5: =F5-G5 -> -151 | M5: =G5-H5 -> -185
A6: 9940-12 | B6: Mesa Jantar Salta TAMPO CANTO MOEDA | C6: 2,70 x 1,20 x 0,76 | D6: 6543 | E6: 7482 | F6: 8095 | G6: 8238 | H6: 8425 | J6: =D6-E6 -> -939 | K6: =E6-F6 -> -613 | L6: =F6-G6 -> -143 | M6: =G6-H6 -> -187
A7: 9940-13 | B7: Mesa Jantar Salta TAMPO CANTO MOEDA | C7: 3,00 x 1,20 x 0,76 | D7: 8168 | E7: 9529 | F7: 10199 | G7: 10370 | H7: 10574 | J7: =D7-E7 -> -1361 | K7: =E7-F7 -> -670 | L7: =F7-G7 -> -171 | M7: =G7-H7 -> -204
A8: 9940-14 | B8: Mesa Jantar Salta TAMPO CANTO MOEDA | C8: 3,20 x 1,20 x 0,76 | D8: 8374 | E8: 9750 | F8: 10468 | G8: 10641 | H8: 10865 | J8: =D8-E8 -> -1376 | K8: =E8-F8 -> -718 | L8: =F8-G8 -> -173 | M8: =G8-H8 -> -224
A9: 9940-16 | B9: Mesa Jantar Salta (tp reto) (se com vidro, vidro bi-partido) TAMPO CANTO MOEDA | C9: 3,50 x 1,20 x 0,76 | D9: 9871 | E9: 11279 | F9: 11991 | G9: 12194 | H9: 12431 | J9: =D9-E9 -> -1408 | K9: =E9-F9 -> -712 | L9: =F9-G9 -> -203 | M9: =G9-H9 -> -237
A10: 9940-18 | B10: Mesa Jantar Salta (tp reto) (se com vidro, vidro bi-partido) TAMPO CANTO MOEDA | C10: 3,70 x 1,20 x 0,76 | D10: 10399 | E10: 11833 | F10: 12887 | G10: 13175 | H10: 13402 | J10: =D10-E10 -> -1434 | K10: =E10-F10 -> -1054 | L10: =F10-G10 -> -288 | M10: =G10-H10 -> -227
A11: 9940-20 | B11: Mesa Jantar Salta (tp reto) (se com vidro, vidro bi-partido) TAMPO CANTO MOEDA | C11: 4,00 x 1,20 x 0,76 | D11: 11091 | E11: 12458 | F11: 13447 | G11: 13752 | H11: 13986 | J11: =D11-E11 -> -1367 | K11: =E11-F11 -> -989 | L11: =F11-G11 -> -305 | M11: =G11-H11 -> -234
A12: 11200-9 | B12: MESA JANTAR TOMIE "TP OBLONGO" | C12: 2,40 x 1,20 x 0,76 | D12: 7517 | E12: 8307 | F12: 8949 | G12: 9178 | H12: 9402 | J12: =D12-E12 -> -790 | K12: =E12-F12 -> -642 | L12: =F12-G12 -> -229 | M12: =G12-H12 -> -224
A13: 11200-12 | B13: MESA JANTAR TOMIE "TP OBLONGO" | C13: 2,70 x 1,20 x 0,76 | D13: 8031 | E13: 8706 | F13: 9709 | G13: 9906 | H13: 10156 | J13: =D13-E13 -> -675 | K13: =E13-F13 -> -1003 | L13: =F13-G13 -> -197 | M13: =G13-H13 -> -250
A14: 11200-13 | B14: MESA JANTAR TOMIE "TP OBLONGO" | C14: 3,00 x 1,20 x 0,76 | D14: 9184 | E14: 10054 | F14: 10799 | G14: 10998 | H14: 11257 | J14: =D14-E14 -> -870 | K14: =E14-F14 -> -745 | L14: =F14-G14 -> -199 | M14: =G14-H14 -> -259
A15: 11200-14 | B15: MESA JANTAR TOMIE "TP OBLONGO" | C15: 3,20 x 1,20 x 0,76 | D15: 9596 | E15: 10414 | F15: 11156 | G15: 11398 | H15: 11596 | J15: =D15-E15 -> -818 | K15: =E15-F15 -> -742 | L15: =F15-G15 -> -242 | M15: =G15-H15 -> -198
A16: 11200-16 | B16: MESA JANTAR TOMIE (SE COM VIDRO, VIDRO BI-PARTIDO)"TP OBLONGO SEUL" | C16: 3,50 x 1,20 x 0,76 | D16: 11295 | E16: 12064 | F16: 13068 | G16: 13356 | H16: 13652 | J16: =D16-E16 -> -769 | K16: =E16-F16 -> -1004 | L16: =F16-G16 -> -288 | M16: =G16-H16 -> -296
... A18: 11200-20 | B18: MESA JANTAR TOMIE (SE COM VIDRO, VIDRO BI-PARTIDO)"TP OBLONGO SEUL" | C18: 4,00 x 1,20 x 0,76 | D18: 12230 | E18: 13335 | F18: 14051 | G18: 14374 | H18: 14685 | J18: =D18-E18 -> -1105 | K18: =E18-F18 -> -716 | L18: =F18-G18 -> -323 | M18: =G18-H18 -> -311
A19: 10010-8 | B19: Mesa de Jantar Monza TAMPO CANTO MOEDA | C19: 2,20 x 1,10 x 0,76 | D19: 5280 | E19: 5252 | F19: 5466 | G19: 5577 | H19: X | J19: =D19-E19 -> 28 | K19: =E19-F19 -> -214 | L19: =F19-G19 -> -111 | M19: =G19-H19 -> #VALUE!
A20: 10010-9 | B20: Mesa de Jantar Monza TAMPO CANTO MOEDA | C20: 2,40 x 1,10 x 0,76 | D20: 5549 | E20: 5365 | F20: 5766 | G20: 5883 | H20: X | J20: =D20-E20 -> 184 | K20: =E20-F20 -> -401 | L20: =F20-G20 -> -117 | M20: =G20-H20 -> #VALUE!
A21: 10010-12 | B21: Mesa de Jantar Monza TAMPO CANTO MOEDA | C21: 2,70 x 1,20 x 0,76 | D21: 6440 | E21: 6161 | F21: 6775 | G21: 6913 | H21: X | J21: =D21-E21 -> 279 | K21: =E21-F21 -> -614 | L21: =F21-G21 -> -138 | M21: =G21-H21 -> #VALUE!
A22: 10010-13 | B22: Mesa de Jantar Monza TAMPO CANTO MOEDA | C22: 3,00 x 1,20 x 0,76 | D22: 7573 | E22: 7512 | F22: 8182 | G22: 8348 | H22: X | J22: =D22-E22 -> 61 | K22: =E22-F22 -> -670 | L22: =F22-G22 -> -166 | M22: =G22-H22 -> #VALUE!
A23: 10010-14 | B23: Mesa de Jantar Monza TAMPO CANTO MOEDA | C23: 3,20 x 1,20 x 0,76 | D23: 7779 | E23: 7732 | F23: 8450 | G23: 8622 | H23: X | J23: =D23-E23 -> 47 | K23: =E23-F23 -> -718 | L23: =F23-G23 -> -172 | M23: =G23-H23 -> #VALUE!
A24: 10050-8 | B24: Mesa de Jantar La Plata TAMPO CANTO MOEDA | C24: 2,20 x 1,10 x 0,76 | D24: 4949 | E24: 5191 | F24: 5500 | G24: 5882 | H24: 6053 | J24: =D24-E24 -> -242 | K24: =E24-F24 -> -309 | L24: =F24-G24 -> -382 | M24: =G24-H24 -> -171
A25: 10050-9 | B25: Mesa de Jantar La Plata TAMPO CANTO MOEDA | C25: 2,40 x 1,10 x 0,76 | D25: 5218 | E25: 5400 | F25: 5800 | G25: 6164 | H25: 6347 | J25: =D25-E25 -> -182 | K25: =E25-F25 -> -400 | L25: =F25-G25 -> -364 | M25: =G25-H25 -> -183
A26: 10050-12 | B26: Mesa de Jantar La Plata TAMPO CANTO MOEDA | C26: 2,70 x 1,20 x 0,76 | D26: 5922 | E26: 5957 | F26: 6571 | G26: 6932 | H26: 7110 | J26: =D26-E26 -> -35 | K26: =E26-F26 -> -614 | L26: =F26-G26 -> -361 | M26: =G26-H26 -> -178
A27: 10050-13 | B27: Mesa de Jantar La Plata TAMPO CANTO MOEDA | C27: 3,00 x 1,20 x 0,76 | D27: 7055 | E27: 7308 | F27: 7978 | G27: 8329 | H27: 8510 | J27: =D27-E27 -> -253 | K27: =E27-F27 -> -670 | L27: =F27-G27 -> -351 | M27: =G27-H27 -> -181
A28: 10050-14 | B28: Mesa de Jantar La Plata TAMPO CANTO MOEDA | C28: 3,20 x 1,20 x 0,76 | D28: 7261 | E28: 7527 | F28: 8246 | G28: 8600 | H28: 8781 | J28: =D28-E28 -> -266 | K28: =E28-F28 -> -719 | L28: =F28-G28 -> -354 | M28: =G28-H28 -> -181
A29: 11180-9 | B29: MESA DE JANTAR LESCHER | C29: 2,40 x 1,10 x 0,76 | D29: 12086 | E29: 11929 | F29: 12350 | G29: 12602 | H29: 12793 | J29: =D29-E29 -> 157 | K29: =E29-F29 -> -421 | L29: =F29-G29 -> -252 | M29: =G29-H29 -> -191
A30: 11180-12 | B30: MESA DE JANTAR LESCHER | C30: 2,70 x 1,20 x 0,76 | D30: 12601 | E30: 12461 | F30: 13106 | G30: 13373 | H30: 13576 | J30: =D30-E30 -> 140 | K30: =E30-F30 -> -645 | L30: =F30-G30 -> -267 | M30: =G30-H30 -> -203
A31: 11180-13 | B31: MESA DE JANTAR LESCHER | C31: 3,00 x 1,20 x 0,76 | D31: 13987 | E31: 13880 | F31: 14583 | G31: 14880 | H31: 15106 | J31: =D31-E31 -> 107 | K31: =E31-F31 -> -703 | L31: =F31-G31 -> -297 | M31: =G31-H31 -> -226
A32: 11180-14 | B32: MESA DE JANTAR LESCHER | C32: 3,20 x 1,20 x 0,76 | D32: 14205 | E32: 14111 | F32: 14864 | G32: 15167 | H32: 15397 | J32: =D32-E32 -> 94 | K32: =E32-F32 -> -753 | L32: =F32-G32 -> -303 | M32: =G32-H32 -> -230
A33: 11180-16 | B33: MESA DE JANTAR LESCHER | C33: 3,50 x 1,20 x 0,76 | D33: 17756 | E33: 17517 | F33: 18265 | G33: 18637 | H33: 18920 | J33: =D33-E33 -> 239 | K33: =E33-F33 -> -748 | L33: =F33-G33 -> -372 | M33: =G33-H33 -> -283
A34: 11180-18 | B34: MESA DE JANTAR LESCHER | C34: 3,70 x 1,20 x 0,76 | D34: 18289 | E34: 18099 | F34: 19207 | G34: 19598 | H34: 19896 | J34: =D34-E34 -> 190 | K34: =E34-F34 -> -1108 | L34: =F34-G34 -> -391 | M34: =G34-H34 -> -298
A35: 11180-20 | B35: MESA DE JANTAR LESCHER | C35: 4,00 x 1,20 x 0,76 | D35: 18965 | E35: 18755 | F35: 19793 | G35: 20196 | H35: 20503 | J35: =D35-E35 -> 210 | K35: =E35-F35 -> -1038 | L35: =F35-G35 -> -403 | M35: =G35-H35 -> -307
... A68: 10061-14 | B68: Mesa de Jantar Dijon TAMPO CANTO MOEDA, COM MARCHETARIA | C68: 3,20 x 1,20 x 0,76 | D68: 8492 | E68: 9103 | F68: 9900 | G68: 9913 | H68: 10071 | J68: =D68-E68 -> -611 | K68: =E68-F68 -> -797 | L68: =F68-G68 -> -13 | M68: =G68-H68 -> -158
A69: 10020-7 | B69: Mesa Jantar Elíptica Macaçar " somente s/VIDRO" | C69: 2,00 x 1,20 x 0,76 | D69: 3720 | E69: 4038 | F69: 4038 | G69: 4465 | H69: X | J69: =D69-E69 -> -318 | K69: =E69-F69 -> 0 | L69: =F69-G69 -> -427 | M69: =G69-H69 -> #VALUE!
A70: 10020-8 | B70: Mesa Jantar Elíptica Macaçar " somente s/VIDRO" | C70: 2,20 x 1,20 x 0,76 | D70: 4113 | E70: 4501 | F70: 4501 | G70: 4996 | H70: X | J70: =D70-E70 -> -388 | K70: =E70-F70 -> 0 | L70: =F70-G70 -> -495 | M70: =G70-H70 -> #VALUE!
A71: 10020-9 | B71: Mesa Jantar Elíptica Macaçar " somente s/VIDRO" | C71: 2,40 x 1,20 x 0,76 | D71: 4849 | E71: 4929 | F71: 4929 | G71: 5435 | H71: X | J71: =D71-E71 -> -80 | K71: =E71-F71 -> 0 | L71: =F71-G71 -> -506 | M71: =G71-H71 -> #VALUE!
A72: 10020-12 | B72: Mesa Jantar Elíptica Macaçar " somente s/VIDRO" | C72: 2,70 x 1,20 x 0,76 | D72: 5342 | E72: 5475 | F72: 5475 | G72: 6188 | H72: X | J72: =D72-E72 -> -133 | K72: =E72-F72 -> 0 | L72: =F72-G72 -> -713 | M72: =G72-H72 -> #VALUE!
A73: 10020-13 | B73: Mesa Jantar Elíptica Macaçar " somente s/VIDRO" | C73: 3,00 x 1,20 x 0,76 | D73: 6453 | E73: 6723 | F73: 6723 | G73: 7268 | H73: X | J73: =D73-E73 -> -270 | K73: =E73-F73 -> 0 | L73: =F73-G73 -> -545 | M73: =G73-H73 -> #VALUE!
...

Sheet Aparadores
C1: APARADORES | G1: LANÇAMENTO 2025 | K1: LANÇAMENTO 2025
A2: COLEÇÃO | B2: REF | C2: DESCRIÇÃO | D2: COMP X PROF X ALT | E2: Em caso de cores diferentes Base ou Tampo, utilizar preço de maior valor | I2: Em caso de cores diferentes Base ou Tampo, utilizar preço de maior valor
E3: COLUNA 1 | F3: COLUNA 2 | G3: COLUNA 3 | H3: COLUNA 4 | I3: COLUNA 1 | J3: COLUNA 2 | K3: COLUNA 3 | L3: COLUNA 4
E4: LACA LISA BRAZIL ( COM OU SEM VIDRO PINTADO) | F4: - CARVALHO CLARO - CARVALHO NATURAL - CARVALHO LAVADO - CARV. EBANIZADO - IMBUIA CLARA * ACRESCENTAR 12% SE COM VIDRO PINTADO | G4: - NOGUEIRA - NOGUEIRA NATURAL - LOURO FREIJÓ - LOURO FREIJÓ NATURAL - CANELA - LACA METALIZADA BRAZIL - CARV. ÔNIX METALIZADO - CARV. N109 METALIZADO - CARV. ALBANIZADO - CARV. H155 FOSCO - CONCRETO (SOMENTE SEM VIDRO) | H4: - PAU FERRO | I4: LACA LISA BRAZIL ( COM OU SEM VIDRO PINTADO) | J4: - CARVALHO CLARO - CARVALHO NATURAL - CARVALHO LAVADO - CARV. EBANIZADO - IMBUIA CLARA * ACRESCENTAR 12% SE COM VIDRO PINTADO | K4: - NOGUEIRA - NOGUEIRA NATURAL - LOURO FREIJÓ - LOURO FREIJÓ NATURAL - CANELA - LACA METALIZADA BRAZIL - CARV. ÔNIX METALIZADO - CARV. N109 METALIZADO - CARV. ALBANIZADO - CARV. H155 FOSCO - CONCRETO (SOMENTE SEM VIDRO) | L4: - PAU FERRO
E5: OBS. O ACABAMENTO DO METAL NÃO INFLUENCIARÁ NO VALOR DO APARADOR | I5: OBS. O ACABAMENTO DO METAL NÃO INFLUENCIARÁ NO VALOR DO APARADOR
A6: CILDO | B6: 11104-4 | C6: Aparador Cildo "SOMENTE SEM VIDRO" | D6: 2,00 X 0,50 X 0,76 | E6: =VLOOKUP(B6,'Origem '!$A$1:$D$181,4,0) -> 3610 | F6: =VLOOKUP(B6,'Origem '!$A$1:$E$181,5,0) -> 4295 | G6: =VLOOKUP(B6,'Origem '!$A$1:$F$181,6,0) -> 4755 | H6: =VLOOKUP(B6,'Origem '!$A$1:$G$181,7,0) -> 4958 | I6: =E6*'Mark Up '!$C$2 -> 16678.2 | J6: =F6*'Mark Up '!$C$2 -> 19842.9 | K6: =G6*'Mark Up '!$C$2 -> 21968.1 | L6: =H6*'Mark Up '!$C$2 -> 22905.96
B7: 11104-5 | C7: Aparador Cildo "SOMENTE SEM VIDRO" | D7: 2,20 X 0,50 X 0,76 | E7: =VLOOKUP(B7,'Origem '!$A$1:$D$181,4,0) -> 3738 | F7: =VLOOKUP(B7,'Origem '!$A$1:$E$181,5,0) -> 4515 | G7: =VLOOKUP(B7,'Origem '!$A$1:$F$181,6,0) -> 5005 | H7: =VLOOKUP(B7,'Origem '!$A$1:$G$181,7,0) -> 5170 | I7: =E7*'Mark Up '!$C$2 -> 17269.56 | J7: =F7*'Mark Up '!$C$2 -> 20859.3 | K7: =G7*'Mark Up '!$C$2 -> 23123.1 | L7: =H7*'Mark Up '!$C$2 -> 23885.4
B8: 11104-6 | C8: Aparador Cildo "SOMENTE SEM VIDRO" | D8: 2,40 X 0,50 X 0,76 | E8: =VLOOKUP(B8,'Origem '!$A$1:$D$181,4,0) -> 4029 | F8: =VLOOKUP(B8,'Origem '!$A$1:$E$181,5,0) -> 4851 | G8: =VLOOKUP(B8,'Origem '!$A$1:$F$181,6,0) -> 5406 | H8: =VLOOKUP(B8,'Origem '!$A$1:$G$181,7,0) -> 5583 | I8: =E8*'Mark Up '!$C$2 -> 18613.98 | J8: =F8*'Mark Up '!$C$2 -> 22411.62 | K8: =G8*'Mark Up '!$C$2 -> 24975.72 | L8: =H8*'Mark Up '!$C$2 -> 25793.46
A9: COBK | B9: 1014-1 | C9: Aparador Cobk Vidro Apenas na Bandeja, Pés Metal | D9: 1,36 x 0,39 x 0,76 | E9: =VLOOKUP(B9,'Origem '!$A$1:$D$181,4,0) -> 1919 | F9: =VLOOKUP(B9,'Origem '!$A$1:$E$181,5,0) -> 2203 | G9: =VLOOKUP(B9,'Origem '!$A$1:$F$181,6,0) -> 2444 | H9: =VLOOKUP(B9,'Origem '!$A$1:$G$181,7,0) -> 2501 | I9: =E9*'Mark Up '!$C$2 -> 8865.78 | J9: =F9*'Mark Up '!$C$2 -> 10177.86 | K9: =G9*'Mark Up '!$C$2 -> 11291.28 | L9: =H9*'Mark Up '!$C$2 -> 11554.62
B10: 1014-2 | C10: Aparador Cobk Vidro Apenas na Bandeja, Pés Metal | D10: 1,60 x 0,39 x 0,76 | E10: =VLOOKUP(B10,'Origem '!$A$1:$D$181,4,0) -> 1989 | F10: =VLOOKUP(B10,'Origem '!$A$1:$E$181,5,0) -> 2317 | G10: =VLOOKUP(B10,'Origem '!$A$1:$F$181,6,0) -> 2529 | H10: =VLOOKUP(B10,'Origem '!$A$1:$G$181,7,0) -> 2624 | I10: =E10*'Mark Up '!$C$2 -> 9189.18 | J10: =F10*'Mark Up '!$C$2 -> 10704.54 | K10: =G10*'Mark Up '!$C$2 -> 11683.98 | L10: =H10*'Mark Up '!$C$2 -> 12122.88
B11: 1014-3 | C11: Aparador Cobk Vidro Apenas na Bandeja, Pés Metal | D11: 1,80 x 0,39 x 0,76 | E11: =VLOOKUP(B11,'Origem '!$A$1:$D$181,4,0) -> 2096 | F11: =VLOOKUP(B11,'Origem '!$A$1:$E$181,5,0) -> 2454 | G11: =VLOOKUP(B11,'Origem '!$A$1:$F$181,6,0) -> 2680 | H11: =VLOOKUP(B11,'Origem '!$A$1:$G$181,7,0) -> 2730 | I11: =E11*'Mark Up '!$C$2 -> 9683.52 | J11: =F11*'Mark Up '!$C$2 -> 11337.48 | K11: =G11*'Mark Up '!$C$2 -> 12381.6 | L11: =H11*'Mark Up '!$C$2 -> 12612.6
B12: 1014-4 | C12: Aparador Cobk Vidro Apenas na Bandeja, Pés Metal | D12: 2,00 x 0,39 x 0,76 | E12: =VLOOKUP(B12,'Origem '!$A$1:$D$181,4,0) -> 2237 | F12: =VLOOKUP(B12,'Origem '!$A$1:$E$181,5,0) -> 2614 | G12: =VLOOKUP(B12,'Origem '!$A$1:$F$181,6,0) -> 2928 | H12: =VLOOKUP(B12,'Origem '!$A$1:$G$181,7,0) -> 2973 | I12: =E12*'Mark Up '!$C$2 -> 10334.94 | J12: =F12*'Mark Up '!$C$2 -> 12076.68 | K12: =G12*'Mark Up '!$C$2 -> 13527.36 | L12: =H12*'Mark Up '!$C$2 -> 13735.26
A13: LA PLATA | B13: 10054-2 | C13: Aparador Lá Plata | D13: 1,60 x 0,45 x 0,76 | E13: =VLOOKUP(B13,'Origem '!$A$1:$D$181,4,0) -> 2066 | F13: =VLOOKUP(B13,'Origem '!$A$1:$E$181,5,0) -> 2417 | G13: =VLOOKUP(B13,'Origem '!$A$1:$F$181,6,0) -> 2653 | H13: =VLOOKUP(B13,'Origem '!$A$1:$G$181,7,0) -> 2741 | I13: =E13*'Mark Up '!$C$2 -> 9544.92 | J13: =F13*'Mark Up '!$C$2 -> 11166.54 | K13: =G13*'Mark Up '!$C$2 -> 12256.86 | L13: =H13*'Mark Up '!$C$2 -> 12663.42
B14: 10054-3 | C14: Aparador Lá Plata | D14: 1,80 x 0,45 x 0,76 | E14: =VLOOKUP(B14,'Origem '!$A$1:$D$181,4,0) -> 2144 | F14: =VLOOKUP(B14,'Origem '!$A$1:$E$181,5,0) -> 2486 | G14: =VLOOKUP(B14,'Origem '!$A$1:$F$181,6,0) -> 2728 | H14: =VLOOKUP(B14,'Origem '!$A$1:$G$181,7,0) -> 2815 | I14: =E14*'Mark Up '!$C$2 -> 9905.28 | J14: =F14*'Mark Up '!$C$2 -> 11485.32 | K14: =G14*'Mark Up '!$C$2 -> 12603.36 | L14: =H14*'Mark Up '!$C$2 -> 13005.3
B15: 10054-4 | C15: Aparador Lá Plata | D15: 2,00 x 0,45 x 0,76 | E15: =VLOOKUP(B15,'Origem '!$A$1:$D$181,4,0) -> 2288 | F15: =VLOOKUP(B15,'Origem '!$A$1:$E$181,5,0) -> 2614 | G15: =VLOOKUP(B15,'Origem '!$A$1:$F$181,6,0) -> 2884 | H15: =VLOOKUP(B15,'Origem '!$A$1:$G$181,7,0) -> 2971 | I15: =E15*'Mark Up '!$C$2 -> 10570.56 | J15: =F15*'Mark Up '!$C$2 -> 12076.68 | K15: =G15*'Mark Up '!$C$2 -> 13324.08 | L15: =H15*'Mark Up '!$C$2 -> 13726.02
B16: 10054-5 | C16: Aparador Lá Plata | D16: 2,20 x 0,45 x 0,76 | E16: =VLOOKUP(B16,'Origem '!$A$1:$D$181,4,0) -> 2406 | F16: =VLOOKUP(B16,'Origem '!$A$1:$E$181,5,0) -> 2732 | G16: =VLOOKUP(B16,'Origem '!$A$1:$F$181,6,0) -> 3045 | H16: =VLOOKUP(B16,'Origem '!$A$1:$G$181,7,0) -> 3132 | I16: =E16*'Mark Up '!$C$2 -> 11115.72 | J16: =F16*'Mark Up '!$C$2 -> 12621.84 | K16: =G16*'Mark Up '!$C$2 -> 14067.9 | L16: =H16*'Mark Up '!$C$2 -> 14469.84
A17: LIPSIA | B17: 9924-1 | C17: Aparador Lipsia "SOMENTE SEM VIDRO" | D17: 1,40 x 0,45 x 0,76 | E17: =VLOOKUP(B17,'Origem '!$A$1:$D$181,4,0) -> 1943 | F17: =VLOOKUP(B17,'Origem '!$A$1:$E$181,5,0) -> 2169 | G17: =VLOOKUP(B17,'Origem '!$A$1:$F$181,6,0) -> 2279 | H17: =VLOOKUP(B17,'Origem '!$A$1:$G$181,7,0) -> X | I17: =E17*'Mark Up '!$C$2 -> 8976.66 | J17: =F17*'Mark Up '!$C$2 -> 10020.78 | K17: =G17*'Mark Up '!$C$2 -> 10528.98 | L17: X
B18: 9924-2 | C18: Aparador Lipsia "SOMENTE SEM VIDRO" | D18: 1,60 x 0,45 x 0,76 | E18: =VLOOKUP(B18,'Origem '!$A$1:$D$181,4,0) -> 2005 | F18: =VLOOKUP(B18,'Origem '!$A$1:$E$181,5,0) -> 2314 | G18: =VLOOKUP(B18,'Origem '!$A$1:$F$181,6,0) -> 2438 | H18: =VLOOKUP(B18,'Origem '!$A$1:$G$181,7,0) -> X | I18: =E18*'Mark Up '!$C$2 -> 9263.1 | J18: =F18*'Mark Up '!$C$2 -> 10690.68 | K18: =G18*'Mark Up '!$C$2 -> 11263.56 | L18: X
B19: 9924-3 | C19: Aparador Lipsia "SOMENTE SEM VIDRO" | D19: 1,80 x 0,45 x 0,76 | E19: =VLOOKUP(B19,'Origem '!$A$1:$D$181,4,0) -> 2115 | F19: =VLOOKUP(B19,'Origem '!$A$1:$E$181,5,0) -> 2442 | G19: =VLOOKUP(B19,'Origem '!$A$1:$F$181,6,0) -> 2576 | H19: =VLOOKUP(B19,'Origem '!$A$1:$G$181,7,0) -> X | I19: =E19*'Mark Up '!$C$2 -> 9771.3 | J19: =F19*'Mark Up '!$C$2 -> 11282.04 | K19: =G19*'Mark Up '!$C$2 -> 11901.12 | L19: X
B20: 9924-4 | C20: Aparador Lipsia "SOMENTE SEM VIDRO" | D20: 2,00 x 0,45 x 0,76 | E20: =VLOOKUP(B20,'Origem '!$A$1:$D$181,4,0) -> 2260 | F20: =VLOOKUP(B20,'Origem '!$A$1:$E$181,5,0) -> 2642 | G20: =VLOOKUP(B20,'Origem '!$A$1:$F$181,6,0) -> 2786 | H20: =VLOOKUP(B20,'Origem '!$A$1:$G$181,7,0) -> X | I20: =E20*'Mark Up '!$C$2 -> 10441.2 | J20: =F20*'Mark Up '!$C$2 -> 12206.04 | K20: =G20*'Mark Up '!$C$2 -> 12871.32 | L20: X
A21: MACAÇAR | B21: 10024-2 | C21: Aparador Macaçar "SOMENTE SEM VIDRO" | D21: 1,60 x 0,45 x 0,76 | E21: =VLOOKUP(B21,'Origem '!$A$1:$D$181,4,0) -> 2170 | F21: =VLOOKUP(B21,'Origem '!$A$1:$E$181,5,0) -> 2733 | G21: =VLOOKUP(B21,'Origem '!$A$1:$F$181,6,0) -> 2920 | H21: =VLOOKUP(B21,'Origem '!$A$1:$G$181,7,0) -> X | I21: =E21*'Mark Up '!$C$2 -> 10025.4 | J21: =F21*'Mark Up '!$C$2 -> 12626.46 | K21: =G21*'Mark Up '!$C$2 -> 13490.4 | L21: X
B22: 10024-3 | C22: Aparador Macaçar "SOMENTE SEM VIDRO" | D22: 1,80 x 0,45 x 0,76 | E22: =VLOOKUP(B22,'Origem '!$A$1:$D$181,4,0) -> 2286 | F22: =VLOOKUP(B22,'Origem '!$A$1:$E$181,5,0) -> 2957 | G22: =VLOOKUP(B22,'Origem '!$A$1:$F$181,6,0) -> 3196 | H22: =VLOOKUP(B22,'Origem '!$A$1:$G$181,7,0) -> X | I22: =E22*'Mark Up '!$C$2 -> 10561.32 | J22: =F22*'Mark Up '!$C$2 -> 13661.34 | K22: =G22*'Mark Up '!$C$2 -> 14765.52 | L22: X
B23: 10024-4 | C23: Aparador Macaçar "SOMENTE SEM VIDRO" | D23: 2,00 x 0,45 x 0,76 | E23: =VLOOKUP(B23,'Origem '!$A$1:$D$181,4,0) -> 2598 | F23: =VLOOKUP(B23,'Origem '!$A$1:$E$181,5,0) -> 3111 | G23: =VLOOKUP(B23,'Origem '!$A$1:$F$181,6,0) -> 3347 | H23: =VLOOKUP(B23,'Origem '!$A$1:$G$181,7,0) -> X | I23: =E23*'Mark Up '!$C$2 -> 12002.76 | J23: =F23*'Mark Up '!$C$2 -> 14372.82 | K23: =G23*'Mark Up '!$C$2 -> 15463.14 | L23: X
A24: OITICICA | B24: 11094-4 | C24: Aparador Oiticica "SOMENTE SEM VIDRO" | D24: 2,00 X 0,50 X 0,76 | E24: =VLOOKUP(B24,'Origem '!$A$1:$D$181,4,0) -> 3739 | F24: =VLOOKUP(B24,'Origem '!$A$1:$E$181,5,0) -> 4272 | G24: =VLOOKUP(B24,'Origem '!$A$1:$F$181,6,0) -> 4523 | H24: =VLOOKUP(B24,'Origem '!$A$1:$G$181,7,0) -> 4670 | I24: =E24*'Mark Up '!$C$2 -> 17274.18 | J24: =F24*'Mark Up '!$C$2 -> 19736.64 | K24: =G24*'Mark Up '!$C$2 -> 20896.26 | L24: =H24*'Mark Up '!$C$2 -> 21575.4
B25: 11094-6 | C25: Aparador Oiticica "SOMENTE SEM VIDRO" | D25: 2,40 X 0,50 X 0,76 | E25: =VLOOKUP(B25,'Origem '!$A$1:$D$181,4,0) -> 4027 | F25: =VLOOKUP(B25,'Origem '!$A$1:$E$181,5,0) -> 4565 | G25: =VLOOKUP(B25,'Origem '!$A$1:$F$181,6,0) -> 4860 | H25: =VLOOKUP(B25,'Origem '!$A$1:$G$181,7,0) -> 4978 | I25: =E25*'Mark Up '!$C$2 -> 18604.74 | J25: =F25*'Mark Up '!$C$2 -> 21090.3 | K25: =G25*'Mark Up '!$C$2 -> 22453.2 | L25: =H25*'Mark Up '!$C$2 -> 22998.36
A26: TROIA | B26: 6064-3 | C26: Aparador Troia | D26: 1,80 x 0,50 x 0,76 | E26: =VLOOKUP(B26,'Origem '!$A$1:$D$181,4,0) -> 2451 | F26: =VLOOKUP(B26,'Origem '!$A$1:$E$181,5,0) -> 2489 | G26: =VLOOKUP(B26,'Origem '!$A$1:$F$181,6,0) -> 2676 | H26: =VLOOKUP(B26,'Origem '!$A$1:$G$181,7,0) -> X | I26: =E26*'Mark Up '!$C$2 -> 11323.62 | J26: =F26*'Mark Up '!$C$2 -> 11499.18 | K26: =G26*'Mark Up '!$C$2 -> 12363.12 | L26: X
B27: 6064-4 | C27: Aparador Troia | D27: 2,00 x 0,50 x 0,76 | E27: =VLOOKUP(B27,'Origem '!$A$1:$D$181,4,0) -> 2546 | F27: =VLOOKUP(B27,'Origem '!$A$1:$E$181,5,0) -> 2587 | G27: =VLOOKUP(B27,'Origem '!$A$1:$F$181,6,0) -> 2771 | H27: =VLOOKUP(B27,'Origem '!$A$1:$G$181,7,0) -> X | I27: =E27*'Mark Up '!$C$2 -> 11762.52 | J27: =F27*'Mark Up '!$C$2 -> 11951.94 | K27: =G27*'Mark Up '!$C$2 -> 12802.02 | L27: X
B28: 6064-5 | C28: Aparador Troia | D28: 2,20 x 0,50 x 0,76 | E28: =VLOOKUP(B28,'Origem '!$A$1:$D$181,4,0) -> 2836 | F28: =VLOOKUP(B28,'Origem '!$A$1:$E$181,5,0) -> 2890 | G28: =VLOOKUP(B28,'Origem '!$A$1:$F$181,6,0) -> 3081 | H28: =VLOOKUP(B28,'Origem '!$A$1:$G$181,7,0) -> X | I28: =E28*'Mark Up '!$C$2 -> 13102.32 | J28: =F28*'Mark Up '!$C$2 -> 13351.8 | K28: =G28*'Mark Up '!$C$2 -> 14234.22 | L28: X
A29: USSÉ | B29: 1064-1 | C29: Aparador Ussé | D29: 1,41 x 0,46 x 0,76 | E29: =VLOOKUP(B29,'Origem '!$A$1:$D$181,4,0) -> 1811 | F29: =VLOOKUP(B29,'Origem '!$A$1:$E$181,5,0) -> 2223 | G29: =VLOOKUP(B29,'Origem '!$A$1:$F$181,6,0) -> 2430 | H29: =VLOOKUP(B29,'Origem '!$A$1:$G$181,7,0) -> 2525 | I29: =E29*'Mark Up '!$C$2 -> 8366.82 | J29: =F29*'Mark Up '!$C$2 -> 10270.26 | K29: =G29*'Mark Up '!$C$2 -> 11226.6 | L29: =H29*'Mark Up '!$C$2 -> 11665.5
B30: 1064-2 | C30: Aparador Ussé | D30: 1,61 x 0,46 x 0,76 | E30: =VLOOKUP(B30,'Origem '!$A$1:$D$181,4,0) -> 1959 | F30: =VLOOKUP(B30,'Origem '!$A$1:$E$181,5,0) -> 2344 | G30: =VLOOKUP(B30,'Origem '!$A$1:$F$181,6,0) -> 2560 | H30: =VLOOKUP(B30,'Origem '!$A$1:$G$181,7,0) -> 2647 | I30: =E30*'Mark Up '!$C$2 -> 9050.58 | J30: =F30*'Mark Up '!$C$2 -> 10829.28 | K30: =G30*'Mark Up '!$C$2 -> 11827.2 | L30: =H30*'Mark Up '!$C$2 -> 12229.14
B31: 1064-3 | C31: Aparador Ussé | D31: 1,81 x 0,46 x 0,76 | E31: =VLOOKUP(B31,'Origem '!$A$1:$D$181,4,0) -> 2072 | F31: =VLOOKUP(B31,'Origem '!$A$1:$E$181,5,0) -> 2459 | G31: =VLOOKUP(B31,'Origem '!$A$1:$F$181,6,0) -> 2696 | H31: =VLOOKUP(B31,'Origem '!$A$1:$G$181,7,0) -> 2800 | I31: =E31*'Mark Up '!$C$2 -> 9572.64 | J31: =F31*'Mark Up '!$C$2 -> 11360.58 | K31: =G31*'Mark Up '!$C$2 -> 12455.52 | L31: =H31*'Mark Up '!$C$2 -> 12936
B32: 1064-4 | C32: Aparador Ussé | D32: 2,01 x 0,46 x 0,76 | E32: =VLOOKUP(B32,'Origem '!$A$1:$D$181,4,0) -> 2531 | F32: =VLOOKUP(B32,'Origem '!$A$1:$E$181,5,0) -> 2664 | G32: =VLOOKUP(B32,'Origem '!$A$1:$F$181,6,0) -> 3317 | H32: =VLOOKUP(B32,'Origem '!$A$1:$G$181,7,0) -> 3426 | I32: =E32*'Mark Up '!$C$2 -> 11693.22 | J32: =F32*'Mark Up '!$C$2 -> 12307.68 | K32: =G32*'Mark Up '!$C$2 -> 15324.54 | L32: =H32*'Mark Up '!$C$2 -> 15828.12

Sheet Gaveteiros
C1: GAVETEIROS | G1: LANÇAMENTO 2025 | K1: LANÇAMENTO 2025
A2: COLEÇÃO | B2: REF | C2: DESCRIÇÃO | D2: COMP X PROF X ALT | E2: Em caso de cores diferentes, utilizar preço de maior valor | I2: Em caso de cores diferentes, utilizar preço de maior valor
E3: COLUNA 1 | F3: COLUNA 2 | G3: COLUNA 3 | H3: COLUNA 4 | I3: COLUNA 1 | J3: COLUNA 2 | K3: COLUNA 3 | L3: COLUNA 4
E4: LACA LISA BRAZIL ( COM OU SEM VIDRO PINTADO) | F4: - CARVALHO CLARO - CARVALHO NATURAL - CARVALHO LAVADO - CARV. EBANIZADO - IMBUIA CLARA * ACRESCENTAR 12% SE COM VIDRO PINTADO | G4: - NOGUEIRA - NOGUEIRA NATURAL - LOURO FREIJÓ - LOURO FREIJÓ NATURAL - CANELA - LACA METALIZADA BRAZIL - CARV. ÔNIX METALIZADO - CARV. N109 METALIZADO - CARV. ALBANIZADO - CARV. H155 FOSCO - CONCRETO (SOMENTE SEM VIDRO) | H4: - PAU FERRO | I4: LACA LISA BRAZIL ( COM OU SEM VIDRO PINTADO) | J4: - CARVALHO CLARO - CARVALHO NATURAL - CARVALHO LAVADO - CARV. EBANIZADO - IMBUIA CLARA * ACRESCENTAR 12% SE COM VIDRO PINTADO | K4: - NOGUEIRA - NOGUEIRA NATURAL - LOURO FREIJÓ - LOURO FREIJÓ NATURAL - CANELA - LACA METALIZADA BRAZIL - CARV. ÔNIX METALIZADO - CARV. N109 METALIZADO - CARV. ALBANIZADO - CARV. H155 FOSCO - CONCRETO (SOMENTE SEM VIDRO) | L4: - PAU FERRO
E5: OBS. O ACABAMENTO DO METAL NÃO INFLUENCIARÁ NO VALOR DOS GAVETEIROS | I5: OBS. O ACABAMENTO DO METAL NÃO INFLUENCIARÁ NO VALOR DOS GAVETEIROS
A6: ERNESTO | B6: 11122-0 | C6: Gaveteiro Ernesto Pés Metal | D6: 0,54 X 0,46 X 0,58 | E6: =VLOOKUP(B6,'Origem '!$A$1:$D$181,4,0) -> 2258 | F6: =VLOOKUP(B6,'Origem '!$A$1:$E$181,5,0) -> 2656 | G6: =VLOOKUP(B6,'Origem '!$A$1:$F$181,6,0) -> 2798 | H6: =VLOOKUP(B6,'Origem '!$A$1:$G$181,7,0) -> 2885 | I6: =E6*'Mark Up '!$C$2 -> 10431.96 | J6: =F6*'Mark Up '!$C$2 -> 12270.72 | K6: =G6*'Mark Up '!$C$2 -> 12926.76 | L6: =H6*'Mark Up '!$C$2 -> 13328.7
B7: 11122-2 | C7: Gaveteiro Ernesto Pés Metal | D7: 0,74 X 0,46 X 0,58 | E7: =VLOOKUP(B7,'Origem '!$A$1:$D$181,4,0) -> 2451 | F7: =VLOOKUP(B7,'Origem '!$A$1:$E$181,5,0) -> 2909 | G7: =VLOOKUP(B7,'Origem '!$A$1:$F$181,6,0) -> 3189 | H7: =VLOOKUP(B7,'Origem '!$A$1:$G$181,7,0) -> 3305 | I7: =E7*'Mark Up '!$C$2 -> 11323.62 | J7: =F7*'Mark Up '!$C$2 -> 13439.58 | K7: =G7*'Mark Up '!$C$2 -> 14733.18 | L7: =H7*'Mark Up '!$C$2 -> 15269.1
A8: HADAR | B8: 3322-0 | C8: Gaveteiro Hadar Pés Metal | D8: 54 x 46,5 x 60 | E8: =VLOOKUP(B8,'Origem '!$A$1:$D$181,4,0) -> 1882 | F8: =VLOOKUP(B8,'Origem '!$A$1:$E$181,5,0) -> 2462 | G8: =VLOOKUP(B8,'Origem '!$A$1:$F$181,6,0) -> 2623 | H8: =VLOOKUP(B8,'Origem '!$A$1:$G$181,7,0) -> 2687 | I8: =E8*'Mark Up '!$C$2 -> 8694.84 | J8: =F8*'Mark Up '!$C$2 -> 11374.44 | K8: =G8*'Mark Up '!$C$2 -> 12118.26 | L8: =H8*'Mark Up '!$C$2 -> 12413.94
B9: 3322-2 | C9: Gaveteiro Hadar Pés Metal | D9: 74 x 46,5 x 60 | E9: =VLOOKUP(B9,'Origem '!$A$1:$D$181,4,0) -> 1998 | F9: =VLOOKUP(B9,'Origem '!$A$1:$E$181,5,0) -> 2698 | G9: =VLOOKUP(B9,'Origem '!$A$1:$F$181,6,0) -> 2819 | H9: =VLOOKUP(B9,'Origem '!$A$1:$G$181,7,0) -> 2896 | I9: =E9*'Mark Up '!$C$2 -> 9230.76 | J9: =F9*'Mark Up '!$C$2 -> 12464.76 | K9: =G9*'Mark Up '!$C$2 -> 13023.78 | L9: =H9*'Mark Up '!$C$2 -> 13379.52
A10: LASI | B10: 3222-5 | C10: Gaveteiro Lasi | D10: 0,41 Ø X 0,65 | E10: =VLOOKUP(B10,'Origem '!$A$1:$D$181,4,0) -> 1698 | F10: =VLOOKUP(B10,'Origem '!$A$1:$E$181,5,0) -> 2160 | G10: =VLOOKUP(B10,'Origem '!$A$1:$F$181,6,0) -> 2255 | H10: =VLOOKUP(B10,'Origem '!$A$1:$G$181,7,0) -> 2348 | I10: =E10*'Mark Up '!$C$2 -> 7844.76 | J10: =F10*'Mark Up '!$C$2 -> 9979.2 | K10: =G10*'Mark Up '!$C$2 -> 10418.1 | L10: =H10*'Mark Up '!$C$2 -> 10847.76

Sheet Complementos
C1: COMPLEMENTOS | G1: LANÇAMENTO 2025 | K1: LANÇAMENTO 2025
A2: COLEÇÃO | B2: REF | C2: DESCRIÇÃO | D2: COMP X PROF X ALT | E2: Em caso de cores diferentes Base ou Tampo, utilizar preço de maior valor | I2: Em caso de cores diferentes Base ou Tampo, utilizar preço de maior valor
E3: COLUNA 1 | F3: COLUNA 2 | G3: COLUNA 3 | H3: COLUNA 4 | I3: COLUNA 1 | J3: COLUNA 2 | K3: COLUNA 3 | L3: COLUNA 4
E4: LACA LISA BRAZIL ( COM OU SEM VIDRO PINTADO) | F4: - CARVALHO CLARO - CARVALHO NATURAL - CARVALHO LAVADO - CARV. EBANIZADO - IMBUIA CLARA * ACRESCENTAR 12% SE COM VIDRO PINTADO | G4: - NOGUEIRA - NOGUEIRA NATURAL - LOURO FREIJÓ - LOURO FREIJÓ NATURAL - CANELA - LACA METALIZADA BRAZIL - CARV. ÔNIX METALIZADO - CARV. N109 METALIZADO - CARV. ALBANIZADO - CARV. H155 FOSCO - CONCRETO (SOMENTE SEM VIDRO) | H4: - PAU FERRO | I4: LACA LISA BRAZIL ( COM OU SEM VIDRO PINTADO) | J4: - CARVALHO CLARO - CARVALHO NATURAL - CARVALHO LAVADO - CARV. EBANIZADO - IMBUIA CLARA * ACRESCENTAR 12% SE COM VIDRO PINTADO | K4: - NOGUEIRA - NOGUEIRA NATURAL - LOURO FREIJÓ - LOURO FREIJÓ NATURAL - CANELA - LACA METALIZADA BRAZIL - CARV. ÔNIX METALIZADO - CARV. N109 METALIZADO - CARV. ALBANIZADO - CARV. H155 FOSCO - CONCRETO (SOMENTE SEM VIDRO) | L4: - PAU FERRO
E5: OBS. O ACABAMENTO DO METAL NÃO INFLUENCIARÁ NO VALOR DO MÓVEL | I5: OBS. O ACABAMENTO DO METAL NÃO INFLUENCIARÁ NO VALOR DO MÓVEL
A6: RESPIRO | B6: 4060-4 | C6: Banco Respiro | D6: 1,80 X 0,45 X 0,42 | E6: =VLOOKUP(B6,'Origem '!$A$1:$D$181,4,0) -> 2471 | F6: =VLOOKUP(B6,'Origem '!$A$1:$E$181,5,0) -> 2714 | G6: =VLOOKUP(B6,'Origem '!$A$1:$F$181,6,0) -> 2837 | H6: =VLOOKUP(B6,'Origem '!$A$1:$G$181,7,0) -> X | I6: =E6*'Mark Up '!$C$2 -> 11416.02 | J6: =F6*'Mark Up '!$C$2 -> 12538.68 | K6: =G6*'Mark Up '!$C$2 -> 13106.94 | L6: X
B7: 4060-5 | C7: Banco Respiro | D7: 2,00 X 0,45 X 0,42 | E7: =VLOOKUP(B7,'Origem '!$A$1:$D$181,4,0) -> 2586 | F7: =VLOOKUP(B7,'Origem '!$A$1:$E$181,5,0) -> 2858 | G7: =VLOOKUP(B7,'Origem '!$A$1:$F$181,6,0) -> 2990 | H7: =VLOOKUP(B7,'Origem '!$A$1:$G$181,7,0) -> X | I7: =E7*'Mark Up '!$C$2 -> 11947.32 | J7: =F7*'Mark Up '!$C$2 -> 13203.96 | K7: =G7*'Mark Up '!$C$2 -> 13813.8 | L7: X
A8: IRAN | B8: 11133-2 | C8: Moldura Iran | D8: 1,96 X 0,95 X 0,75 | E8: =VLOOKUP(B8,'Origem '!$A$1:$D$181,4,0) -> 4046 | F8: =VLOOKUP(B8,'Origem '!$A$1:$E$181,5,0) -> 4770 | G8: =VLOOKUP(B8,'Origem '!$A$1:$F$181,6,0) -> 4794 | H8: =VLOOKUP(B8,'Origem '!$A$1:$G$181,7,0) -> 4876 | I8: =E8*'Mark Up '!$C$2 -> 18692.52 | J8: =F8*'Mark Up '!$C$2 -> 22037.4 | K8: =G8*'Mark Up '!$C$2 -> 22148.28 | L8: =H8*'Mark Up '!$C$2 -> 22527.12
A9: MUNIZ | B9: 3310-0 | C9: Moldura Muniz | D9: 1,06 X 0,13 X 1,13 | E9: =VLOOKUP(B9,'Origem '!$A$1:$D$181,4,0) -> 2246 | F9: =VLOOKUP(B9,'Origem '!$A$1:$E$181,5,0) -> 2289 | G9: =VLOOKUP(B9,'Origem '!$A$1:$F$181,6,0) -> 2449 | H9: =VLOOKUP(B9,'Origem '!$A$1:$G$181,7,0) -> 2506 | I9: =E9*'Mark Up '!$C$2 -> 10376.52 | J9: =F9*'Mark Up '!$C$2 -> 10575.18 | K9: =G9*'Mark Up '!$C$2 -> 11314.38 | L9: =H9*'Mark Up '!$C$2 -> 11577.72

Sheet Mesa Centro e Laterais
C1: MESAS DE CENTRO E LATERAIS | H1: LANÇAMENTO 2025 | M1: LANÇAMENTO 2025
A2: COLEÇÃO | B2: REF | C2: DESCRIÇÃO | D2: COMP X PROF X ALT | E2: Em caso de cores diferentes Base ou Tampo, utilizar preço de maior valor | J2: Em caso de cores diferentes Base ou Tampo, utilizar preço de maior valor
E3: COLUNA 1 | F3: COLUNA 2 | G3: COLUNA 3 | H3: COLUNA 4 | I3: COLUNA 5 | J3: COLUNA 1 | K3: COLUNA 2 | L3: COLUNA 3 | M3: COLUNA 4 | N3: COLUNA 5
E4: LACA LISA BRAZIL ( COM OU SEM VIDRO PINTADO) | F4: - CARVALHO CLARO - CARVALHO NATURAL - CARVALHO LAVADO - CARV. EBANIZADO - IMBUIA CLARA * ACRESCENTAR 12% SE COM VIDRO PINTADO | G4: MESA COM TAMPO LACA LISA (COM OU SEM VIDRO PINTADO) E BASE EM: - CARVALHO CLARO - CARVALHO NATURAL - CARVALHO LAVADO - CARV. EBANIZADO - IMBUIA CLARA | H4: - NOGUEIRA - NOGUEIRA NATURAL - LOURO FREIJÓ - LOURO FREIJÓ NATURAL - CANELA - LACA METALIZADA BRAZIL - CARVALHO ÔNIX METALIZADO - CARVALHO N109 METALIZADO - CARVALHO ALBANIZADO - CARVALHO H155 FOSCO (TAMPO COM OU SEM VIDRO) - CONCRETO (SOMENTE SEM VIDRO) | I4: - PAU FERRO | J4: LACA LISA BRAZIL ( COM OU SEM VIDRO PINTADO) | K4: - CARVALHO CLARO - CARVALHO NATURAL - CARVALHO LAVADO - CARV. EBANIZADO - IMBUIA CLARA * ACRESCENTAR 12% SE COM VIDRO PINTADO | L4: MESA COM TAMPO LACA LISA (COM OU SEM VIDRO PINTADO) E BASE EM: - CARVALHO CLARO - CARVALHO NATURAL - CARVALHO LAVADO - CARV. EBANIZADO - IMBUIA CLARA | M4: - NOGUEIRA - NOGUEIRA NATURAL - LOURO FREIJÓ - LOURO FREIJÓ NATURAL - CANELA - LACA METALIZADA BRAZIL - CARVALHO ÔNIX METALIZADO - CARVALHO N109 METALIZADO - CARVALHO ALBANIZADO - CARVALHO H155 FOSCO (TAMPO COM OU SEM VIDRO) - CONCRETO (SOMENTE SEM VIDRO) | N4: - PAU FERRO
E5: OBS. O ACABAMENTO DO METAL NÃO INFLUENCIARÁ NO VALOR DA MESA CENTRO/LATERAL | J5: OBS. O ACABAMENTO DO METAL NÃO INFLUENCIARÁ NO VALOR DA MESA CENTRO/LATERAL
A6: ADORE | B6: 3166-8 | C6: Mesa Centro Adore "SOMENTE S/VIDRO" | D6: 1,60 X 0,70 X 0,33 | E6: =VLOOKUP(B6,'Origem '!$A$1:$D$181,4,0) -> 2350 | F6: =VLOOKUP(B6,'Origem '!$A$1:$E$181,5,0) -> 3036 | G6: =VLOOKUP(B6,'Origem '!$A$1:$F$181,6,0) -> 3036 | H6: =VLOOKUP(B6,'Origem '!$A$1:$G$181,7,0) -> 3349 | I6: =VLOOKUP(B6,'Origem '!$A$1:$H$181,8,0) -> 3463 | J6: =E6*'Mark Up '!$C$2 -> 10857 | K6: =F6*'Mark Up '!$C$2 -> 14026.32 | L6: =G6*'Mark Up '!$C$2 -> 14026.32 | M6: =H6*'Mark Up '!$C$2 -> 15472.38 | N6: =I6*'Mark Up '!$C$2 -> 15999.06
B7: 3166-10 | C7: Mesa Centro Adore "SOMENTE S/VIDRO" | D7: 1,80 X 0,80 X 0,33 | E7: =VLOOKUP(B7,'Origem '!$A$1:$D$181,4,0) -> 2686 | F7: =VLOOKUP(B7,'Origem '!$A$1:$E$181,5,0) -> 3251 | G7: =VLOOKUP(B7,'Origem '!$A$1:$F$181,6,0) -> 3251 | H7: =VLOOKUP(B7,'Origem '!$A$1:$G$181,7,0) -> 3619 | I7: =VLOOKUP(B7,'Origem '!$A$1:$H$181,8,0) -> 3769 | J7: =E7*'Mark Up '!$C$2 -> 12409.32 | K7: =F7*'Mark Up '!$C$2 -> 15019.62 | L7: =G7*'Mark Up '!$C$2 -> 15019.62 | M7: =H7*'Mark Up '!$C$2 -> 16719.78 | N7: =I7*'Mark Up '!$C$2 -> 17412.78
A8: ATLAS | B8: 3178-3 | C8: Mesa Lateral Atlas | D8: 0,90 X 0,34 X 0,63 | E8: =VLOOKUP(B8,'Origem '!$A$1:$D$181,4,0) -> 1288 | F8: =VLOOKUP(B8,'Origem '!$A$1:$E$181,5,0) -> 1359 | G8: =VLOOKUP(B8,'Origem '!$A$1:$F$181,6,0) -> 1392 | H8: =VLOOKUP(B8,'Origem '!$A$1:$G$181,7,0) -> 1445 | I8: =VLOOKUP(B8,'Origem '!$A$1:$H$181,8,0) -> X | J8: =E8*'Mark Up '!$C$2 -> 5950.56 | K8: =F8*'Mark Up '!$C$2 -> 6278.58 | L8: =G8*'Mark Up '!$C$2 -> 6431.04 | M8: =H8*'Mark Up '!$C$2 -> 6675.9 | N8: X
A9: BASKA | B9: 3278-3 | C9: Mesa Lateral Baska | D9: 0,45 Ø X 0,55 | E9: =VLOOKUP(B9,'Origem '!$A$1:$D$181,4,0) -> 1056 | F9: =VLOOKUP(B9,'Origem '!$A$1:$E$181,5,0) -> 1109 | G9: =VLOOKUP(B9,'Origem '!$A$1:$F$181,6,0) -> 1170 | H9: =VLOOKUP(B9,'Origem '!$A$1:$G$181,7,0) -> 1195 | I9: =VLOOKUP(B9,'Origem '!$A$1:$H$181,8,0) -> X | J9: =E9*'Mark Up '!$C$2 -> 4878.72 | K9: =F9*'Mark Up '!$C$2 -> 5123.58 | L9: =G9*'Mark Up '!$C$2 -> 5405.4 | M9: =H9*'Mark Up '!$C$2 -> 5520.9 | N9: X
B10: 3278-4 | C10: Mesa Lateral Baska | D10: 0,48 Ø X 0,63 | E10: =VLOOKUP(B10,'Origem '!$A$1:$D$181,4,0) -> 1189 | F10: =VLOOKUP(B10,'Origem '!$A$1:$E$181,5,0) -> 1202 | G10: =VLOOKUP(B10,'Origem '!$A$1:$F$181,6,0) -> 1277 | H10: =VLOOKUP(B10,'Origem '!$A$1:$G$181,7,0) -> 1299 | I10: =VLOOKUP(B10,'Origem '!$A$1:$H$181,8,0) -> X | J10: =E10*'Mark Up '!$C$2 -> 5493.18 | K10: =F10*'Mark Up '!$C$2 -> 5553.24 | L10: =G10*'Mark Up '!$C$2 -> 5899.74 | M10: =H10*'Mark Up '!$C$2 -> 6001.38 | N10: X
A11: COLLE | B11: 3248-1 | C11: Mesa Lateral Colle | D11: 0,50 Ø X 0,55 | E11: =VLOOKUP(B11,'Origem '!$A$1:$D$181,4,0) -> 823 | F11: =VLOOKUP(B11,'Origem '!$A$1:$E$181,5,0) -> 809 | G11: =VLOOKUP(B11,'Origem '!$A$1:$F$181,6,0) -> 895 | H11: =VLOOKUP(B11,'Origem '!$A$1:$G$181,7,0) -> 909 | I11: =VLOOKUP(B11,'Origem '!$A$1:$H$181,8,0) -> X | J11: =E11*'Mark Up '!$C$2 -> 3802.26 | K11: =F11*'Mark Up '!$C$2 -> 3737.58 | L11: =G11*'Mark Up '!$C$2 -> 4134.9 | M11: =H11*'Mark Up '!$C$2 -> 4199.58 | N11: X
B12: 3248-2 | C12: Mesa Lateral Colle | D12: 0,60 Ø X 0,63 | E12: =VLOOKUP(B12,'Origem '!$A$1:$D$181,4,0) -> 924 | F12: =VLOOKUP(B12,'Origem '!$A$1:$E$181,5,0) -> 895 | G12: =VLOOKUP(B12,'Origem '!$A$1:$F$181,6,0) -> 1008 | H12: =VLOOKUP(B12,'Origem '!$A$1:$G$181,7,0) -> 1023 | I12: =VLOOKUP(B12,'Origem '!$A$1:$H$181,8,0) -> X | J12: =E12*'Mark Up '!$C$2 -> 4268.88 | K12: =F12*'Mark Up '!$C$2 -> 4134.9 | L12: =G12*'Mark Up '!$C$2 -> 4656.96 | M12: =H12*'Mark Up '!$C$2 -> 4726.26 | N12: X
A13: CORA | B13: 3301-3 | C13: Mesa Centro Cora Redonda "SOMENTE S/VIDRO" | D13: 0,70 Ø X 0,29 | E13: =VLOOKUP(B13,'Origem '!$A$1:$D$181,4,0) -> 1096 | F13: =VLOOKUP(B13,'Origem '!$A$1:$E$181,5,0) -> 1211 | G13: =VLOOKUP(B13,'Origem '!$A$1:$F$181,6,0) -> 1211 | H13: =VLOOKUP(B13,'Origem '!$A$1:$G$181,7,0) -> 1289 | I13: =VLOOKUP(B13,'Origem '!$A$1:$H$181,8,0) -> 1325 | J13: =E13*'Mark Up '!$C$2 -> 5063.52 | K13: =F13*'Mark Up '!$C$2 -> 5594.82 | L13: =G13*'Mark Up '!$C$2 -> 5594.82 | M13: =H13*'Mark Up '!$C$2 -> 5955.18 | N13: =I13*'Mark Up '!$C$2 -> 6121.5
B14: 3301-4 | C14: Mesa Centro Cora Redonda "SOMENTE S/VIDRO" | D14: 0,90 Ø X 0,29 | E14: =VLOOKUP(B14,'Origem '!$A$1:$D$181,4,0) -> 1294 | F14: =VLOOKUP(B14,'Origem '!$A$1:$E$181,5,0) -> 1461 | G14: =VLOOKUP(B14,'Origem '!$A$1:$F$181,6,0) -> 1461 | H14: =VLOOKUP(B14,'Origem '!$A$1:$G$181,7,0) -> 1586 | I14: =VLOOKUP(B14,'Origem '!$A$1:$H$181,8,0) -> 1647 | J14: =E14*'Mark Up '!$C$2 -> 5978.28 | K14: =F14*'Mark Up '!$C$2 -> 6749.82 | L14: =G14*'Mark Up '!$C$2 -> 6749.82 | M14: =H14*'Mark Up '!$C$2 -> 7327.32 | N14: =I14*'Mark Up '!$C$2 -> 7609.14
B15: 3300-7 | C15: Mesa Centro Cora "SOMENTE S/VIDRO" | D15: 1,35 X 0,70 X 0,35 | E15: =VLOOKUP(B15,'Origem '!$A$1:$D$181,4,0) -> 1316 | F15: =VLOOKUP(B15,'Origem '!$A$1:$E$181,5,0) -> 1489 | G15: =VLOOKUP(B15,'Origem '!$A$1:$F$181,6,0) -> 1489 | H15: =VLOOKUP(B15,'Origem '!$A$1:$G$181,7,0) -> 1645 | I15: =VLOOKUP(B15,'Origem '!$A$1:$H$181,8,0) -> 1698 | J15: =E15*'Mark Up '!$C$2 -> 6079.92 | K15: =F15*'Mark Up '!$C$2 -> 6879.18 | L15: =G15*'Mark Up '!$C$2 -> 6879.18 | M15: =H15*'Mark Up '!$C$2 -> 7599.9 | N15: =I15*'Mark Up '!$C$2 -> 7844.76
B16: 3300-8 | C16: Mesa Centro Cora "SOMENTE S/VIDRO" | D16: 1,60 X 0,70 X 0,35 | E16: =VLOOKUP(B16,'Origem '!$A$1:$D$181,4,0) -> 1428 | F16: =VLOOKUP(B16,'Origem '!$A$1:$E$181,5,0) -> 1687 | G16: =VLOOKUP(B16,'Origem '!$A$1:$F$181,6,0) -> 1687 | H16: =VLOOKUP(B16,'Origem '!$A$1:$G$181,7,0) -> 1865 | I16: =VLOOKUP(B16,'Origem '!$A$1:$H$181,8,0) -> 1933 | J16: =E16*'Mark Up '!$C$2 -> 6597.36 | K16: =F16*'Mark Up '!$C$2 -> 7793.94 | L16: =G16*'Mark Up '!$C$2 -> 7793.94 | M16: =H16*'Mark Up '!$C$2 -> 8616.3 | N16: =I16*'Mark Up '!$C$2 -> 8930.46
A17: DALI | B17: 3238-1 | C17: Mesa Lateral Dali ''PRODUZIDO APENAS EM LACA PADRÃO E METALIZADA"" | D17: 0,31 Ø X 0,55 | E17: =VLOOKUP(B17,'Origem '!$A$1:$D$181,4,0) -> 984 | F17: =VLOOKUP(B17,'Origem '!$A$1:$E$181,5,0) -> X | G17: =VLOOKUP(B17,'Origem '!$A$1:$F$181,6,0) -> X | H17: =VLOOKUP(B17,'Origem '!$A$1:$G$181,7,0) -> 1079 | I17: =VLOOKUP(B17,'Origem '!$A$1:$H$181,8,0) -> X | J17: =E17*'Mark Up '!$C$2 -> 4546.08 | K17: X | L17: X | M17: =H17*'Mark Up '!$C$2 -> 4984.98 | N17: X
B18: 3238-2 | C18: Mesa Lateral Dali ''PRODUZIDO APENAS EM LACA PADRÃO E METALIZADA"" | D18: 0,31 Ø X 0,63 | E18: =VLOOKUP(B18,'Origem '!$A$1:$D$181,4,0) -> 1044 | F18: =VLOOKUP(B18,'Origem '!$A$1:$E$181,5,0) -> X | G18: =VLOOKUP(B18,'Origem '!$A$1:$F$181,6,0) -> X | H18: =VLOOKUP(B18,'Origem '!$A$1:$G$181,7,0) -> 1150 | I18: =VLOOKUP(B18,'Origem '!$A$1:$H$181,8,0) -> X | J18: =E18*'Mark Up '!$C$2 -> 4823.28 | K18: X | L18: X | M18: =H18*'Mark Up '!$C$2 -> 5313 | N18: X
A19: DEVILLE | B19: 3208-0 | C19: Mesa Lateral Deville "SOMENTE S/VIDRO" | D19: 0,50 Ø X 0,51 | E19: =VLOOKUP(B19,'Origem '!$A$1:$D$181,4,0) -> 1027 | F19: =VLOOKUP(B19,'Origem '!$A$1:$E$181,5,0) -> 1290 | G19: =VLOOKUP(B19,'Origem '!$A$1:$F$181,6,0) -> 1290 | H19: =VLOOKUP(B19,'Origem '!$A$1:$G$181,7,0) -> 1374 | I19: =VLOOKUP(B19,'Origem '!$A$1:$H$181,8,0) -> 1433 | J19: =E19*'Mark Up '!$C$2 -> 4744.74 | K19: =F19*'Mark Up '!$C$2 -> 5959.8 | L19: =G19*'Mark Up '!$C$2 -> 5959.8 | M19: =H19*'Mark Up '!$C$2 -> 6347.88 | N19: =I19*'Mark Up '!$C$2 -> 6620.46
B20: 3208-1 | C20: Mesa Lateral Deville "SOMENTE S/VIDRO" | D20: 0,50 Ø X 0,56 | E20: =VLOOKUP(B20,'Origem '!$A$1:$D$181,4,0) -> 1045 | F20: =VLOOKUP(B20,'Origem '!$A$1:$E$181,5,0) -> 1316 | G20: =VLOOKUP(B20,'Origem '!$A$1:$F$181,6,0) -> 1316 | H20: =VLOOKUP(B20,'Origem '!$A$1:$G$181,7,0) -> 1403 | I20: =VLOOKUP(B20,'Origem '!$A$1:$H$181,8,0) -> 1519 | J20: =E20*'Mark Up '!$C$2 -> 4827.9 | K20: =F20*'Mark Up '!$C$2 -> 6079.92 | L20: =G20*'Mark Up '!$C$2 -> 6079.92 | M20: =H20*'Mark Up '!$C$2 -> 6481.86 | N20: =I20*'Mark Up '!$C$2 -> 7017.78
B21: 3208-2 | C21: Mesa Lateral Deville "SOMENTE S/VIDRO" | D21: 0,50 Ø X 0,64 | E21: =VLOOKUP(B21,'Origem '!$A$1:$D$181,4,0) -> 1084 | F21: =VLOOKUP(B21,'Origem '!$A$1:$E$181,5,0) -> 1394 | G21: =VLOOKUP(B21,'Origem '!$A$1:$F$181,6,0) -> 1394 | H21: =VLOOKUP(B21,'Origem '!$A$1:$G$181,7,0) -> 1507 | I21: =VLOOKUP(B21,'Origem '!$A$1:$H$181,8,0) -> 1633 | J21: =E21*'Mark Up '!$C$2 -> 5008.08 | K21: =F21*'Mark Up '!$C$2 -> 6440.28 | L21: =G21*'Mark Up '!$C$2 -> 6440.28 | M21: =H21*'Mark Up '!$C$2 -> 6962.34 | N21: =I21*'Mark Up '!$C$2 -> 7544.46
A22: LIPSIA | B22: 9921-2 | C22: Mesa Centro Lipsia Redonda "SOMENTE S/VIDRO" | D22: 0,70 Ø X 0,30 | E22: =VLOOKUP(B22,'Origem '!$A$1:$D$181,4,0) -> 1381 | F22: =VLOOKUP(B22,'Origem '!$A$1:$E$181,5,0) -> 1580 | G22: =VLOOKUP(B22,'Origem '!$A$1:$F$181,6,0) -> 1580 | H22: =VLOOKUP(B22,'Origem '!$A$1:$G$181,7,0) -> 1640 | I22: =VLOOKUP(B22,'Origem '!$A$1:$H$181,8,0) -> X | J22: =E22*'Mark Up '!$C$2 -> 6380.22 | K22: =F22*'Mark Up '!$C$2 -> 7299.6 | L22: =G22*'Mark Up '!$C$2 -> 7299.6 | M22: =H22*'Mark Up '!$C$2 -> 7576.8 | N22: X
B23: 9921-5 | C23: Mesa Centro Lipsia Redonda "SOMENTE S/VIDRO" | D23: 0,90 Ø X 0,30 | E23: =VLOOKUP(B23,'Origem '!$A$1:$D$181,4,0) -> 1639 | F23: =VLOOKUP(B23,'Origem '!$A$1:$E$181,5,0) -> 1875 | G23: =VLOOKUP(B23,'Origem '!$A$1:$F$181,6,0) -> 1875 | H23: =VLOOKUP(B23,'Origem '!$A$1:$G$181,7,0) -> 1986 | I23: =VLOOKUP(B23,'Origem '!$A$1:$H$181,8,0) -> X | J23: =E23*'Mark Up '!$C$2 -> 7572.18 | K23: =F23*'Mark Up '!$C$2 -> 8662.5 | L23: =G23*'Mark Up '!$C$2 -> 8662.5 | M23: =H23*'Mark Up '!$C$2 -> 9175.32 | N23: X
B24: 9921-4 | C24: Mesa Centro Lipsia Redonda "SOMENTE S/VIDRO" | D24: 0,90 Ø X 0,35 | E24: =VLOOKUP(B24,'Origem '!$A$1:$D$181,4,0) -> 1672 | F24: =VLOOKUP(B24,'Origem '!$A$1:$E$181,5,0) -> 1908 | G24: =VLOOKUP(B24,'Origem '!$A$1:$F$181,6,0) -> 1908 | H24: =VLOOKUP(B24,'Origem '!$A$1:$G$181,7,0) -> 2019 | I24: =VLOOKUP(B24,'Origem '!$A$1:$H$181,8,0) -> X | J24: =E24*'Mark Up '!$C$2 -> 7724.64 | K24: =F24*'Mark Up '!$C$2 -> 8814.96 | L24: =G24*'Mark Up '!$C$2 -> 8814.96 | M24: =H24*'Mark Up '!$C$2 -> 9327.78 | N24: X
B25: 9921-6 | C25: Mesa Centro Lipsia Redonda "SOMENTE S/VIDRO" | D25: 1,20 Ø X 0,35 | E25: =VLOOKUP(B25,'Origem '!$A$1:$D$181,4,0) -> 2178 | F25: =VLOOKUP(B25,'Origem '!$A$1:$E$181,5,0) -> 2513 | G25: =VLOOKUP(B25,'Origem '!$A$1:$F$181,6,0) -> 2513 | H25: =VLOOKUP(B25,'Origem '!$A$1:$G$181,7,0) -> 2722 | I25: =VLOOKUP(B25,'Origem '!$A$1:$H$181,8,0) -> X | J25: =E25*'Mark Up '!$C$2 -> 10062.36 | K25: =F25*'Mark Up '!$C$2 -> 11610.06 | L25: =G25*'Mark Up '!$C$2 -> 11610.06 | M25: =H25*'Mark Up '!$C$2 -> 12575.64 | N25: X
B26: 9926-7 | C26: Mesa Centro Lipsia "SOMENTE S/VIDRO" | D26: 1,35 X 0,70 X 0,30 | E26: =VLOOKUP(B26,'Origem '!$A$1:$D$181,4,0) -> 1969 | F26: =VLOOKUP(B26,'Origem '!$A$1:$E$181,5,0) -> 2182 | G26: =VLOOKUP(B26,'Origem '!$A$1:$F$181,6,0) -> 2182 | H26: =VLOOKUP(B26,'Origem '!$A$1:$G$181,7,0) -> 2330 | I26: =VLOOKUP(B26,'Origem '!$A$1:$H$181,8,0) -> X | J26: =E26*'Mark Up '!$C$2 -> 9096.78 | K26: =F26*'Mark Up '!$C$2 -> 10080.84 | L26: =G26*'Mark Up '!$C$2 -> 10080.84 | M26: =H26*'Mark Up '!$C$2 -> 10764.6 | N26: X
B27: 9926-8 | C27: Mesa Centro Lipsia "SOMENTE S/VIDRO" | D27: 1,60 X 0,70 X 0,30 | E27: =VLOOKUP(B27,'Origem '!$A$1:$D$181,4,0) -> 2156 | F27: =VLOOKUP(B27,'Origem '!$A$1:$E$181,5,0) -> 2408 | G27: =VLOOKUP(B27,'Origem '!$A$1:$F$181,6,0) -> 2408 | H27: =VLOOKUP(B27,'Origem '!$A$1:$G$181,7,0) -> 2573 | I27: =VLOOKUP(B27,'Origem '!$A$1:$H$181,8,0) -> X | J27: =E27*'Mark Up '!$C$2 -> 9960.72 | K27: =F27*'Mark Up '!$C$2 -> 11124.96 | L27: =G27*'Mark Up '!$C$2 -> 11124.96 | M27: =H27*'Mark Up '!$C$2 -> 11887.26 | N27: X
B28: 9926-10 | C28: Mesa Centro Lipsia "SOMENTE S/VIDRO" | D28: 1,80 X 0,80 X 0,30 | E28: =VLOOKUP(B28,'Origem '!$A$1:$D$181,4,0) -> 2315 | F28: =VLOOKUP(B28,'Origem '!$A$1:$E$181,5,0) -> 2927 | G28: =VLOOKUP(B28,'Origem '!$A$1:$F$181,6,0) -> 2927 | H28: =VLOOKUP(B28,'Origem '!$A$1:$G$181,7,0) -> 3141 | I28: =VLOOKUP(B28,'Origem '!$A$1:$H$181,8,0) -> X | J28: =E28*'Mark Up '!$C$2 -> 10695.3 | K28: =F28*'Mark Up '!$C$2 -> 13522.74 | L28: =G28*'Mark Up '!$C$2 -> 13522.74 | M28: =H28*'Mark Up '!$C$2 -> 14511.42 | N28: X
A29: LIRA | B29: 3338-0 | C29: Mesa Lateral Lira "Base Somente Textura Concreto" | D29: 0,30 Ø X 0,50 | E29: =VLOOKUP(B29,'Origem '!$A$1:$D$181,4,0) -> 1037 | F29: =VLOOKUP(B29,'Origem '!$A$1:$E$181,5,0) -> 1026 | G29: =VLOOKUP(B29,'Origem '!$A$1:$F$181,6,0) -> 1075 | H29: =VLOOKUP(B29,'Origem '!$A$1:$G$181,7,0) -> 1092 | I29: =VLOOKUP(B29,'Origem '!$A$1:$H$181,8,0) -> 1112 | J29: =E29*'Mark Up '!$C$2 -> 4790.94 | K29: =F29*'Mark Up '!$C$2 -> 4740.12 | L29: =G29*'Mark Up '!$C$2 -> 4966.5 | M29: =H29*'Mark Up '!$C$2 -> 5045.04 | N29: =I29*'Mark Up '!$C$2 -> 5137.44
B30: 3338-1 | C30: Mesa Lateral Lira "Base Somente Textura Concreto" | D30: 0,30 Ø X 0,55 | E30: =VLOOKUP(B30,'Origem '!$A$1:$D$181,4,0) -> 1052 | F30: =VLOOKUP(B30,'Origem '!$A$1:$E$181,5,0) -> 1039 | G30: =VLOOKUP(B30,'Origem '!$A$1:$F$181,6,0) -> 1091 | H30: =VLOOKUP(B30,'Origem '!$A$1:$G$181,7,0) -> 1112 | I30: =VLOOKUP(B30,'Origem '!$A$1:$H$181,8,0) -> 1131 | J30: =E30*'Mark Up '!$C$2 -> 4860.24 | K30: =F30*'Mark Up '!$C$2 -> 4800.18 | L30: =G30*'Mark Up '!$C$2 -> 5040.42 | M30: =H30*'Mark Up '!$C$2 -> 5137.44 | N30: =I30*'Mark Up '!$C$2 -> 5225.22
B31: 3338-2 | C31: Mesa Lateral Lira "Base Somente Textura Concreto" | D31: 0,30 Ø X 0,61 | E31: =VLOOKUP(B31,'Origem '!$A$1:$D$181,4,0) -> 1072 | F31: =VLOOKUP(B31,'Origem '!$A$1:$E$181,5,0) -> 1061 | G31: =VLOOKUP(B31,'Origem '!$A$1:$F$181,6,0) -> 1098 | H31: =VLOOKUP(B31,'Origem '!$A$1:$G$181,7,0) -> 1120 | I31: =VLOOKUP(B31,'Origem '!$A$1:$H$181,8,0) -> 1141 | J31: =E31*'Mark Up '!$C$2 -> 4952.64 | K31: =F31*'Mark Up '!$C$2 -> 4901.82 | L31: =G31*'Mark Up '!$C$2 -> 5072.76 | M31: =H31*'Mark Up '!$C$2 -> 5174.4 | N31: =I31*'Mark Up '!$C$2 -> 5271.42
A32: MILHARES | B32: 11175-8 | C32: Mesa Centro Milhares "SOMENTE S/VIDRO" | D32: 1,60 x 0,55 x 0,40 | E32: =VLOOKUP(B32,'Origem '!$A$1:$D$181,4,0) -> 2480 | F32: =VLOOKUP(B32,'Origem '!$A$1:$E$181,5,0) -> 3328 | G32: =VLOOKUP(B32,'Origem '!$A$1:$F$181,6,0) -> 3328 | H32: =VLOOKUP(B32,'Origem '!$A$1:$G$181,7,0) -> 3495 | I32: =VLOOKUP(B32,'Origem '!$A$1:$H$181,8,0) -> 3609 | J32: =E32*'Mark Up '!$C$2 -> 11457.6 | K32: =F32*'Mark Up '!$C$2 -> 15375.36 | L32: =G32*'Mark Up '!$C$2 -> 15375.36 | M32: =H32*'Mark Up '!$C$2 -> 16146.9 | N32: =I32*'Mark Up '!$C$2 -> 16673.58
B33: 11175-10 | C33: Mesa Centro Milhares "SOMENTE S/VIDRO" | D33: 1,80 x 0,70 x 0,32 | E33: =VLOOKUP(B33,'Origem '!$A$1:$D$181,4,0) -> 3004 | F33: =VLOOKUP(B33,'Origem '!$A$1:$E$181,5,0) -> 4085 | G33: =VLOOKUP(B33,'Origem '!$A$1:$F$181,6,0) -> 4085 | H33: =VLOOKUP(B33,'Origem '!$A$1:$G$181,7,0) -> 4357 | I33: =VLOOKUP(B33,'Origem '!$A$1:$H$181,8,0) -> 4477 | J33: =E33*'Mark Up '!$C$2 -> 13878.48 | K33: =F33*'Mark Up '!$C$2 -> 18872.7 | L33: =G33*'Mark Up '!$C$2 -> 18872.7 | M33: =H33*'Mark Up '!$C$2 -> 20129.34 | N33: =I33*'Mark Up '!$C$2 -> 20683.74
B34: 11175-11 | C34: Mesa Centro Milhares "SOMENTE S/VIDRO" | D34: 2,25 x 0,70 x 0,32 | E34: =VLOOKUP(B34,'Origem '!$A$1:$D$181,4,0) -> 3340 | F34: =VLOOKUP(B34,'Origem '!$A$1:$E$181,5,0) -> 4624 | G34: =VLOOKUP(B34,'Origem '!$A$1:$F$181,6,0) -> 4624 | H34: =VLOOKUP(B34,'Origem '!$A$1:$G$181,7,0) -> 4950 | I34: =VLOOKUP(B34,'Origem '!$A$1:$H$181,8,0) -> 5139 | J34: =E34*'Mark Up '!$C$2 -> 15430.8 | K34: =F34*'Mark Up '!$C$2 -> 21362.88 | L34: =G34*'Mark Up '!$C$2 -> 21362.88 | M34: =H34*'Mark Up '!$C$2 -> 22869 | N34: =I34*'Mark Up '!$C$2 -> 23742.18
B35: 11176-8 | C35: Mesa Centro Milhares C/ detalhe em pedra "SOMENTE S/VIDRO" | D35: 1,60 x 0,55 x 0,40 | E35: =VLOOKUP(B35,'Origem '!$A$1:$D$181,4,0) -> 2780 | F35: =VLOOKUP(B35,'Origem '!$A$1:$E$181,5,0) -> 3856 | G35: =VLOOKUP(B35,'Origem '!$A$1:$F$181,6,0) -> 3856 | H35: =VLOOKUP(B35,'Origem '!$A$1:$G$181,7,0) -> 4100 | I35: =VLOOKUP(B35,'Origem '!$A$1:$H$181,8,0) -> 4276 | J35: =E35*'Mark Up '!$C$2 -> 12843.6 | K35: =F35*'Mark Up '!$C$2 -> 17814.72 | L35: =G35*'Mark Up '!$C$2 -> 17814.72 | M35: =H35*'Mark Up '!$C$2 -> 18942 | N35: =I35*'Mark Up '!$C$2 -> 19755.12
B36: 11176-10 | C36: Mesa Centro Milhares C/ detalhe em pedra "SOMENTE S/VIDRO" | D36: 1,80 x 0,70 x 0,32 | E36: =VLOOKUP(B36,'Origem '!$A$1:$D$181,4,0) -> 3508 | F36: =VLOOKUP(B36,'Origem '!$A$1:$E$181,5,0) -> 4573 | G36: =VLOOKUP(B36,'Origem '!$A$1:$F$181,6,0) -> 4573 | H36: =VLOOKUP(B36,'Origem '!$A$1:$G$181,7,0) -> 4832 | I36: =VLOOKUP(B36,'Origem '!$A$1:$H$181,8,0) -> 4996 | J36: =E36*'Mark Up '!$C$2 -> 16206.96 | K36: =F36*'Mark Up '!$C$2 -> 21127.26 | L36: =G36*'Mark Up '!$C$2 -> 21127.26 | M36: =H36*'Mark Up '!$C$2 -> 22323.84 | N36: =I36*'Mark Up '!$C$2 -> 23081.52
B37: 11176-11 | C37: Mesa Centro Milhares C/ detalhe em pedra "SOMENTE S/VIDRO" | D37: 2,25 x 0,70 x 0,32 | E37: =VLOOKUP(B37,'Origem '!$A$1:$D$181,4,0) -> 3864 | F37: =VLOOKUP(B37,'Origem '!$A$1:$E$181,5,0) -> 5240 | G37: =VLOOKUP(B37,'Origem '!$A$1:$F$181,6,0) -> 5240 | H37: =VLOOKUP(B37,'Origem '!$A$1:$G$181,7,0) -> 5577 | I37: =VLOOKUP(B37,'Origem '!$A$1:$H$181,8,0) -> 5748 | J37: =E37*'Mark Up '!$C$2 -> 17851.68 | K37: =F37*'Mark Up '!$C$2 -> 24208.8 | L37: =G37*'Mark Up '!$C$2 -> 24208.8 | M37: =H37*'Mark Up '!$C$2 -> 25765.74 | N37: =I37*'Mark Up '!$C$2 -> 26555.76
A38: MUNIQUE | B38: 3218-8 | C38: Mesa Lateral Munique "SOMENTE S/VIDRO" | D38: 0,46 Ø X 0,50 | E38: =VLOOKUP(B38,'Origem '!$A$1:$D$181,4,0) -> 1112 | F38: =VLOOKUP(B38,'Origem '!$A$1:$E$181,5,0) -> 1235 | G38: =VLOOKUP(B38,'Origem '!$A$1:$F$181,6,0) -> 1235 | H38: =VLOOKUP(B38,'Origem '!$A$1:$G$181,7,0) -> 1304 | I38: =VLOOKUP(B38,'Origem '!$A$1:$H$181,8,0) -> 1327 | J38: =E38*'Mark Up '!$C$2 -> 5137.44 | K38: =F38*'Mark Up '!$C$2 -> 5705.7 | L38: =G38*'Mark Up '!$C$2 -> 5705.7 | M38: =H38*'Mark Up '!$C$2 -> 6024.48 | N38: =I38*'Mark Up '!$C$2 -> 6130.74
B39: 3218-12 | C39: Mesa Lateral Munique "SOMENTE S/VIDRO" | D39: 0,62 Ø X 0,60 | E39: =VLOOKUP(B39,'Origem '!$A$1:$D$181,4,0) -> 1251 | F39: =VLOOKUP(B39,'Origem '!$A$1:$E$181,5,0) -> 1445 | G39: =VLOOKUP(B39,'Origem '!$A$1:$F$181,6,0) -> 1445 | H39: =VLOOKUP(B39,'Origem '!$A$1:$G$181,7,0) -> 1566 | I39: =VLOOKUP(B39,'Origem '!$A$1:$H$181,8,0) -> 1607 | J39: =E39*'Mark Up '!$C$2 -> 5779.62 | K39: =F39*'Mark Up '!$C$2 -> 6675.9 | L39: =G39*'Mark Up '!$C$2 -> 6675.9 | M39: =H39*'Mark Up '!$C$2 -> 7234.92 | N39: =I39*'Mark Up '!$C$2 -> 7424.34
A40: NIDA | B40: 3196-3 | C40: Mesa Centro Nida "SOMENTE S/VIDRO" | D40: 0,70 Ø X 0,33 | E40: =VLOOKUP(B40,'Origem '!$A$1:$D$181,4,0) -> 1089 | F40: =VLOOKUP(B40,'Origem '!$A$1:$E$181,5,0) -> 1284 | G40: =VLOOKUP(B40,'Origem '!$A$1:$F$181,6,0) -> 1284 | H40: =VLOOKUP(B40,'Origem '!$A$1:$G$181,7,0) -> 1376 | I40: =VLOOKUP(B40,'Origem '!$A$1:$H$181,8,0) -> 1430 | J40: =E40*'Mark Up '!$C$2 -> 5031.18 | K40: =F40*'Mark Up '!$C$2 -> 5932.08 | L40: =G40*'Mark Up '!$C$2 -> 5932.08 | M40: =H40*'Mark Up '!$C$2 -> 6357.12 | N40: =I40*'Mark Up '!$C$2 -> 6606.6
...

Sheet Mesas Jantar e Mesa Apoio
C1: MESAS DE JANTAR E MESAS DE APOIO | H1: LANÇAMENTO 2025 | M1: LANÇAMENTO 2025
A2: COLEÇÃO | B2: REF | C2: DESCRIÇÃO | D2: COMP X PROF X ALT | E2: Em caso de cores diferentes Base ou Tampo, utilizar preço de maior valor | J2: Em caso de cores diferentes Base ou Tampo, utilizar preço de maior valor
E3: COLUNA 1 | F3: COLUNA 2 | G3: COLUNA 3 | H3: COLUNA 4 | I3: COLUNA 5 | J3: COLUNA 1 | K3: COLUNA 2 | L3: COLUNA 3 | M3: COLUNA 4 | N3: COLUNA 5
E4: LACA LISA BRAZIL ( COM OU SEM VIDRO PINTADO) | F4: - CARVALHO CLARO - CARVALHO NATURAL - CARVALHO LAVADO - CARV. EBANIZADO - IMBUIA CLARA * ACRESCENTAR 12% SE COM VIDRO PINTADO | G4: MESA COM TAMPO LACA LISA (COM OU SEM VIDRO PINTADO) E BASE EM: - CARVALHO CLARO - CARVALHO NATURAL - CARVALHO LAVADO - CARV. EBANIZADO - IMBUIA CLARA | H4: - NOGUEIRA - NOGUEIRA NATURAL - LOURO FREIJÓ - LOURO FREIJÓ NATURAL - CANELA - LACA METALIZADA BRAZIL - CARVALHO ÔNIX METALIZADO - CARVALHO N109 METALIZADO - CARVALHO ALBANIZADO - CARVALHO H155 FOSCO TAMPO COM OU SEM VIDRO - CONCRETO (SOMENTE SEM VIDRO) | I4: - PAU FERRO | J4: LACA LISA BRAZIL ( COM OU SEM VIDRO PINTADO) | K4: - CARVALHO CLARO - CARVALHO NATURAL - CARVALHO LAVADO - CARV. EBANIZADO - IMBUIA CLARA * ACRESCENTAR 12% SE COM VIDRO PINTADO | L4: MESA COM TAMPO LACA LISA (COM OU SEM VIDRO PINTADO) E BASE EM: - CARVALHO CLARO - CARVALHO NATURAL - CARVALHO LAVADO - CARV. EBANIZADO - IMBUIA CLARA | M4: - NOGUEIRA - NOGUEIRA NATURAL - LOURO FREIJÓ - LOURO FREIJÓ NATURAL - CANELA - LACA METALIZADA BRAZIL - CARVALHO ÔNIX METALIZADO - CARVALHO N109 METALIZADO - CARVALHO ALBANIZADO - CARVALHO H155 FOSCO TAMPO COM OU SEM VIDRO - CONCRETO (SOMENTE SEM VIDRO) | N4: - PAU FERRO
A5: DIJON | B5: 10060-6 | C5: Mesa Jantar Dijon (Tampo Canto Moeda) | D5: 1,80 x 1,00 x 0,76 | E5: =VLOOKUP(B5,'Origem '!$A$1:$D$181,4,0) -> 4503 | F5: =VLOOKUP(B5,'Origem '!$A$1:$E$181,5,0) -> 5058 | G5: =VLOOKUP(B5,'Origem '!$A$1:$F$181,6,0) -> 5293 | H5: =VLOOKUP(B5,'Origem '!$A$1:$G$181,7,0) -> 5338 | I5: =VLOOKUP(B5,'Origem '!$A$1:$H$181,8,0) -> 5463 | J5: =E5*'Mark Up '!$C$2 -> 20803.86 | K5: =F5*'Mark Up '!$C$2 -> 23367.96 | L5: =G5*'Mark Up '!$C$2 -> 24453.66 | M5: =H5*'Mark Up '!$C$2 -> 24661.56 | N5: =I5*'Mark Up '!$C$2 -> 25239.06
B6: 10060-7 | C6: Mesa Jantar Dijon (Tampo Canto Moeda) | D6: 2,00 x 1,00 x 0,76 | E6: =VLOOKUP(B6,'Origem '!$A$1:$D$181,4,0) -> 4718 | F6: =VLOOKUP(B6,'Origem '!$A$1:$E$181,5,0) -> 5453 | G6: =VLOOKUP(B6,'Origem '!$A$1:$F$181,6,0) -> 5614 | H6: =VLOOKUP(B6,'Origem '!$A$1:$G$181,7,0) -> 5670 | I6: =VLOOKUP(B6,'Origem '!$A$1:$H$181,8,0) -> 5712 | J6: =E6*'Mark Up '!$C$2 -> 21797.16 | K6: =F6*'Mark Up '!$C$2 -> 25192.86 | L6: =G6*'Mark Up '!$C$2 -> 25936.68 | M6: =H6*'Mark Up '!$C$2 -> 26195.4 | N6: =I6*'Mark Up '!$C$2 -> 26389.44
B7: 10060-8 | C7: Mesa Jantar Dijon (Tampo Canto Moeda) | D7: 2,20 x 1,10 x 0,76 | E7: =VLOOKUP(B7,'Origem '!$A$1:$D$181,4,0) -> 5191 | F7: =VLOOKUP(B7,'Origem '!$A$1:$E$181,5,0) -> 5697 | G7: =VLOOKUP(B7,'Origem '!$A$1:$F$181,6,0) -> 5994 | H7: =VLOOKUP(B7,'Origem '!$A$1:$G$181,7,0) -> 6032 | I7: =VLOOKUP(B7,'Origem '!$A$1:$H$181,8,0) -> 6160 | J7: =E7*'Mark Up '!$C$2 -> 23982.42 | K7: =F7*'Mark Up '!$C$2 -> 26320.14 | L7: =G7*'Mark Up '!$C$2 -> 27692.28 | M7: =H7*'Mark Up '!$C$2 -> 27867.84 | N7: =I7*'Mark Up '!$C$2 -> 28459.2
B8: 10060-9 | C8: Mesa Jantar Dijon (Tampo Canto Moeda) | D8: 2,40 x 1,10 x 0,76 | E8: =VLOOKUP(B8,'Origem '!$A$1:$D$181,4,0) -> 5452 | F8: =VLOOKUP(B8,'Origem '!$A$1:$E$181,5,0) -> 5900 | G8: =VLOOKUP(B8,'Origem '!$A$1:$F$181,6,0) -> 6285 | H8: =VLOOKUP(B8,'Origem '!$A$1:$G$181,7,0) -> 6314 | I8: =VLOOKUP(B8,'Origem '!$A$1:$H$181,8,0) -> 6445 | J8: =E8*'Mark Up '!$C$2 -> 25188.24 | K8: =F8*'Mark Up '!$C$2 -> 27258 | L8: =G8*'Mark Up '!$C$2 -> 29036.7 | M8: =H8*'Mark Up '!$C$2 -> 29170.68 | N8: =I8*'Mark Up '!$C$2 -> 29775.9
B9: 10060-12 | C9: Mesa Jantar Dijon (Tampo Canto Moeda) | D9: 2,70 x 1,20 x 0,76 | E9: =VLOOKUP(B9,'Origem '!$A$1:$D$181,4,0) -> 6086 | F9: =VLOOKUP(B9,'Origem '!$A$1:$E$181,5,0) -> 6392 | G9: =VLOOKUP(B9,'Origem '!$A$1:$F$181,6,0) -> 6983 | H9: =VLOOKUP(B9,'Origem '!$A$1:$G$181,7,0) -> 7003 | I9: =VLOOKUP(B9,'Origem '!$A$1:$H$181,8,0) -> 7136 | J9: =E9*'Mark Up '!$C$2 -> 28117.32 | K9: =F9*'Mark Up '!$C$2 -> 29531.04 | L9: =G9*'Mark Up '!$C$2 -> 32261.46 | M9: =H9*'Mark Up '!$C$2 -> 32353.86 | N9: =I9*'Mark Up '!$C$2 -> 32968.32
B10: 10060-13 | C10: Mesa Jantar Dijon (Tampo Canto Moeda) | D10: 3,00 x 1,20 x 0,76 | E10: =VLOOKUP(B10,'Origem '!$A$1:$D$181,4,0) -> 7185 | F10: =VLOOKUP(B10,'Origem '!$A$1:$E$181,5,0) -> 7701 | G10: =VLOOKUP(B10,'Origem '!$A$1:$F$181,6,0) -> 8348 | H10: =VLOOKUP(B10,'Origem '!$A$1:$G$181,7,0) -> 8357 | I10: =VLOOKUP(B10,'Origem '!$A$1:$H$181,8,0) -> 8494 | J10: =E10*'Mark Up '!$C$2 -> 33194.7 | K10: =F10*'Mark Up '!$C$2 -> 35578.62 | L10: =G10*'Mark Up '!$C$2 -> 38567.76 | M10: =H10*'Mark Up '!$C$2 -> 38609.34 | N10: =I10*'Mark Up '!$C$2 -> 39242.28
B11: 10060-14 | C11: Mesa Jantar Dijon (Tampo Canto Moeda) | D11: 3,20 x 1,20 x 0,76 | E11: =VLOOKUP(B11,'Origem '!$A$1:$D$181,4,0) -> 7384 | F11: =VLOOKUP(B11,'Origem '!$A$1:$E$181,5,0) -> 7915 | G11: =VLOOKUP(B11,'Origem '!$A$1:$F$181,6,0) -> 8608 | H11: =VLOOKUP(B11,'Origem '!$A$1:$G$181,7,0) -> 8620 | I11: =VLOOKUP(B11,'Origem '!$A$1:$H$181,8,0) -> 8757 | J11: =E11*'Mark Up '!$C$2 -> 34114.08 | K11: =F11*'Mark Up '!$C$2 -> 36567.3 | L11: =G11*'Mark Up '!$C$2 -> 39768.96 | M11: =H11*'Mark Up '!$C$2 -> 39824.4 | N11: =I11*'Mark Up '!$C$2 -> 40457.34
B12: 10061-6 | C12: Mesa Jantar Dijon (Tampo Canto Moeda c/ Marchetaria) | D12: 1,80 x 1,00 x 0,76 | E12: =VLOOKUP(B12,'Origem '!$A$1:$D$181,4,0) -> 5179 | F12: =VLOOKUP(B12,'Origem '!$A$1:$E$181,5,0) -> 5817 | G12: =VLOOKUP(B12,'Origem '!$A$1:$F$181,6,0) -> 6087 | H12: =VLOOKUP(B12,'Origem '!$A$1:$G$181,7,0) -> 6139 | I12: =VLOOKUP(B12,'Origem '!$A$1:$H$181,8,0) -> 6283 | J12: =E12*'Mark Up '!$C$2 -> 23926.98 | K12: =F12*'Mark Up '!$C$2 -> 26874.54 | L12: =G12*'Mark Up '!$C$2 -> 28121.94 | M12: =H12*'Mark Up '!$C$2 -> 28362.18 | N12: =I12*'Mark Up '!$C$2 -> 29027.46
B13: 10061-7 | C13: Mesa Jantar Dijon (Tampo Canto Moeda c/ Marchetaria) | D13: 2,00 x 1,00 x 0,76 | E13: =VLOOKUP(B13,'Origem '!$A$1:$D$181,4,0) -> 5426 | F13: =VLOOKUP(B13,'Origem '!$A$1:$E$181,5,0) -> 6271 | G13: =VLOOKUP(B13,'Origem '!$A$1:$F$181,6,0) -> 6457 | H13: =VLOOKUP(B13,'Origem '!$A$1:$G$181,7,0) -> 6521 | I13: =VLOOKUP(B13,'Origem '!$A$1:$H$181,8,0) -> 6569 | J13: =E13*'Mark Up '!$C$2 -> 25068.12 | K13: =F13*'Mark Up '!$C$2 -> 28972.02 | L13: =G13*'Mark Up '!$C$2 -> 29831.34 | M13: =H13*'Mark Up '!$C$2 -> 30127.02 | N13: =I13*'Mark Up '!$C$2 -> 30348.78
B14: 10061-8 | C14: Mesa Jantar Dijon (Tampo Canto Moeda c/ Marchetaria) | D14: 2,20 x 1,10 x 0,76 | E14: =VLOOKUP(B14,'Origem '!$A$1:$D$181,4,0) -> 5970 | F14: =VLOOKUP(B14,'Origem '!$A$1:$E$181,5,0) -> 6552 | G14: =VLOOKUP(B14,'Origem '!$A$1:$F$181,6,0) -> 6894 | H14: =VLOOKUP(B14,'Origem '!$A$1:$G$181,7,0) -> 6937 | I14: =VLOOKUP(B14,'Origem '!$A$1:$H$181,8,0) -> 7084 | J14: =E14*'Mark Up '!$C$2 -> 27581.4 | K14: =F14*'Mark Up '!$C$2 -> 30270.24 | L14: =G14*'Mark Up '!$C$2 -> 31850.28 | M14: =H14*'Mark Up '!$C$2 -> 32048.94 | N14: =I14*'Mark Up '!$C$2 -> 32728.08
