Workbook

Sheet Capa Tabela
A1: 2025/1
G3: 17 de Fevereiro 2025
A4: ACABAMENTOS:
A5: VIDROS:
A7: * Para colocar VIDRO EXTRA CLEAR, ESPELHO PRATA OU ESPELHO BRONZE, acrescentar ao móvel valor descrito na ultima página. * O vidro utilizado nos móveis é comum, pode haver diferença de tonalidade;
A8: * Vidros comum 4mm e extra clear 4mm medida maxima de 3,20x1,30 ou redondos e quadrados de 2,00x2,00
A9: * Vidros comum 6mm medida maxima de 3,59x1,50 ou redondos e quadrados de 2,00x2,00(sob consulta) esta espessura é mais esverdeado que o vidro comum 4mm
A10: OBS: A Nogueira o Carvalho e o Louro Freijó somente são fornecidos em laminados, as bases de madeira maciça serão produzidas em madeira tingida em cor semelhante.
A11: OBS: Os metais presentes nas peças podem ser feitos em qualquer cor de LACA PADRÃO BRILHO OU FOSCO (Informar no pedido)

Sheet Garantia

Sheet Cores Capa
A1: LACAS LISAS BRAZIL | C1: LACAS METALIZADAS BRAZIL | E1: MADEIRAS TINGIDAS | G1: CARVALHOS TINGIDOS
A2: Areia H109 Brilho / Fosco Branco Brilho / Fosco Cinza Claro H155 Brilho / Fosco Crômo Fosco Fendi N109 Brilho / Fosco Preto Fosco LACA CONCRETO BRAZIL Concreto (Somente s/ Vidro) | C2: Bronze Chumbo N109 Ônix METAIS Aço Cortein New Golden Preto Fosco Ônix Metalizado N109 Metalizado | E2: Imbuia Clara LÂMINAS Carvalho Louro Freijó Nogueira Pau Ferro | G2: Carvalho Claro Carvalho Ebanizado Carvalho Lavado Carvalho Natural CARVALHOS LAQUEADO Albanizado Cinza Claro (H155 Fosco) CARVALHOS METALIZADOS N109 Metalizado Ônix Metalizado
A4: OBS: Lacas especiais Sayerlack Brilho ou Fosca acrescentar 15% sobre a terceira coluna da tabela, se for laca especial metalizada ou perolizada consultar a empresa.

Sheet Mark Up 
A1: Local onde faz a multiplicação nas colunas da tabelas, se precisar dobrar o valor mudar o numero 1 para 2, se precisar triplicar o valor trocar numero 1 para 3 e por assim adiante.
A2: MARK UP | C2: 4.62

Sheet Origem 
A1: 9464-1 | B1: Aparador Alabama (canto garrafa) | C1: 1,40 x 0,45 x 0,76 | D1: 1939 | E1: 1995 | F1: 2187 | G1: X | H1: 0
A2: 9464-2 | B2: Aparador Alabama (canto garrafa) | C2: 1,60 x 0,45 x 0,76 | D2: 1990 | E2: 2070 | F2: 2276 | G2: X | H2: 0
A3: 9464-3 | B3: Aparador Alabama (canto garrafa) | C3: 1,80 x 0,45 x 0,76 | D3: 2179 | E3: 2287 | F3: 2556 | G3: X | H3: 0
A4: 9464-4 | B4: Aparador Alabama (canto garrafa) | C4: 2,00 x 0,45 x 0,76 | D4: 2304 | E4: 2399 | F4: 2628 | G4: X | H4: 0
A5: 9464-5 | B5: Aparador Alabama (canto garrafa) | C5: 2,20 x 0,45 x 0,76 | D5: 2423 | E5: 2530 | F5: 2762 | G5: X | H5: 0
A6: 4064-2 | B6: Aparador Aurora (3 gavetas marchetadas); pés metal | C6: 1,66 x 0,45 x 0,80 | D6: 3463 | E6: 4140 | F6: 4592 | G6: 4835 | H6: 0
A7: 4064-3 | B7: Aparador Aurora (3 gaveta marchetadas) pés metal | C7: 1,86 x 0,45 x 0,80 | D7: 3809 | E7: 4312 | F7: 4920 | G7: 5199 | H7: 0
A8: 4064-4 | B8: Aparador Aurora (3 gavetas marchetadas) pés metal | C8: 2,06 x 0,45 x 0,80 | D8: 3967 | E8: 4656 | F8: 5562 | G8: 5681 | H8: 0
A9: 4065-2 | B9: Aparador Aurora (c/ bandeja), pés metal | C9: 1,66 x 0,45 x 0,76 | D9: 2694 | E9: 3103 | F9: 3461 | G9: 3687 | H9: 0
A10: 4065-3 | B10: Aparador Aurora (c/ bandeja), pés metal | C10: 1,86 x 0,45 x 0,76 | D10: 2936 | E10: 3330 | F10: 3801 | G10: 4061 | H10: 0
A11: 4065-4 | B11: Aparador Aurora (c/ bandeja), pés metal | C11: 2,06 x 0,45 x 0,76 | D11: 3204 | E11: 3648 | F11: 4176 | G11: 4467 | H11: 0
A12: 10984-1 | B12: Aparador Baden ,tp e bandeja canto garrafa, pés metal (se laca brilho somente c/ VD) | C12: 1,40 x 0,39 x 0,75 | D12: 2233 | E12: 2455 | F12: 2790 | G12: 2945 | H12: 0
A13: 10984-2 | B13: Aparador Baden ,tp e bandeja canto garrafa, pés metal (se laca brilho somente c/ VD) | C13: 1,60 x 0,39 x 0,75 | D13: 2397 | E13: 2545 | F13: 2925 | G13: 3120 | H13: 0
A14: 10984-3 | B14: Aparador Baden ,tp e bandeja canto garrafa, pés metal (se laca brilho somente c/ VD) | C14: 1,80 x 0,39 x 0,75 | D14: 2504 | E14: 2717 | F14: 3199 | G14: 3368 | H14: 0
A15: 10984-4 | B15: Aparador Baden ,tp e bandeja canto garrafa, pés metal (se laca brilho somente c/ VD) | C15: 2,00 x 0,39 x 0,75 | D15: 2616 | E15: 2911 | F15: 3400 | G15: 3640 | H15: 0
A16: 11620-1 | B16: Aparador Bari TP.(Seul) | C16: 1,40 x 0,45 x 0,76 | D16: 1992 | E16: 2038 | F16: 2138 | G16: X | H16: 0
A17: 11620-2 | B17: Aparador Bari TP.(Seul) | C17: 1,60 x 0,45 x 0,76 | D17: 2110 | E17: 2177 | F17: 2399 | G17: X | H17: 0
A18: 11620-3 | B18: Aparador Bari TP.(Seul) | C18: 1,80 x 0,45 x 0,76 | D18: 2299 | E18: 2364 | F18: 2599 | G18: X | H18: 0
A19: 11640-2 | B19: Aparador Bogotá ,TP.Canto Garrafa; C/ MARCHETARIA | C19: 1,60 x 0,45 x 0,76 | D19: X | E19: 2311 | F19: 2554 | G19: 2940 | H19: 0
A20: 11640-3 | B20: Aparador Bogotá ,TP.Canto Garrafa; C/ MARCHETARIA | C20: 1,80 x 0,45 x 0,76 | D20: X | E20: 2424 | F20: 2678 | G20: 3172 | H20: 0
A21: 11640-4 | B21: Aparador Bogotá ,TP.Canto Garrafa; C/ MARCHETARIA | C21: 2,00 x 0,45 x 0,76 | D21: X | E21: 2520 | F21: 2788 | G21: 3306 | H21: 0
A22: 11641-2 | B22: Aparador Bogotá ,TP.Canto Garrafa; S/ MARCHETARIA | C22: 1,60 x 0,45 x 0,76 | D22: 1968 | E22: 2198 | F22: 2405 | G22: 2847 | H22: 0
A23: 11641-3 | B23: Aparador Bogotá ,TP.Canto Garrafa; S/ MARCHETARIA | C23: 1,80 x 0,45 x 0,76 | D23: 2088 | E23: 2300 | F23: 2522 | G23: 2989 | H23: 0
A24: 11641-4 | B24: Aparador Bogotá ,TP.Canto Garrafa; S/ MARCHETARIA | C24: 2,00 x 0,45 x 0,76 | D24: 2182 | E24: 2387 | F24: 2615 | G24: 3105 | H24: 0
A25: 9554-1 | B25: Aparador Copenhague (tmp oblongo) (se laca brilho somente c/ VD) | C25: 1,41 x 0,46 x 0,76 | D25: 2744 | E25: 3147 | F25: 3548 | G25: 3883 | H25: 0
A26: 9554-2 | B26: Aparador Copenhague (tmp oblongo) (se laca brilho somente c/ VD) | C26: 1,61 x 0,46 x 0,76 | D26: 2937 | E26: 3496 | F26: 3721 | G26: 4103 | H26: 0
A27: 9554-3 | B27: Aparador Copenhague (tmp oblongo) (se laca brilho somente c/ VD) | C27: 1,81 x 0,46 x 0,76 | D27: 3103 | E27: 3680 | F27: 3911 | G27: 4306 | H27: 0
A28: 4594-2 | B28: Aparador Ellos (canto garrafa), pés metal | C28: 1,35 x 0,35 x 0,76 | D28: 1774 | E28: 1923 | F28: 2139 | G28: 2191 | H28: 0
A29: 4594-3 | B29: Aparador Ellos (canto garrafa), pés metal | C29: 1,60 x 0,35 x 0,76 | D29: 1950 | E29: 2069 | F29: 2318 | G29: 2407 | H29: 0
A30: 4594-4 | B30: Aparador Ellos (canto garrafa), pés metal | C30: 1,80 x 0,35 x 0,76 | D30: 2233 | E30: 2352 | F30: 2575 | G30: 2688 | H30: 0
A31: 11034-1 | B31: Aparador Granada (tp oblongo), pés mad. (se laca brilho somente c/ VD) | C31: 1,46 x 0,45 x 0,76 | D31: 1640 | E31: 1714 | F31: 2068 | G31: X | H31: 0
A32: 11034-2 | B32: Aparador Granada (tp oblongo), pés mad. (se laca brilho somente c/ VD) | C32: 1,66 x 0,45 x 0,76 | D32: 1801 | E32: 1854 | F32: 2200 | G32: X | H32: 0
A33: 11034-3 | B33: Aparador Granada (tp oblongo), pés mad. (se laca brilho somente c/ VD) | C33: 1,86 x 0,45 x 0,76 | D33: 1890 | E33: 1942 | F33: 2325 | G33: X | H33: 0
A34: 11034-4 | B34: Aparador Granada (tp oblongo), pés mad. (se laca brilho somente c/ VD) | C34: 2,06 x 0,45 x 0,76 | D34: 2056 | E34: 2126 | F34: 2493 | G34: X | H34: 0
A35: 10484-1 | B35: Aparador Madagascar (tp oblongo), pés metal; (com tampo sobreposto) | C35: 1,36 x 0,39 x 0,76 | D35: 1964 | E35: 2076 | F35: 2356 | G35: 2493 | H35: 0
A36: 10484-2 | B36: Aparador Madagascar (tp oblongo), pés metal; (com tampo sobreposto) | C36: 1,56 x 0,39 x 0,76 | D36: 2079 | E36: 2279 | F36: 2494 | G36: 2640 | H36: 0
A37: 10484-3 | B37: Aparador Madagascar (tp oblongo), pés metal; (com tampo sobreposto) | C37: 1,76 x 0,39 x 0,76 | D37: 2193 | E37: 2365 | F37: 2636 | G37: 2769 | H37: 0
A38: 10484-4 | B38: Aparador Madagascar (tp oblongo), pés metal; (com tampo sobreposto) | C38: 1,96 x 0,39 x 0,76 | D38: 2276 | E38: 2492 | F38: 2790 | G38: 2946 | H38: 0
A39: 11294-1 | B39: Aparador Maracatu, c/ 2 gavetas (se laca brilho somente c/ VD) | C39: 1,51 x 0,46 x 0,78 | D39: 3007 | E39: 3257 | F39: 3985 | G39: X | H39: 0
A40: 11294-2 | B40: Aparador Maracatu, c/ 2 gavetas (se laca brilho somente c/ VD) | C40: 1,71 x 0,46 x 0,78 | D40: 3340 | E40: 3598 | F40: 4386 | G40: X | H40: 0
...

Sheet Aparadores
C1: APARADORES | I1: AMBIENTADAS
A2: COLEÇÃO | B2: REF | C2: DESCRIÇÃO | D2: COMP X PROF X ALT | E2: Em caso de cores diferentes Base ou Tampo, utilizar preço de maior valor
E3: COLUNA 1 | F3: COLUNA 2 | G3: COLUNA 3 | H3: COLUNA 4
E4: LACA LISA BRAZIL ( COM OU SEM VIDRO PINTADO) | F4: - CARVALHO CLARO - CARVALHO NATURAL - CARVALHO LAVADO - CARV. EBANIZADO - IMBUIA CLARA * ACRESCENTAR 12% SE COM VIDRO PINTADO | G4: - NOGUEIRA - NOGUEIRA NATURAL - LOURO FREIJÓ - LOURO FREIJÓ NATURAL - CANELA - LACA METALIZADA BRAZIL - CARV. ÔNIX METALIZADO - CARV. N109 METALIZADO - CARV. ALBANIZADO - CARV. H155 FOSCO - CONCRETO (SOMENTE SEM VIDRO) | H4: - PAU FERRO
E5: OBS. O ACABAMENTO DO METAL NÃO INFLUENCIARÁ NO VALOR DO APARADOR
A6: ALABAMA | B6: 9464-1 | C6: Aparador Alabama (canto garrafa) | D6: 1,40 x 0,45 x 0,76 | E6: =IFERROR((VLOOKUP(B6,'Origem '!$A$1:$H$1002,4,0)*'Mark Up '!$C$2),"X") -> 8958.18 | F6: =IFERROR((VLOOKUP(B6,'Origem '!$A$1:$H$1002,5,0)*'Mark Up '!$C$2),"X") -> 9216.9 | G6: =IFERROR((VLOOKUP(B6,'Origem '!$A$1:$H$1002,6,0)*'Mark Up '!$C$2),"X") -> 10103.94 | H6: =IFERROR((VLOOKUP(B6,'Origem '!$A$1:$H$1002,7,0)*'Mark Up '!$C$2),"X") -> X
B7: 9464-2 | C7: Aparador Alabama (canto garrafa) | D7: 1,60 x 0,45 x 0,76 | E7: =IFERROR((VLOOKUP(B7,'Origem '!$A$1:$H$1002,4,0)*'Mark Up '!$C$2),"X") -> 9193.8 | F7: =IFERROR((VLOOKUP(B7,'Origem '!$A$1:$H$1002,5,0)*'Mark Up '!$C$2),"X") -> 9563.4 | G7: =IFERROR((VLOOKUP(B7,'Origem '!$A$1:$H$1002,6,0)*'Mark Up '!$C$2),"X") -> 10515.12 | H7: =IFERROR((VLOOKUP(B7,'Origem '!$A$1:$H$1002,7,0)*'Mark Up '!$C$2),"X") -> X
B8: 9464-3 | C8: Aparador Alabama (canto garrafa) | D8: 1,80 x 0,45 x 0,76 | E8: =IFERROR((VLOOKUP(B8,'Origem '!$A$1:$H$1002,4,0)*'Mark Up '!$C$2),"X") -> 10066.98 | F8: =IFERROR((VLOOKUP(B8,'Origem '!$A$1:$H$1002,5,0)*'Mark Up '!$C$2),"X") -> 10565.94 | G8: =IFERROR((VLOOKUP(B8,'Origem '!$A$1:$H$1002,6,0)*'Mark Up '!$C$2),"X") -> 11808.72 | H8: =IFERROR((VLOOKUP(B8,'Origem '!$A$1:$H$1002,7,0)*'Mark Up '!$C$2),"X") -> X
B9: 9464-4 | C9: Aparador Alabama (canto garrafa) | D9: 2,00 x 0,45 x 0,76 | E9: =IFERROR((VLOOKUP(B9,'Origem '!$A$1:$H$1002,4,0)*'Mark Up '!$C$2),"X") -> 10644.48 | F9: =IFERROR((VLOOKUP(B9,'Origem '!$A$1:$H$1002,5,0)*'Mark Up '!$C$2),"X") -> 11083.38 | G9: =IFERROR((VLOOKUP(B9,'Origem '!$A$1:$H$1002,6,0)*'Mark Up '!$C$2),"X") -> 12141.36 | H9: =IFERROR((VLOOKUP(B9,'Origem '!$A$1:$H$1002,7,0)*'Mark Up '!$C$2),"X") -> X
B10: 9464-5 | C10: Aparador Alabama (canto garrafa) | D10: 2,20 x 0,45 x 0,76 | E10: =IFERROR((VLOOKUP(B10,'Origem '!$A$1:$H$1002,4,0)*'Mark Up '!$C$2),"X") -> 11194.26 | F10: =IFERROR((VLOOKUP(B10,'Origem '!$A$1:$H$1002,5,0)*'Mark Up '!$C$2),"X") -> 11688.6 | G10: =IFERROR((VLOOKUP(B10,'Origem '!$A$1:$H$1002,6,0)*'Mark Up '!$C$2),"X") -> 12760.44 | H10: =IFERROR((VLOOKUP(B10,'Origem '!$A$1:$H$1002,7,0)*'Mark Up '!$C$2),"X") -> X
A11: AURORA | B11: 4064-2 | C11: Aparador Aurora (3 gavetas marchetadas); pés metal | D11: 1,66 x 0,45 x 0,80 | E11: =IFERROR((VLOOKUP(B11,'Origem '!$A$1:$H$1002,4,0)*'Mark Up '!$C$2),"X") -> 15999.06 | F11: =IFERROR((VLOOKUP(B11,'Origem '!$A$1:$H$1002,5,0)*'Mark Up '!$C$2),"X") -> 19126.8 | G11: =IFERROR((VLOOKUP(B11,'Origem '!$A$1:$H$1002,6,0)*'Mark Up '!$C$2),"X") -> 21215.04 | H11: =IFERROR((VLOOKUP(B11,'Origem '!$A$1:$H$1002,7,0)*'Mark Up '!$C$2),"X") -> 22337.7
B12: 4064-3 | C12: Aparador Aurora (3 gaveta marchetadas) pés metal | D12: 1,86 x 0,45 x 0,80 | E12: =IFERROR((VLOOKUP(B12,'Origem '!$A$1:$H$1002,4,0)*'Mark Up '!$C$2),"X") -> 17597.58 | F12: =IFERROR((VLOOKUP(B12,'Origem '!$A$1:$H$1002,5,0)*'Mark Up '!$C$2),"X") -> 19921.44 | G12: =IFERROR((VLOOKUP(B12,'Origem '!$A$1:$H$1002,6,0)*'Mark Up '!$C$2),"X") -> 22730.4 | H12: =IFERROR((VLOOKUP(B12,'Origem '!$A$1:$H$1002,7,0)*'Mark Up '!$C$2),"X") -> 24019.38
B13: 4064-4 | C13: Aparador Aurora (3 gavetas marchetadas) pés metal | D13: 2,06 x 0,45 x 0,80 | E13: =IFERROR((VLOOKUP(B13,'Origem '!$A$1:$H$1002,4,0)*'Mark Up '!$C$2),"X") -> 18327.54 | F13: =IFERROR((VLOOKUP(B13,'Origem '!$A$1:$H$1002,5,0)*'Mark Up '!$C$2),"X") -> 21510.72 | G13: =IFERROR((VLOOKUP(B13,'Origem '!$A$1:$H$1002,6,0)*'Mark Up '!$C$2),"X") -> 25696.44 | H13: =IFERROR((VLOOKUP(B13,'Origem '!$A$1:$H$1002,7,0)*'Mark Up '!$C$2),"X") -> 26246.22
B14: 4065-2 | C14: Aparador Aurora (c/ bandeja), pés metal | D14: 1,66 x 0,45 x 0,76 | E14: =IFERROR((VLOOKUP(B14,'Origem '!$A$1:$H$1002,4,0)*'Mark Up '!$C$2),"X") -> 12446.28 | F14: =IFERROR((VLOOKUP(B14,'Origem '!$A$1:$H$1002,5,0)*'Mark Up '!$C$2),"X") -> 14335.86 | G14: =IFERROR((VLOOKUP(B14,'Origem '!$A$1:$H$1002,6,0)*'Mark Up '!$C$2),"X") -> 15989.82 | H14: =IFERROR((VLOOKUP(B14,'Origem '!$A$1:$H$1002,7,0)*'Mark Up '!$C$2),"X") -> 17033.94
B15: 4065-3 | C15: Aparador Aurora (c/ bandeja), pés metal | D15: 1,86 x 0,45 x 0,76 | E15: =IFERROR((VLOOKUP(B15,'Origem '!$A$1:$H$1002,4,0)*'Mark Up '!$C$2),"X") -> 13564.32 | F15: =IFERROR((VLOOKUP(B15,'Origem '!$A$1:$H$1002,5,0)*'Mark Up '!$C$2),"X") -> 15384.6 | G15: =IFERROR((VLOOKUP(B15,'Origem '!$A$1:$H$1002,6,0)*'Mark Up '!$C$2),"X") -> 17560.62 | H15: =IFERROR((VLOOKUP(B15,'Origem '!$A$1:$H$1002,7,0)*'Mark Up '!$C$2),"X") -> 18761.82
B16: 4065-4 | C16: Aparador Aurora (c/ bandeja), pés metal | D16: 2,06 x 0,45 x 0,76 | E16: =IFERROR((VLOOKUP(B16,'Origem '!$A$1:$H$1002,4,0)*'Mark Up '!$C$2),"X") -> 14802.48 | F16: =IFERROR((VLOOKUP(B16,'Origem '!$A$1:$H$1002,5,0)*'Mark Up '!$C$2),"X") -> 16853.76 | G16: =IFERROR((VLOOKUP(B16,'Origem '!$A$1:$H$1002,6,0)*'Mark Up '!$C$2),"X") -> 19293.12 | H16: =IFERROR((VLOOKUP(B16,'Origem '!$A$1:$H$1002,7,0)*'Mark Up '!$C$2),"X") -> 20637.54
A17: BADEN | B17: 10984-1 | C17: Aparador Baden ,tp e bandeja canto garrafa, pés metal (se laca brilho somente c/ VD) | D17: 1,40 x 0,39 x 0,76 | E17: =IFERROR((VLOOKUP(B17,'Origem '!$A$1:$H$1002,4,0)*'Mark Up '!$C$2),"X") -> 10316.46 | F17: =IFERROR((VLOOKUP(B17,'Origem '!$A$1:$H$1002,5,0)*'Mark Up '!$C$2),"X") -> 11342.1 | G17: =IFERROR((VLOOKUP(B17,'Origem '!$A$1:$H$1002,6,0)*'Mark Up '!$C$2),"X") -> 12889.8 | H17: =IFERROR((VLOOKUP(B17,'Origem '!$A$1:$H$1002,7,0)*'Mark Up '!$C$2),"X") -> 13605.9
B18: 10984-2 | C18: Aparador Baden ,tp e bandeja canto garrafa, pés metal (se laca brilho somente c/ VD) | D18: 1,60 x 0,39 x 0,76 | E18: =IFERROR((VLOOKUP(B18,'Origem '!$A$1:$H$1002,4,0)*'Mark Up '!$C$2),"X") -> 11074.14 | F18: =IFERROR((VLOOKUP(B18,'Origem '!$A$1:$H$1002,5,0)*'Mark Up '!$C$2),"X") -> 11757.9 | G18: =IFERROR((VLOOKUP(B18,'Origem '!$A$1:$H$1002,6,0)*'Mark Up '!$C$2),"X") -> 13513.5 | H18: =IFERROR((VLOOKUP(B18,'Origem '!$A$1:$H$1002,7,0)*'Mark Up '!$C$2),"X") -> 14414.4
B19: 10984-3 | C19: Aparador Baden ,tp e bandeja canto garrafa, pés metal (se laca brilho somente c/ VD) | D19: 1,80 x 0,39 x 0,76 | E19: =IFERROR((VLOOKUP(B19,'Origem '!$A$1:$H$1002,4,0)*'Mark Up '!$C$2),"X") -> 11568.48 | F19: =IFERROR((VLOOKUP(B19,'Origem '!$A$1:$H$1002,5,0)*'Mark Up '!$C$2),"X") -> 12552.54 | G19: =IFERROR((VLOOKUP(B19,'Origem '!$A$1:$H$1002,6,0)*'Mark Up '!$C$2),"X") -> 14779.38 | H19: =IFERROR((VLOOKUP(B19,'Origem '!$A$1:$H$1002,7,0)*'Mark Up '!$C$2),"X") -> 15560.16
B20: 10984-4 | C20: Aparador Baden ,tp e bandeja canto garrafa, pés metal (se laca brilho somente c/ VD) | D20: 2,00 x 0,39 x 0,76 | E20: =IFERROR((VLOOKUP(B20,'Origem '!$A$1:$H$1002,4,0)*'Mark Up '!$C$2),"X") -> 12085.92 | F20: =IFERROR((VLOOKUP(B20,'Origem '!$A$1:$H$1002,5,0)*'Mark Up '!$C$2),"X") -> 13448.82 | G20: =IFERROR((VLOOKUP(B20,'Origem '!$A$1:$H$1002,6,0)*'Mark Up '!$C$2),"X") -> 15708 | H20: =IFERROR((VLOOKUP(B20,'Origem '!$A$1:$H$1002,7,0)*'Mark Up '!$C$2),"X") -> 16816.8
A21: BARI | B21: 11620-1 | C21: Aparador Bari pés Mad. | D21: 1,40 x 0,45 x 0,76 | E21: =IFERROR((VLOOKUP(B21,'Origem '!$A$1:$H$1002,4,0)*'Mark Up '!$C$2),"X") -> 9203.04 | F21: =IFERROR((VLOOKUP(B21,'Origem '!$A$1:$H$1002,5,0)*'Mark Up '!$C$2),"X") -> 9415.56 | G21: =IFERROR((VLOOKUP(B21,'Origem '!$A$1:$H$1002,6,0)*'Mark Up '!$C$2),"X") -> 9877.56 | H21: =IFERROR((VLOOKUP(B21,'Origem '!$A$1:$H$1002,7,0)*'Mark Up '!$C$2),"X") -> X
B22: 11620-2 | C22: Aparador Bari pés Mad. | D22: 1,60 x 0,45 x 0,76 | E22: =IFERROR((VLOOKUP(B22,'Origem '!$A$1:$H$1002,4,0)*'Mark Up '!$C$2),"X") -> 9748.2 | F22: =IFERROR((VLOOKUP(B22,'Origem '!$A$1:$H$1002,5,0)*'Mark Up '!$C$2),"X") -> 10057.74 | G22: =IFERROR((VLOOKUP(B22,'Origem '!$A$1:$H$1002,6,0)*'Mark Up '!$C$2),"X") -> 11083.38 | H22: =IFERROR((VLOOKUP(B22,'Origem '!$A$1:$H$1002,7,0)*'Mark Up '!$C$2),"X") -> X
B23: 11620-3 | C23: Aparador Bari pés Mad. | D23: 1,80 x 0,45 x 0,76 | E23: =IFERROR((VLOOKUP(B23,'Origem '!$A$1:$H$1002,4,0)*'Mark Up '!$C$2),"X") -> 10621.38 | F23: =IFERROR((VLOOKUP(B23,'Origem '!$A$1:$H$1002,5,0)*'Mark Up '!$C$2),"X") -> 10921.68 | G23: =IFERROR((VLOOKUP(B23,'Origem '!$A$1:$H$1002,6,0)*'Mark Up '!$C$2),"X") -> 12007.38 | H23: =IFERROR((VLOOKUP(B23,'Origem '!$A$1:$H$1002,7,0)*'Mark Up '!$C$2),"X") -> X
A24: BOGOTÁ | B24: 11640-2 | C24: Aparador Bogotá ,TP.Canto Garrafa; C/ MARCHETARIA | D24: 1,60 x 0,45 x 0,76 | E24: =IFERROR((VLOOKUP(B24,'Origem '!$A$1:$H$1002,4,0)*'Mark Up '!$C$2),"X") -> X | F24: =IFERROR((VLOOKUP(B24,'Origem '!$A$1:$H$1002,5,0)*'Mark Up '!$C$2),"X") -> 10676.82 | G24: =IFERROR((VLOOKUP(B24,'Origem '!$A$1:$H$1002,6,0)*'Mark Up '!$C$2),"X") -> 11799.48 | H24: =IFERROR((VLOOKUP(B24,'Origem '!$A$1:$H$1002,7,0)*'Mark Up '!$C$2),"X") -> 13582.8
B25: 11640-3 | C25: Aparador Bogotá ,TP.Canto Garrafa; C/ MARCHETARIA | D25: 1,80 x 0,45 x 0,76 | E25: =IFERROR((VLOOKUP(B25,'Origem '!$A$1:$H$1002,4,0)*'Mark Up '!$C$2),"X") -> X | F25: =IFERROR((VLOOKUP(B25,'Origem '!$A$1:$H$1002,5,0)*'Mark Up '!$C$2),"X") -> 11198.88 | G25: =IFERROR((VLOOKUP(B25,'Origem '!$A$1:$H$1002,6,0)*'Mark Up '!$C$2),"X") -> 12372.36 | H25: =IFERROR((VLOOKUP(B25,'Origem '!$A$1:$H$1002,7,0)*'Mark Up '!$C$2),"X") -> 14654.64
B26: 11640-4 | C26: Aparador Bogotá ,TP.Canto Garrafa; C/ MARCHETARIA | D26: 2,00 x 0,45 x 0,76 | E26: =IFERROR((VLOOKUP(B26,'Origem '!$A$1:$H$1002,4,0)*'Mark Up '!$C$2),"X") -> X | F26: =IFERROR((VLOOKUP(B26,'Origem '!$A$1:$H$1002,5,0)*'Mark Up '!$C$2),"X") -> 11642.4 | G26: =IFERROR((VLOOKUP(B26,'Origem '!$A$1:$H$1002,6,0)*'Mark Up '!$C$2),"X") -> 12880.56 | H26: =IFERROR((VLOOKUP(B26,'Origem '!$A$1:$H$1002,7,0)*'Mark Up '!$C$2),"X") -> 15273.72
B27: 11641-2 | C27: Aparador Bogotá ,TP.Canto Garrafa; S/ MARCHETARIA | D27: 1,60 x 0,45 x 0,76 | E27: =IFERROR((VLOOKUP(B27,'Origem '!$A$1:$H$1002,4,0)*'Mark Up '!$C$2),"X") -> 9092.16 | F27: =IFERROR((VLOOKUP(B27,'Origem '!$A$1:$H$1002,5,0)*'Mark Up '!$C$2),"X") -> 10154.76 | G27: =IFERROR((VLOOKUP(B27,'Origem '!$A$1:$H$1002,6,0)*'Mark Up '!$C$2),"X") -> 11111.1 | H27: =IFERROR((VLOOKUP(B27,'Origem '!$A$1:$H$1002,7,0)*'Mark Up '!$C$2),"X") -> 13153.14
B28: 11641-3 | C28: Aparador Bogotá ,TP.Canto Garrafa; S/ MARCHETARIA | D28: 1,80 x 0,45 x 0,76 | E28: =IFERROR((VLOOKUP(B28,'Origem '!$A$1:$H$1002,4,0)*'Mark Up '!$C$2),"X") -> 9646.56 | F28: =IFERROR((VLOOKUP(B28,'Origem '!$A$1:$H$1002,5,0)*'Mark Up '!$C$2),"X") -> 10626 | G28: =IFERROR((VLOOKUP(B28,'Origem '!$A$1:$H$1002,6,0)*'Mark Up '!$C$2),"X") -> 11651.64 | H28: =IFERROR((VLOOKUP(B28,'Origem '!$A$1:$H$1002,7,0)*'Mark Up '!$C$2),"X") -> 13809.18
B29: 11641-4 | C29: Aparador Bogotá ,TP.Canto Garrafa; S/ MARCHETARIA | D29: 2,00 x 0,45 x 0,76 | E29: =IFERROR((VLOOKUP(B29,'Origem '!$A$1:$H$1002,4,0)*'Mark Up '!$C$2),"X") -> 10080.84 | F29: =IFERROR((VLOOKUP(B29,'Origem '!$A$1:$H$1002,5,0)*'Mark Up '!$C$2),"X") -> 11027.94 | G29: =IFERROR((VLOOKUP(B29,'Origem '!$A$1:$H$1002,6,0)*'Mark Up '!$C$2),"X") -> 12081.3 | H29: =IFERROR((VLOOKUP(B29,'Origem '!$A$1:$H$1002,7,0)*'Mark Up '!$C$2),"X") -> 14345.1
A30: CILDO | B30: 11104-4 | C30: Aparador Cildo "SOMENTE SEM VIDRO" | D30: 2,00 X 0,50 X 0,76 | E30: =IFERROR((VLOOKUP(B30,'Origem '!$A$1:$H$1002,4,0)*'Mark Up '!$C$2),"X") -> 17514.42 | F30: =IFERROR((VLOOKUP(B30,'Origem '!$A$1:$H$1002,5,0)*'Mark Up '!$C$2),"X") -> 20836.2 | G30: =IFERROR((VLOOKUP(B30,'Origem '!$A$1:$H$1002,6,0)*'Mark Up '!$C$2),"X") -> 23067.66 | H30: =IFERROR((VLOOKUP(B30,'Origem '!$A$1:$H$1002,7,0)*'Mark Up '!$C$2),"X") -> 24051.72
B31: 11104-5 | C31: Aparador Cildo "SOMENTE SEM VIDRO" | D31: 2,20 X 0,50 X 0,76 | E31: =IFERROR((VLOOKUP(B31,'Origem '!$A$1:$H$1002,4,0)*'Mark Up '!$C$2),"X") -> 18133.5 | F31: =IFERROR((VLOOKUP(B31,'Origem '!$A$1:$H$1002,5,0)*'Mark Up '!$C$2),"X") -> 21903.42 | G31: =IFERROR((VLOOKUP(B31,'Origem '!$A$1:$H$1002,6,0)*'Mark Up '!$C$2),"X") -> 24282.72 | H31: =IFERROR((VLOOKUP(B31,'Origem '!$A$1:$H$1002,7,0)*'Mark Up '!$C$2),"X") -> 25081.98
B32: 11104-6 | C32: Aparador Cildo "SOMENTE SEM VIDRO" | D32: 2,40 X 0,50 X 0,76 | E32: =IFERROR((VLOOKUP(B32,'Origem '!$A$1:$H$1002,4,0)*'Mark Up '!$C$2),"X") -> 19547.22 | F32: =IFERROR((VLOOKUP(B32,'Origem '!$A$1:$H$1002,5,0)*'Mark Up '!$C$2),"X") -> 23534.28 | G32: =IFERROR((VLOOKUP(B32,'Origem '!$A$1:$H$1002,6,0)*'Mark Up '!$C$2),"X") -> 26227.74 | H32: =IFERROR((VLOOKUP(B32,'Origem '!$A$1:$H$1002,7,0)*'Mark Up '!$C$2),"X") -> 27087.06
A33: COBK | B33: 1014-1 | C33: Aparador Cobk Vidro Apenas na Bandeja, Pés Metal | D33: 1,36 x 0,39 x 0,76 | E33: =IFERROR((VLOOKUP(B33,'Origem '!$A$1:$H$1002,4,0)*'Mark Up '!$C$2),"X") -> 9309.3 | F33: =IFERROR((VLOOKUP(B33,'Origem '!$A$1:$H$1002,5,0)*'Mark Up '!$C$2),"X") -> 10690.68 | G33: =IFERROR((VLOOKUP(B33,'Origem '!$A$1:$H$1002,6,0)*'Mark Up '!$C$2),"X") -> 11859.54 | H33: =IFERROR((VLOOKUP(B33,'Origem '!$A$1:$H$1002,7,0)*'Mark Up '!$C$2),"X") -> 12136.74
B34: 1014-2 | C34: Aparador Cobk Vidro Apenas na Bandeja, Pés Metal | D34: 1,60 x 0,39 x 0,76 | E34: =IFERROR((VLOOKUP(B34,'Origem '!$A$1:$H$1002,4,0)*'Mark Up '!$C$2),"X") -> 9651.18 | F34: =IFERROR((VLOOKUP(B34,'Origem '!$A$1:$H$1002,5,0)*'Mark Up '!$C$2),"X") -> 11240.46 | G34: =IFERROR((VLOOKUP(B34,'Origem '!$A$1:$H$1002,6,0)*'Mark Up '!$C$2),"X") -> 12270.72 | H34: =IFERROR((VLOOKUP(B34,'Origem '!$A$1:$H$1002,7,0)*'Mark Up '!$C$2),"X") -> 12732.72
B35: 1014-3 | C35: Aparador Cobk Vidro Apenas na Bandeja, Pés Metal | D35: 1,80 x 0,39 x 0,76 | E35: =IFERROR((VLOOKUP(B35,'Origem '!$A$1:$H$1002,4,0)*'Mark Up '!$C$2),"X") -> 10168.62 | F35: =IFERROR((VLOOKUP(B35,'Origem '!$A$1:$H$1002,5,0)*'Mark Up '!$C$2),"X") -> 11905.74 | G35: =IFERROR((VLOOKUP(B35,'Origem '!$A$1:$H$1002,6,0)*'Mark Up '!$C$2),"X") -> 13000.68 | H35: =IFERROR((VLOOKUP(B35,'Origem '!$A$1:$H$1002,7,0)*'Mark Up '!$C$2),"X") -> 13245.54
B36: 1014-4 | C36: Aparador Cobk Vidro Apenas na Bandeja, Pés Metal | D36: 2,00 x 0,39 x 0,76 | E36: =IFERROR((VLOOKUP(B36,'Origem '!$A$1:$H$1002,4,0)*'Mark Up '!$C$2),"X") -> 10852.38 | F36: =IFERROR((VLOOKUP(B36,'Origem '!$A$1:$H$1002,5,0)*'Mark Up '!$C$2),"X") -> 12681.9 | G36: =IFERROR((VLOOKUP(B36,'Origem '!$A$1:$H$1002,6,0)*'Mark Up '!$C$2),"X") -> 14206.5 | H36: =IFERROR((VLOOKUP(B36,'Origem '!$A$1:$H$1002,7,0)*'Mark Up '!$C$2),"X") -> 14423.64
A37: COPENHAGUE | B37: 9554-1 | C37: Aparador Copenhague (tmp oblongo) (se laca brilho somente c/ VD) | D37: 1,41 x 0,46 x 0,76 | E37: =IFERROR((VLOOKUP(B37,'Origem '!$A$1:$H$1002,4,0)*'Mark Up '!$C$2),"X") -> 12677.28 | F37: =IFERROR((VLOOKUP(B37,'Origem '!$A$1:$H$1002,5,0)*'Mark Up '!$C$2),"X") -> 14539.14 | G37: =IFERROR((VLOOKUP(B37,'Origem '!$A$1:$H$1002,6,0)*'Mark Up '!$C$2),"X") -> 16391.76 | H37: =IFERROR((VLOOKUP(B37,'Origem '!$A$1:$H$1002,7,0)*'Mark Up '!$C$2),"X") -> 17939.46
B38: 9554-2 | C38: Aparador Copenhague (tmp oblongo) (se laca brilho somente c/ VD) | D38: 1,61 x 0,46 x 0,76 | E38: =IFERROR((VLOOKUP(B38,'Origem '!$A$1:$H$1002,4,0)*'Mark Up '!$C$2),"X") -> 13568.94 | F38: =IFERROR((VLOOKUP(B38,'Origem '!$A$1:$H$1002,5,0)*'Mark Up '!$C$2),"X") -> 16151.52 | G38: =IFERROR((VLOOKUP(B38,'Origem '!$A$1:$H$1002,6,0)*'Mark Up '!$C$2),"X") -> 17191.02 | H38: =IFERROR((VLOOKUP(B38,'Origem '!$A$1:$H$1002,7,0)*'Mark Up '!$C$2),"X") -> 18955.86
B39: 9554-3 | C39: Aparador Copenhague (tmp oblongo) (se laca brilho somente c/ VD) | D39: 1,81 x 0,46 x 0,76 | E39: =IFERROR((VLOOKUP(B39,'Origem '!$A$1:$H$1002,4,0)*'Mark Up '!$C$2),"X") -> 14335.86 | F39: =IFERROR((VLOOKUP(B39,'Origem '!$A$1:$H$1002,5,0)*'Mark Up '!$C$2),"X") -> 17001.6 | G39: =IFERROR((VLOOKUP(B39,'Origem '!$A$1:$H$1002,6,0)*'Mark Up '!$C$2),"X") -> 18068.82 | H39: =IFERROR((VLOOKUP(B39,'Origem '!$A$1:$H$1002,7,0)*'Mark Up '!$C$2),"X") -> 19893.72
A40: ELLOS | B40: 4594-2 | C40: Aparador Ellos (canto garrafa), pés metal | D40: 1,35 x 0,35 x 0,76 | E40: =IFERROR((VLOOKUP(B40,'Origem '!$A$1:$H$1002,4,0)*'Mark Up '!$C$2),"X") -> 8195.88 | F40: =IFERROR((VLOOKUP(B40,'Origem '!$A$1:$H$1002,5,0)*'Mark Up '!$C$2),"X") -> 8884.26 | G40: =IFERROR((VLOOKUP(B40,'Origem '!$A$1:$H$1002,6,0)*'Mark Up '!$C$2),"X") -> 9882.18 | H40: =IFERROR((VLOOKUP(B40,'Origem '!$A$1:$H$1002,7,0)*'Mark Up '!$C$2),"X") -> 10122.42
...

Sheet Buffets
C1: BUFFETS | I1: AMBIENTADAS
A2: COLEÇÃO | B2: REF | C2: DESCRIÇÃO | D2: COMP X PROF X ALT | E2: Em caso de cores diferentes, utilizar preço de maior valor
E3: COLUNA 1 | F3: COLUNA 2 | G3: COLUNA 3 | H3: COLUNA 4
E4: LACA LISA BRAZIL ( COM OU SEM VIDRO PINTADO) | F4: - CARVALHO CLARO - CARVALHO NATURAL - CARVALHO LAVADO - CARV. EBANIZADO - IMBUIA CLARA * ACRESCENTAR 12% SE COM VIDRO PINTADO | G4: - NOGUEIRA - NOGUEIRA NATURAL - LOURO FREIJÓ - LOURO FREIJÓ NATURAL - CANELA - LACA METALIZADA BRAZIL - CARV. ÔNIX METALIZADO - CARV. N109 METALIZADO - CARV. ALBANIZADO - CARV. H155 FOSCO - CONCRETO (SOMENTE SEM VIDRO) | H4: - PAU FERRO
E5: FUNDO DO BUFFET NO MESMO ACABAMENTO DO MOVEL ACRESCENTAR +5% E INFORMAR NO PEDIDO
E6: OBS. O ACABAMENTO DO METAL NÃO INFLUENCIARÁ NO VALOR DO BUFFET
A7: AURORA | B7: 8990-3 | C7: Buffet Aurora Marchetado (4 portas;1 gav. Int.; 1 prat.), tpo bandeja (se laca somente c/ VD), pés metal | D7: 1,84 x 0,48 x 0,76 | E7: =IFERROR((VLOOKUP(B7,'Origem '!$A$1:$H$1002,4,0)*'Mark Up '!$C$2),"X") -> 22905.96 | F7: =IFERROR((VLOOKUP(B7,'Origem '!$A$1:$H$1002,5,0)*'Mark Up '!$C$2),"X") -> 27724.62 | G7: =IFERROR((VLOOKUP(B7,'Origem '!$A$1:$H$1002,6,0)*'Mark Up '!$C$2),"X") -> 31961.16 | H7: =IFERROR((VLOOKUP(B7,'Origem '!$A$1:$H$1002,7,0)*'Mark Up '!$C$2),"X") -> 34215.72
B8: 8990-4 | C8: Buffet Aurora Marchetado (4 portas;1 gav. Int.; 1 prat.), tpo bandeja (se laca somente c/ VD), pés metal | D8: 2,04 x 0,48 x 0,76 | E8: =IFERROR((VLOOKUP(B8,'Origem '!$A$1:$H$1002,4,0)*'Mark Up '!$C$2),"X") -> 23728.32 | F8: =IFERROR((VLOOKUP(B8,'Origem '!$A$1:$H$1002,5,0)*'Mark Up '!$C$2),"X") -> 29295.42 | G8: =IFERROR((VLOOKUP(B8,'Origem '!$A$1:$H$1002,6,0)*'Mark Up '!$C$2),"X") -> 33397.98 | H8: =IFERROR((VLOOKUP(B8,'Origem '!$A$1:$H$1002,7,0)*'Mark Up '!$C$2),"X") -> 36308.58
B9: 8990-5 | C9: Buffet Aurora Marchetado (5 portas;1 gav. Int.; 2 prat.), tpo bandeja (se laca somente c/ VD), pés metal | D9: 2,29 x 0,48 x 0,76 | E9: =IFERROR((VLOOKUP(B9,'Origem '!$A$1:$H$1002,4,0)*'Mark Up '!$C$2),"X") -> 25446.96 | F9: =IFERROR((VLOOKUP(B9,'Origem '!$A$1:$H$1002,5,0)*'Mark Up '!$C$2),"X") -> 31605.42 | G9: =IFERROR((VLOOKUP(B9,'Origem '!$A$1:$H$1002,6,0)*'Mark Up '!$C$2),"X") -> 35915.88 | H9: =IFERROR((VLOOKUP(B9,'Origem '!$A$1:$H$1002,7,0)*'Mark Up '!$C$2),"X") -> 39145.26
B10: 8990-7 | C10: Buffet Aurora Marchetado (5 portas;1 gav. Int.; 2 prat.), tpo bandeja (se laca somente c/ VD), pés metal | D10: 2,54 x 0,48 x 0,76 | E10: =IFERROR((VLOOKUP(B10,'Origem '!$A$1:$H$1002,4,0)*'Mark Up '!$C$2),"X") -> 27281.1 | F10: =IFERROR((VLOOKUP(B10,'Origem '!$A$1:$H$1002,5,0)*'Mark Up '!$C$2),"X") -> 34252.68 | G10: =IFERROR((VLOOKUP(B10,'Origem '!$A$1:$H$1002,6,0)*'Mark Up '!$C$2),"X") -> 38683.26 | H10: =IFERROR((VLOOKUP(B10,'Origem '!$A$1:$H$1002,7,0)*'Mark Up '!$C$2),"X") -> 42282.24
A11: AURORA | B11: 11800-10 | C11: Buffet Aurora B Marchetado""INTERNO PRETO OU CINZA"" (4 portas;1 gav. Int.; 1 prat.), tpo bandeja (se laca brilho somente c/ VD), pés metal | D11: 1,86 x 0,48 x 0,75 | E11: =IFERROR((VLOOKUP(B11,'Origem '!$A$1:$H$1002,4,0)*'Mark Up '!$C$2),"X") -> X | F11: =IFERROR((VLOOKUP(B11,'Origem '!$A$1:$H$1002,5,0)*'Mark Up '!$C$2),"X") -> 24208.8 | G11: =IFERROR((VLOOKUP(B11,'Origem '!$A$1:$H$1002,6,0)*'Mark Up '!$C$2),"X") -> 27179.46 | H11: =IFERROR((VLOOKUP(B11,'Origem '!$A$1:$H$1002,7,0)*'Mark Up '!$C$2),"X") -> 31780.98
B12: 11800-12 | C12: Buffet Aurora B Marchetado""INTERNO PRETO OU CINZA"" (4 portas;1 gav. Int.; 1 prat.), tpo bandeja (se laca brilho somente c/ VD), pés metal | D12: 2,06 x 0,48 x 0,75 | E12: =IFERROR((VLOOKUP(B12,'Origem '!$A$1:$H$1002,4,0)*'Mark Up '!$C$2),"X") -> X | F12: =IFERROR((VLOOKUP(B12,'Origem '!$A$1:$H$1002,5,0)*'Mark Up '!$C$2),"X") -> 25664.1 | G12: =IFERROR((VLOOKUP(B12,'Origem '!$A$1:$H$1002,6,0)*'Mark Up '!$C$2),"X") -> 28417.62 | H12: =IFERROR((VLOOKUP(B12,'Origem '!$A$1:$H$1002,7,0)*'Mark Up '!$C$2),"X") -> 33176.22
B13: 11800-14 | C13: Buffet Aurora B Marchetado""INTERNO PRETO OU CINZA"" (5 portas;1 gav. Int.; 1 prat.), tpo bandeja (se laca brilho somente c/ VD), pés metal | D13: 2,31 x 0,48 x 0,75 | E13: =IFERROR((VLOOKUP(B13,'Origem '!$A$1:$H$1002,4,0)*'Mark Up '!$C$2),"X") -> X | F13: =IFERROR((VLOOKUP(B13,'Origem '!$A$1:$H$1002,5,0)*'Mark Up '!$C$2),"X") -> 27720 | G13: =IFERROR((VLOOKUP(B13,'Origem '!$A$1:$H$1002,6,0)*'Mark Up '!$C$2),"X") -> 31092.6 | H13: =IFERROR((VLOOKUP(B13,'Origem '!$A$1:$H$1002,7,0)*'Mark Up '!$C$2),"X") -> 36419.46
B14: 11800-18 | C14: Buffet Aurora B Marchetado""INTERNO PRETO OU CINZA"" (5 portas;1 gav. Int.; 1 prat.), tpo bandeja (se laca brilho somente c/ VD), pés metal | D14: 2,56 x 0,48 x 0,75 | E14: =IFERROR((VLOOKUP(B14,'Origem '!$A$1:$H$1002,4,0)*'Mark Up '!$C$2),"X") -> X | F14: =IFERROR((VLOOKUP(B14,'Origem '!$A$1:$H$1002,5,0)*'Mark Up '!$C$2),"X") -> 29586.48 | G14: =IFERROR((VLOOKUP(B14,'Origem '!$A$1:$H$1002,6,0)*'Mark Up '!$C$2),"X") -> 33287.1 | H14: =IFERROR((VLOOKUP(B14,'Origem '!$A$1:$H$1002,7,0)*'Mark Up '!$C$2),"X") -> 38285.94
A15: BADEN | B15: 10670-10 | C15: Buffet Baden (4 P, 1 Prat Pq, 1 Gav.),pés de metal (se laca brilho somente c/ VD) | D15: 1,80 x 0,48 x 0,76 | E15: =IFERROR((VLOOKUP(B15,'Origem '!$A$1:$H$1002,4,0)*'Mark Up '!$C$2),"X") -> 20157.06 | F15: =IFERROR((VLOOKUP(B15,'Origem '!$A$1:$H$1002,5,0)*'Mark Up '!$C$2),"X") -> 24726.24 | G15: =IFERROR((VLOOKUP(B15,'Origem '!$A$1:$H$1002,6,0)*'Mark Up '!$C$2),"X") -> 28528.5 | H15: =IFERROR((VLOOKUP(B15,'Origem '!$A$1:$H$1002,7,0)*'Mark Up '!$C$2),"X") -> 31679.34
B16: 10670-12 | C16: Buffet Baden (4 P, 1 Prat Pq, 1 Gav.),pés de metal (se laca brilho somente c/ VD) | D16: 2,00 x 0,48 x 0,76 | E16: =IFERROR((VLOOKUP(B16,'Origem '!$A$1:$H$1002,4,0)*'Mark Up '!$C$2),"X") -> 20739.18 | F16: =IFERROR((VLOOKUP(B16,'Origem '!$A$1:$H$1002,5,0)*'Mark Up '!$C$2),"X") -> 26578.86 | G16: =IFERROR((VLOOKUP(B16,'Origem '!$A$1:$H$1002,6,0)*'Mark Up '!$C$2),"X") -> 30039.24 | H16: =IFERROR((VLOOKUP(B16,'Origem '!$A$1:$H$1002,7,0)*'Mark Up '!$C$2),"X") -> 33213.18
B17: 10670-14 | C17: Buffet Baden (5 P, 1 Prat Pq,1 Prat Gr, 1 Gav.),pés de metal (se laca brilho somente c/ VD) | D17: 2,25 x 0,48 x 0,76 | E17: =IFERROR((VLOOKUP(B17,'Origem '!$A$1:$H$1002,4,0)*'Mark Up '!$C$2),"X") -> 22092.84 | F17: =IFERROR((VLOOKUP(B17,'Origem '!$A$1:$H$1002,5,0)*'Mark Up '!$C$2),"X") -> 28121.94 | G17: =IFERROR((VLOOKUP(B17,'Origem '!$A$1:$H$1002,6,0)*'Mark Up '!$C$2),"X") -> 31993.5 | H17: =IFERROR((VLOOKUP(B17,'Origem '!$A$1:$H$1002,7,0)*'Mark Up '!$C$2),"X") -> 35504.7
B18: 10670-18 | C18: Buffet Baden (5 P, 1 Prat Pq,1 Prat Gr, 1 Gav.),pés de metal (se laca brilho somente c/ VD) | D18: 2,50 x 0,48 x 0,76 | E18: =IFERROR((VLOOKUP(B18,'Origem '!$A$1:$H$1002,4,0)*'Mark Up '!$C$2),"X") -> 23566.62 | F18: =IFERROR((VLOOKUP(B18,'Origem '!$A$1:$H$1002,5,0)*'Mark Up '!$C$2),"X") -> 28861.14 | G18: =IFERROR((VLOOKUP(B18,'Origem '!$A$1:$H$1002,6,0)*'Mark Up '!$C$2),"X") -> 32912.88 | H18: =IFERROR((VLOOKUP(B18,'Origem '!$A$1:$H$1002,7,0)*'Mark Up '!$C$2),"X") -> 37278.78
A19: CASABLANCA | B19: 8417-0 | C19: Buffet Casablanca (1 gav.int.;1 prat; 4 portas),pés mad. | D19: 1,80 x 0,47 x 0,80 | E19: =IFERROR((VLOOKUP(B19,'Origem '!$A$1:$H$1002,4,0)*'Mark Up '!$C$2),"X") -> 19625.76 | F19: =IFERROR((VLOOKUP(B19,'Origem '!$A$1:$H$1002,5,0)*'Mark Up '!$C$2),"X") -> 23603.58 | G19: =IFERROR((VLOOKUP(B19,'Origem '!$A$1:$H$1002,6,0)*'Mark Up '!$C$2),"X") -> 26588.1 | H19: =IFERROR((VLOOKUP(B19,'Origem '!$A$1:$H$1002,7,0)*'Mark Up '!$C$2),"X") -> 27313.44
B20: 8417-1 | C20: Buffet Casablanca (1 gav.int.;1 prat; 4 portas),pés mad. | D20: 2,00 x 0,47 x 0,80 | E20: =IFERROR((VLOOKUP(B20,'Origem '!$A$1:$H$1002,4,0)*'Mark Up '!$C$2),"X") -> 20595.96 | F20: =IFERROR((VLOOKUP(B20,'Origem '!$A$1:$H$1002,5,0)*'Mark Up '!$C$2),"X") -> 25922.82 | G20: =IFERROR((VLOOKUP(B20,'Origem '!$A$1:$H$1002,6,0)*'Mark Up '!$C$2),"X") -> 28671.72 | H20: =IFERROR((VLOOKUP(B20,'Origem '!$A$1:$H$1002,7,0)*'Mark Up '!$C$2),"X") -> 29549.52
A21: CHAPLIN | B21: 11820-10 | C21: Buffet Chaplin B ""INTERNO PRETO OU CINZA"" (4 portas;1 gav. Int.; 1 prat.), tpo bandeja (se laca brilho somente c/ VD), pés metal | D21: 1,86 x 0,48 x 0,75 | E21: =IFERROR((VLOOKUP(B21,'Origem '!$A$1:$H$1002,4,0)*'Mark Up '!$C$2),"X") -> X | F21: =IFERROR((VLOOKUP(B21,'Origem '!$A$1:$H$1002,5,0)*'Mark Up '!$C$2),"X") -> 23811.48 | G21: =IFERROR((VLOOKUP(B21,'Origem '!$A$1:$H$1002,6,0)*'Mark Up '!$C$2),"X") -> 26740.56 | H21: =IFERROR((VLOOKUP(B21,'Origem '!$A$1:$H$1002,7,0)*'Mark Up '!$C$2),"X") -> 31272.78
B22: 11820-12 | C22: Buffet Chaplin B ""INTERNO PRETO OU CINZA"" (4 portas;1 gav. Int.; 1 prat.), tpo bandeja (se laca brilho somente c/ VD), pés metal | D22: 2,06 x 0,48 x 0,75 | E22: =IFERROR((VLOOKUP(B22,'Origem '!$A$1:$H$1002,4,0)*'Mark Up '!$C$2),"X") -> X | F22: =IFERROR((VLOOKUP(B22,'Origem '!$A$1:$H$1002,5,0)*'Mark Up '!$C$2),"X") -> 25188.24 | G22: =IFERROR((VLOOKUP(B22,'Origem '!$A$1:$H$1002,6,0)*'Mark Up '!$C$2),"X") -> 27890.94 | H22: =IFERROR((VLOOKUP(B22,'Origem '!$A$1:$H$1002,7,0)*'Mark Up '!$C$2),"X") -> 32580.24
B23: 11820-14 | C23: Buffet Chaplin B ""INTERNO PRETO OU CINZA"" (5 portas;1 gav. Int.; 1 prat.), tpo bandeja (se laca brilho somente c/ VD), pés metal | D23: 2,31 x 0,48 x 0,75 | E23: =IFERROR((VLOOKUP(B23,'Origem '!$A$1:$H$1002,4,0)*'Mark Up '!$C$2),"X") -> X | F23: =IFERROR((VLOOKUP(B23,'Origem '!$A$1:$H$1002,5,0)*'Mark Up '!$C$2),"X") -> 27234.9 | G23: =IFERROR((VLOOKUP(B23,'Origem '!$A$1:$H$1002,6,0)*'Mark Up '!$C$2),"X") -> 30533.58 | H23: =IFERROR((VLOOKUP(B23,'Origem '!$A$1:$H$1002,7,0)*'Mark Up '!$C$2),"X") -> 35777.28
B24: 11820-18 | C24: Buffet Chaplin B ""INTERNO PRETO OU CINZA"" (5 portas;1 gav. Int.; 1 prat.), tpo bandeja (se laca brilho somente c/ VD), pés metal | D24: 2,56 x 0,48 x 0,75 | E24: =IFERROR((VLOOKUP(B24,'Origem '!$A$1:$H$1002,4,0)*'Mark Up '!$C$2),"X") -> X | F24: =IFERROR((VLOOKUP(B24,'Origem '!$A$1:$H$1002,5,0)*'Mark Up '!$C$2),"X") -> 30140.88 | G24: =IFERROR((VLOOKUP(B24,'Origem '!$A$1:$H$1002,6,0)*'Mark Up '!$C$2),"X") -> 32792.76 | H24: =IFERROR((VLOOKUP(B24,'Origem '!$A$1:$H$1002,7,0)*'Mark Up '!$C$2),"X") -> 37639.14
A25: DINAMO | B25: 7980-3 | C25: Buffet Dinamo (4 portas, 2 gav.), pés metal | D25: 1,80 x 0,47 x 0,76 | E25: =IFERROR((VLOOKUP(B25,'Origem '!$A$1:$H$1002,4,0)*'Mark Up '!$C$2),"X") -> 27373.5 | F25: =IFERROR((VLOOKUP(B25,'Origem '!$A$1:$H$1002,5,0)*'Mark Up '!$C$2),"X") -> 29397.06 | G25: =IFERROR((VLOOKUP(B25,'Origem '!$A$1:$H$1002,6,0)*'Mark Up '!$C$2),"X") -> 33425.7 | H25: =IFERROR((VLOOKUP(B25,'Origem '!$A$1:$H$1002,7,0)*'Mark Up '!$C$2),"X") -> 34691.58
B26: 7980-4 | C26: Buffet Dinamo (4 portas, 2 gav.), pés metal | D26: 2,00 x 0,47 x 0,76 | E26: =IFERROR((VLOOKUP(B26,'Origem '!$A$1:$H$1002,4,0)*'Mark Up '!$C$2),"X") -> 28297.5 | F26: =IFERROR((VLOOKUP(B26,'Origem '!$A$1:$H$1002,5,0)*'Mark Up '!$C$2),"X") -> 30792.3 | G26: =IFERROR((VLOOKUP(B26,'Origem '!$A$1:$H$1002,6,0)*'Mark Up '!$C$2),"X") -> 34890.24 | H26: =IFERROR((VLOOKUP(B26,'Origem '!$A$1:$H$1002,7,0)*'Mark Up '!$C$2),"X") -> 36313.2
B27: 7980-7 | C27: Buffet Dinamo (5 portas, 3 gav.), pés metal | D27: 2,50 x 0,47 x 0,76 | E27: =IFERROR((VLOOKUP(B27,'Origem '!$A$1:$H$1002,4,0)*'Mark Up '!$C$2),"X") -> 31799.46 | F27: =IFERROR((VLOOKUP(B27,'Origem '!$A$1:$H$1002,5,0)*'Mark Up '!$C$2),"X") -> 35504.7 | G27: =IFERROR((VLOOKUP(B27,'Origem '!$A$1:$H$1002,6,0)*'Mark Up '!$C$2),"X") -> 40623.66 | H27: =IFERROR((VLOOKUP(B27,'Origem '!$A$1:$H$1002,7,0)*'Mark Up '!$C$2),"X") -> 41307.42
A28: GENOVA | B28: 10111-10 | C28: Buffet Genova ,Nicho, Pés de Metal (4 portas, 2 Prat., 1 Gav.) | D28: 1,80 x 0,47 x 0,80 | E28: =IFERROR((VLOOKUP(B28,'Origem '!$A$1:$H$1002,4,0)*'Mark Up '!$C$2),"X") -> 25299.12 | F28: =IFERROR((VLOOKUP(B28,'Origem '!$A$1:$H$1002,5,0)*'Mark Up '!$C$2),"X") -> 29701.98 | G28: =IFERROR((VLOOKUP(B28,'Origem '!$A$1:$H$1002,6,0)*'Mark Up '!$C$2),"X") -> 32963.7 | H28: =IFERROR((VLOOKUP(B28,'Origem '!$A$1:$H$1002,7,0)*'Mark Up '!$C$2),"X") -> 34294.26
B29: 10111-12 | C29: Buffet Genova ,Nicho, Pés de Metal (4 portas, 2 Prat., 1 Gav.) | D29: 2,00 x 0,47 x 0,80 | E29: =IFERROR((VLOOKUP(B29,'Origem '!$A$1:$H$1002,4,0)*'Mark Up '!$C$2),"X") -> 26130.72 | F29: =IFERROR((VLOOKUP(B29,'Origem '!$A$1:$H$1002,5,0)*'Mark Up '!$C$2),"X") -> 30917.04 | G29: =IFERROR((VLOOKUP(B29,'Origem '!$A$1:$H$1002,6,0)*'Mark Up '!$C$2),"X") -> 34220.34 | H29: =IFERROR((VLOOKUP(B29,'Origem '!$A$1:$H$1002,7,0)*'Mark Up '!$C$2),"X") -> 35245.98
B30: 10111-14 | C30: Buffet Genova ,Nicho, Pés de Metal (5 portas, 3 Prat., 1 Gav.) | D30: 2,25 x 0,47 x 0,80 | E30: =IFERROR((VLOOKUP(B30,'Origem '!$A$1:$H$1002,4,0)*'Mark Up '!$C$2),"X") -> 30200.94 | F30: =IFERROR((VLOOKUP(B30,'Origem '!$A$1:$H$1002,5,0)*'Mark Up '!$C$2),"X") -> 33388.74 | G30: =IFERROR((VLOOKUP(B30,'Origem '!$A$1:$H$1002,6,0)*'Mark Up '!$C$2),"X") -> 38669.4 | H30: =IFERROR((VLOOKUP(B30,'Origem '!$A$1:$H$1002,7,0)*'Mark Up '!$C$2),"X") -> 39376.26
B31: 10111-18 | C31: Buffet Genova ,Nicho, Pés de Metal (5 portas, 3 Prat., 1 Gav.) | D31: 2,50 x 0,47 x 0,80 | E31: =IFERROR((VLOOKUP(B31,'Origem '!$A$1:$H$1002,4,0)*'Mark Up '!$C$2),"X") -> 31831.8 | F31: =IFERROR((VLOOKUP(B31,'Origem '!$A$1:$H$1002,5,0)*'Mark Up '!$C$2),"X") -> 36544.2 | G31: =IFERROR((VLOOKUP(B31,'Origem '!$A$1:$H$1002,6,0)*'Mark Up '!$C$2),"X") -> 41071.8 | H31: =IFERROR((VLOOKUP(B31,'Origem '!$A$1:$H$1002,7,0)*'Mark Up '!$C$2),"X") -> 41381.34
B32: 11940-10 | C32: Buffet Genova B ""INTERNO PRETO OU CINZA"" , Nicho, Pés de Metal (4 portas, 2 Prat., 1 Gav.) | D32: 1,82 x 0,47 x 0,80 | E32: =IFERROR((VLOOKUP(B32,'Origem '!$A$1:$H$1002,4,0)*'Mark Up '!$C$2),"X") -> X | F32: =IFERROR((VLOOKUP(B32,'Origem '!$A$1:$H$1002,5,0)*'Mark Up '!$C$2),"X") -> 27918.66 | G32: =IFERROR((VLOOKUP(B32,'Origem '!$A$1:$H$1002,6,0)*'Mark Up '!$C$2),"X") -> 29535.66 | H32: =IFERROR((VLOOKUP(B32,'Origem '!$A$1:$H$1002,7,0)*'Mark Up '!$C$2),"X") -> 30533.58
B33: 11940-12 | C33: Buffet Genova B ""INTERNO PRETO OU CINZA"" , Nicho, Pés de Metal (4 portas, 2 Prat., 1 Gav.) | D33: 2,02 x 0,47 x 0,80 | E33: =IFERROR((VLOOKUP(B33,'Origem '!$A$1:$H$1002,4,0)*'Mark Up '!$C$2),"X") -> X | F33: =IFERROR((VLOOKUP(B33,'Origem '!$A$1:$H$1002,5,0)*'Mark Up '!$C$2),"X") -> 29498.7 | G33: =IFERROR((VLOOKUP(B33,'Origem '!$A$1:$H$1002,6,0)*'Mark Up '!$C$2),"X") -> 31272.78 | H33: =IFERROR((VLOOKUP(B33,'Origem '!$A$1:$H$1002,7,0)*'Mark Up '!$C$2),"X") -> 32400.06
B34: 11940-14 | C34: Buffet Genova B ""INTERNO PRETO OU CINZA"" , Nicho, Pés de Metal (5 portas, 3 Prat., 1 Gav.) | D34: 2,27 x 0,47 x 0,80 | E34: =IFERROR((VLOOKUP(B34,'Origem '!$A$1:$H$1002,4,0)*'Mark Up '!$C$2),"X") -> X | F34: =IFERROR((VLOOKUP(B34,'Origem '!$A$1:$H$1002,5,0)*'Mark Up '!$C$2),"X") -> 31965.78 | G34: =IFERROR((VLOOKUP(B34,'Origem '!$A$1:$H$1002,6,0)*'Mark Up '!$C$2),"X") -> 33832.26 | H34: =IFERROR((VLOOKUP(B34,'Origem '!$A$1:$H$1002,7,0)*'Mark Up '!$C$2),"X") -> 35014.98
B35: 11940-18 | C35: Buffet Genova B ""INTERNO PRETO OU CINZA"" , Nicho, Pés de Metal (5 portas, 3 Prat., 1 Gav.) | D35: 2,52 x 0,47 x 0,80 | E35: =IFERROR((VLOOKUP(B35,'Origem '!$A$1:$H$1002,4,0)*'Mark Up '!$C$2),"X") -> X | F35: =IFERROR((VLOOKUP(B35,'Origem '!$A$1:$H$1002,5,0)*'Mark Up '!$C$2),"X") -> 33254.76 | G35: =IFERROR((VLOOKUP(B35,'Origem '!$A$1:$H$1002,6,0)*'Mark Up '!$C$2),"X") -> 34710.06 | H35: =IFERROR((VLOOKUP(B35,'Origem '!$A$1:$H$1002,7,0)*'Mark Up '!$C$2),"X") -> 36447.18
A36: KYOTO | B36: 10141-10 | C36: Buffet Kyoto Porta Marchetada(4 portas) Pux Cava Tp Arredondado Pés de Metal (Somente SEM VD) | D36: 1,88 x 0,45 x 0,76 | E36: =IFERROR((VLOOKUP(B36,'Origem '!$A$1:$H$1002,4,0)*'Mark Up '!$C$2),"X") -> 24980.34 | F36: =IFERROR((VLOOKUP(B36,'Origem '!$A$1:$H$1002,5,0)*'Mark Up '!$C$2),"X") -> 29868.3 | G36: =IFERROR((VLOOKUP(B36,'Origem '!$A$1:$H$1002,6,0)*'Mark Up '!$C$2),"X") -> 33411.84 | H36: =IFERROR((VLOOKUP(B36,'Origem '!$A$1:$H$1002,7,0)*'Mark Up '!$C$2),"X") -> 35135.1
B37: 10141-12 | C37: Buffet Kyoto Porta Marchetada(4 portas) Pux Cava Tp Arredondado Pés de Metal (Somente SEM VD) | D37: 2,08 x 0,45 x 0,76 | E37: =IFERROR((VLOOKUP(B37,'Origem '!$A$1:$H$1002,4,0)*'Mark Up '!$C$2),"X") -> 26236.98 | F37: =IFERROR((VLOOKUP(B37,'Origem '!$A$1:$H$1002,5,0)*'Mark Up '!$C$2),"X") -> 32136.72 | G37: =IFERROR((VLOOKUP(B37,'Origem '!$A$1:$H$1002,6,0)*'Mark Up '!$C$2),"X") -> 35264.46 | H37: =IFERROR((VLOOKUP(B37,'Origem '!$A$1:$H$1002,7,0)*'Mark Up '!$C$2),"X") -> 38868.06
B38: 10141-15 | C38: Buffet Kyoto Porta Marchetada(5 portas) Pux Cava Tp Arredondado Pés de Metal (Somente SEM VD) | D38: 2,32 x 0,45 x 0,76 | E38: =IFERROR((VLOOKUP(B38,'Origem '!$A$1:$H$1002,4,0)*'Mark Up '!$C$2),"X") -> 27701.52 | F38: =IFERROR((VLOOKUP(B38,'Origem '!$A$1:$H$1002,5,0)*'Mark Up '!$C$2),"X") -> 33758.34 | G38: =IFERROR((VLOOKUP(B38,'Origem '!$A$1:$H$1002,6,0)*'Mark Up '!$C$2),"X") -> 37537.5 | H38: =IFERROR((VLOOKUP(B38,'Origem '!$A$1:$H$1002,7,0)*'Mark Up '!$C$2),"X") -> 39676.56
B39: 10141-18 | C39: Buffet Kyoto Porta Marchetada(5 portas) Pux Cava Tp Arredondado Pés de Metal (Somente SEM VD) | D39: 2,58 x 0,45 x 0,76 | E39: =IFERROR((VLOOKUP(B39,'Origem '!$A$1:$H$1002,4,0)*'Mark Up '!$C$2),"X") -> 30030 | F39: =IFERROR((VLOOKUP(B39,'Origem '!$A$1:$H$1002,5,0)*'Mark Up '!$C$2),"X") -> 35684.88 | G39: =IFERROR((VLOOKUP(B39,'Origem '!$A$1:$H$1002,6,0)*'Mark Up '!$C$2),"X") -> 39399.36 | H39: =IFERROR((VLOOKUP(B39,'Origem '!$A$1:$H$1002,7,0)*'Mark Up '!$C$2),"X") -> 42374.64
B40: 12010-10 | C40: Buffet Kyoto "B" Porta Marchetada "INTERNO PRETO OU CINZA" (4 portas) Pux Cava Tp Arredondado Pés Metal (Somente SEM VD) | D40: 1,88 x 0,45 x 0,76 | E40: =IFERROR((VLOOKUP(B40,'Origem '!$A$1:$H$1002,4,0)*'Mark Up '!$C$2),"X") -> X | F40: =IFERROR((VLOOKUP(B40,'Origem '!$A$1:$H$1002,5,0)*'Mark Up '!$C$2),"X") -> 28302.12 | G40: =IFERROR((VLOOKUP(B40,'Origem '!$A$1:$H$1002,6,0)*'Mark Up '!$C$2),"X") -> 29258.46 | H40: =IFERROR((VLOOKUP(B40,'Origem '!$A$1:$H$1002,7,0)*'Mark Up '!$C$2),"X") -> 32418.54
...

Sheet Carrinhos de Chá 
C1: CARRINHOS DE CHÁ | I1: AMBIENTADAS
A2: COLEÇÃO | B2: REF | C2: DESCRIÇÃO | D2: COMP X PROF X ALT | E2: Em caso de cores diferentes Base ou Tampo, utilizar preço de maior valor
E3: COLUNA 1 | F3: COLUNA 2 | G3: COLUNA 3 | H3: COLUNA 4
E4: LACA LISA BRAZIL ( COM OU SEM VIDRO PINTADO) | F4: - CARVALHO CLARO - CARVALHO NATURAL - CARVALHO LAVADO - CARV. EBANIZADO - IMBUIA CLARA * ACRESCENTAR 12% SE COM VIDRO PINTADO | G4: - NOGUEIRA - NOGUEIRA NATURAL - LOURO FREIJÓ - LOURO FREIJÓ NATURAL - CANELA - LACA METALIZADA BRAZIL - CARV. ÔNIX METALIZADO - CARV. N109 METALIZADO - CARV. ALBANIZADO - CARV. H155 FOSCO - CONCRETO (SOMENTE SEM VIDRO) | H4: - PAU FERRO
E5: OBS. O ACABAMENTO DO METAL NÃO INFLUENCIARÁ NO VALOR DO CARRINHO DE CHÁ
A6: GOLD | B6: 4829-0 | C6: Carrinho de Chá Gold (se laca brilho somente c/ VD) | D6: 1,16 x 0,46 x 0,80 | E6: =IFERROR((VLOOKUP(B6,'Origem '!$A$1:$H$1002,4,0)*'Mark Up '!$C$2),"X") -> 11965.8 | F6: =IFERROR((VLOOKUP(B6,'Origem '!$A$1:$H$1002,5,0)*'Mark Up '!$C$2),"X") -> 13134.66 | G6: =IFERROR((VLOOKUP(B6,'Origem '!$A$1:$H$1002,6,0)*'Mark Up '!$C$2),"X") -> 14603.82 | H6: =IFERROR((VLOOKUP(B6,'Origem '!$A$1:$H$1002,7,0)*'Mark Up '!$C$2),"X") -> 15698.76
A7: MACAU | B7: 10249-4 | C7: Carrinho de Chá Macau (se laca brilho, somente c/ VD) | D7: 0,82 x 0,36 x 0,82 | E7: =IFERROR((VLOOKUP(B7,'Origem '!$A$1:$H$1002,4,0)*'Mark Up '!$C$2),"X") -> 8417.64 | F7: =IFERROR((VLOOKUP(B7,'Origem '!$A$1:$H$1002,5,0)*'Mark Up '!$C$2),"X") -> 9475.62 | G7: =IFERROR((VLOOKUP(B7,'Origem '!$A$1:$H$1002,6,0)*'Mark Up '!$C$2),"X") -> 10676.82 | H7: =IFERROR((VLOOKUP(B7,'Origem '!$A$1:$H$1002,7,0)*'Mark Up '!$C$2),"X") -> 11471.46
A8: QUIOS | B8: 11760-4 | C8: Carrinho de Chá QUIOS (se laca brilho, somente c/ VD) | D8: 0,80 x 0,36 x 0,82 | E8: =IFERROR((VLOOKUP(B8,'Origem '!$A$1:$H$1002,4,0)*'Mark Up '!$C$2),"X") -> 7710.78 | F8: =IFERROR((VLOOKUP(B8,'Origem '!$A$1:$H$1002,5,0)*'Mark Up '!$C$2),"X") -> 8542.38 | G8: =IFERROR((VLOOKUP(B8,'Origem '!$A$1:$H$1002,6,0)*'Mark Up '!$C$2),"X") -> 9009 | H8: =IFERROR((VLOOKUP(B8,'Origem '!$A$1:$H$1002,7,0)*'Mark Up '!$C$2),"X") -> 9521.82
A9: VANCOUVER | B9: 10019-18 | C9: Carrinho de Chá Vancouver (se laca brilho somente c/ VD) - (Vidro somente no tampo superior) | D9: 2,12 x 0,56 x 0,80 | E9: =IFERROR((VLOOKUP(B9,'Origem '!$A$1:$H$1002,4,0)*'Mark Up '!$C$2),"X") -> 20535.9 | F9: =IFERROR((VLOOKUP(B9,'Origem '!$A$1:$H$1002,5,0)*'Mark Up '!$C$2),"X") -> 22148.28 | G9: =IFERROR((VLOOKUP(B9,'Origem '!$A$1:$H$1002,6,0)*'Mark Up '!$C$2),"X") -> 25234.44 | H9: =IFERROR((VLOOKUP(B9,'Origem '!$A$1:$H$1002,7,0)*'Mark Up '!$C$2),"X") -> 26860.68

Sheet Gaveteiros
C1: GAVETEIROS | I1: AMBIENTADAS
A2: COLEÇÃO | B2: REF | C2: DESCRIÇÃO | D2: COMP X PROF X ALT | E2: Em caso de cores diferentes, utilizar preço de maior valor
E3: COLUNA 1 | F3: COLUNA 2 | G3: COLUNA 3 | H3: COLUNA 4
E4: LACA LISA BRAZIL ( COM OU SEM VIDRO PINTADO) | F4: - CARVALHO CLARO - CARVALHO NATURAL - CARVALHO LAVADO - CARV. EBANIZADO - IMBUIA CLARA * ACRESCENTAR 12% SE COM VIDRO PINTADO | G4: - NOGUEIRA - NOGUEIRA NATURAL - LOURO FREIJÓ - LOURO FREIJÓ NATURAL - CANELA - LACA METALIZADA BRAZIL - CARV. ÔNIX METALIZADO - CARV. N109 METALIZADO - CARV. ALBANIZADO - CARV. H155 FOSCO - CONCRETO (SOMENTE SEM VIDRO) | H4: - PAU FERRO
E5: OBS. O ACABAMENTO DO METAL NÃO INFLUENCIARÁ NO VALOR DOS GAVETEIROS
A6: CAIRO | B6: 11880-0 | C6: Gaveteiro Cairo (2 gav.;c/ corrediça toque), pés metal | D6: 0,50 x 0,45 x 0,60 | E6: =IFERROR((VLOOKUP(B6,'Origem '!$A$1:$H$1002,4,0)*'Mark Up '!$C$2),"X") -> 8741.04 | F6: =IFERROR((VLOOKUP(B6,'Origem '!$A$1:$H$1002,5,0)*'Mark Up '!$C$2),"X") -> 11032.56 | G6: =IFERROR((VLOOKUP(B6,'Origem '!$A$1:$H$1002,6,0)*'Mark Up '!$C$2),"X") -> 11947.32 | H6: =IFERROR((VLOOKUP(B6,'Origem '!$A$1:$H$1002,7,0)*'Mark Up '!$C$2),"X") -> 12806.64
B7: 11880-2 | C7: Gaveteiro Cairo (2 gav.;c/ corrediça toque), pés metal | D7: 0,70 x 0,45 x 0,60 | E7: =IFERROR((VLOOKUP(B7,'Origem '!$A$1:$H$1002,4,0)*'Mark Up '!$C$2),"X") -> 10478.16 | F7: =IFERROR((VLOOKUP(B7,'Origem '!$A$1:$H$1002,5,0)*'Mark Up '!$C$2),"X") -> 12340.02 | G7: =IFERROR((VLOOKUP(B7,'Origem '!$A$1:$H$1002,6,0)*'Mark Up '!$C$2),"X") -> 13513.5 | H7: =IFERROR((VLOOKUP(B7,'Origem '!$A$1:$H$1002,7,0)*'Mark Up '!$C$2),"X") -> 14571.48
A8: ERNESTO | B8: 11122-0 | C8: Gaveteiro Ernesto Pés Metal | D8: 0,54 X 0,46 X 0,58 | E8: =IFERROR((VLOOKUP(B8,'Origem '!$A$1:$H$1002,4,0)*'Mark Up '!$C$2),"X") -> 10954.02 | F8: =IFERROR((VLOOKUP(B8,'Origem '!$A$1:$H$1002,5,0)*'Mark Up '!$C$2),"X") -> 12885.18 | G8: =IFERROR((VLOOKUP(B8,'Origem '!$A$1:$H$1002,6,0)*'Mark Up '!$C$2),"X") -> 13573.56 | H8: =IFERROR((VLOOKUP(B8,'Origem '!$A$1:$H$1002,7,0)*'Mark Up '!$C$2),"X") -> 13998.6
B9: 11122-2 | C9: Gaveteiro Ernesto Pés Metal | D9: 0,74 X 0,46 X 0,58 | E9: =IFERROR((VLOOKUP(B9,'Origem '!$A$1:$H$1002,4,0)*'Mark Up '!$C$2),"X") -> 11891.88 | F9: =IFERROR((VLOOKUP(B9,'Origem '!$A$1:$H$1002,5,0)*'Mark Up '!$C$2),"X") -> 14114.1 | G9: =IFERROR((VLOOKUP(B9,'Origem '!$A$1:$H$1002,6,0)*'Mark Up '!$C$2),"X") -> 15472.38 | H9: =IFERROR((VLOOKUP(B9,'Origem '!$A$1:$H$1002,7,0)*'Mark Up '!$C$2),"X") -> 16036.02
A10: HADAR | B10: 3322-0 | C10: Gaveteiro Hadar Pés Metal | D10: 54,0 x 46,5 x 60 | E10: =IFERROR((VLOOKUP(B10,'Origem '!$A$1:$H$1002,4,0)*'Mark Up '!$C$2),"X") -> 9133.74 | F10: =IFERROR((VLOOKUP(B10,'Origem '!$A$1:$H$1002,5,0)*'Mark Up '!$C$2),"X") -> 11947.32 | G10: =IFERROR((VLOOKUP(B10,'Origem '!$A$1:$H$1002,6,0)*'Mark Up '!$C$2),"X") -> 12728.1 | H10: =IFERROR((VLOOKUP(B10,'Origem '!$A$1:$H$1002,7,0)*'Mark Up '!$C$2),"X") -> 13037.64
B11: 3322-2 | C11: Gaveteiro Hadar Pés Metal | D11: 74,0 x 46,5 x 60 | E11: =IFERROR((VLOOKUP(B11,'Origem '!$A$1:$H$1002,4,0)*'Mark Up '!$C$2),"X") -> 9692.76 | F11: =IFERROR((VLOOKUP(B11,'Origem '!$A$1:$H$1002,5,0)*'Mark Up '!$C$2),"X") -> 13088.46 | G11: =IFERROR((VLOOKUP(B11,'Origem '!$A$1:$H$1002,6,0)*'Mark Up '!$C$2),"X") -> 13675.2 | H11: =IFERROR((VLOOKUP(B11,'Origem '!$A$1:$H$1002,7,0)*'Mark Up '!$C$2),"X") -> 14049.42
A12: LASI | B12: 3222-5 | C12: Gaveteiro Lasi | D12: 0,41 Ø X 0,65 | E12: =IFERROR((VLOOKUP(B12,'Origem '!$A$1:$H$1002,4,0)*'Mark Up '!$C$2),"X") -> 8237.46 | F12: =IFERROR((VLOOKUP(B12,'Origem '!$A$1:$H$1002,5,0)*'Mark Up '!$C$2),"X") -> 10478.16 | G12: =IFERROR((VLOOKUP(B12,'Origem '!$A$1:$H$1002,6,0)*'Mark Up '!$C$2),"X") -> 10940.16 | H12: =IFERROR((VLOOKUP(B12,'Origem '!$A$1:$H$1002,7,0)*'Mark Up '!$C$2),"X") -> 11392.92
A13: LOS ANGELES | B13: 11042-0 | C13: Gaveteiro Los Angeles (2 gav.;c/ pux.cava), pés metal | D13: 0,50 x 0,45 x 0,60 | E13: =IFERROR((VLOOKUP(B13,'Origem '!$A$1:$H$1002,4,0)*'Mark Up '!$C$2),"X") -> 7368.9 | F13: =IFERROR((VLOOKUP(B13,'Origem '!$A$1:$H$1002,5,0)*'Mark Up '!$C$2),"X") -> 9410.94 | G13: =IFERROR((VLOOKUP(B13,'Origem '!$A$1:$H$1002,6,0)*'Mark Up '!$C$2),"X") -> 10316.46 | H13: =IFERROR((VLOOKUP(B13,'Origem '!$A$1:$H$1002,7,0)*'Mark Up '!$C$2),"X") -> 10741.5
B14: 11042-2 | C14: Gaveteiro Los Angeles (2 gav.;c/ pux.cava), pés metal | D14: 0,70 x 0,45 x 0,60 | E14: =IFERROR((VLOOKUP(B14,'Origem '!$A$1:$H$1002,4,0)*'Mark Up '!$C$2),"X") -> 8320.62 | F14: =IFERROR((VLOOKUP(B14,'Origem '!$A$1:$H$1002,5,0)*'Mark Up '!$C$2),"X") -> 10843.14 | G14: =IFERROR((VLOOKUP(B14,'Origem '!$A$1:$H$1002,6,0)*'Mark Up '!$C$2),"X") -> 11887.26 | H14: =IFERROR((VLOOKUP(B14,'Origem '!$A$1:$H$1002,7,0)*'Mark Up '!$C$2),"X") -> 12455.52
A15: MILETO | B15: 11860-0 | C15: Gaveteiro Mileto C/ MARCHETARIA (2 gav.;c/ pux.cava), pés metal | D15: 0,50 x 0,47 x 0,60 | E15: =IFERROR((VLOOKUP(B15,'Origem '!$A$1:$H$1002,4,0)*'Mark Up '!$C$2),"X") -> 8376.06 | F15: =IFERROR((VLOOKUP(B15,'Origem '!$A$1:$H$1002,5,0)*'Mark Up '!$C$2),"X") -> 10136.28 | G15: =IFERROR((VLOOKUP(B15,'Origem '!$A$1:$H$1002,6,0)*'Mark Up '!$C$2),"X") -> 10990.98 | H15: =IFERROR((VLOOKUP(B15,'Origem '!$A$1:$H$1002,7,0)*'Mark Up '!$C$2),"X") -> 11245.08
B16: 11860-2 | C16: Gaveteiro Mileto C/ MARCHETARIA (2 gav.;c/ pux.cava), pés metal | D16: 0,70 x 0,47 x 0,60 | E16: =IFERROR((VLOOKUP(B16,'Origem '!$A$1:$H$1002,4,0)*'Mark Up '!$C$2),"X") -> 9628.08 | F16: =IFERROR((VLOOKUP(B16,'Origem '!$A$1:$H$1002,5,0)*'Mark Up '!$C$2),"X") -> 11771.76 | G16: =IFERROR((VLOOKUP(B16,'Origem '!$A$1:$H$1002,6,0)*'Mark Up '!$C$2),"X") -> 12825.12 | H16: =IFERROR((VLOOKUP(B16,'Origem '!$A$1:$H$1002,7,0)*'Mark Up '!$C$2),"X") -> 13171.62
A17: RHONE | B17: 11152-0 | C17: Gaveteiro Rhone (1 gav.;c/ pux.cava), pés metal (se laca brilho somente c/ VD) | D17: 0,54 x 0,47 x 0,60 | E17: =IFERROR((VLOOKUP(B17,'Origem '!$A$1:$H$1002,4,0)*'Mark Up '!$C$2),"X") -> 8186.64 | F17: =IFERROR((VLOOKUP(B17,'Origem '!$A$1:$H$1002,5,0)*'Mark Up '!$C$2),"X") -> 9789.78 | G17: =IFERROR((VLOOKUP(B17,'Origem '!$A$1:$H$1002,6,0)*'Mark Up '!$C$2),"X") -> 10866.24 | H17: =IFERROR((VLOOKUP(B17,'Origem '!$A$1:$H$1002,7,0)*'Mark Up '!$C$2),"X") -> 11563.86
B18: 11152-2 | C18: Gaveteiro Rhone (1 gav.;c/ pux.cava), pés metal (se laca brilho somente c/ VD) | D18: 0,74 x 0,47 x 0,60 | E18: =IFERROR((VLOOKUP(B18,'Origem '!$A$1:$H$1002,4,0)*'Mark Up '!$C$2),"X") -> 8888.88 | F18: =IFERROR((VLOOKUP(B18,'Origem '!$A$1:$H$1002,5,0)*'Mark Up '!$C$2),"X") -> 10658.34 | G18: =IFERROR((VLOOKUP(B18,'Origem '!$A$1:$H$1002,6,0)*'Mark Up '!$C$2),"X") -> 12030.48 | H18: =IFERROR((VLOOKUP(B18,'Origem '!$A$1:$H$1002,7,0)*'Mark Up '!$C$2),"X") -> 13079.22
A19: SICILIANO | B19: 7261-0 | C19: Gaveteiro Siciliano (1 gav.;c/ pux.cava), pés metal | D19: 0,50 x 0,45 x 0,60 | E19: =IFERROR((VLOOKUP(B19,'Origem '!$A$1:$H$1002,4,0)*'Mark Up '!$C$2),"X") -> 7433.58 | F19: =IFERROR((VLOOKUP(B19,'Origem '!$A$1:$H$1002,5,0)*'Mark Up '!$C$2),"X") -> 8325.24 | G19: =IFERROR((VLOOKUP(B19,'Origem '!$A$1:$H$1002,6,0)*'Mark Up '!$C$2),"X") -> 9087.54 | H19: =IFERROR((VLOOKUP(B19,'Origem '!$A$1:$H$1002,7,0)*'Mark Up '!$C$2),"X") -> 9641.94
B20: 7261-2 | C20: Gaveteiro Siciliano (1 gav.;c/ pux.cava), pés metal | D20: 0,70 x 0,45 x 0,60 | E20: =IFERROR((VLOOKUP(B20,'Origem '!$A$1:$H$1002,4,0)*'Mark Up '!$C$2),"X") -> 8061.9 | F20: =IFERROR((VLOOKUP(B20,'Origem '!$A$1:$H$1002,5,0)*'Mark Up '!$C$2),"X") -> 9184.56 | G20: =IFERROR((VLOOKUP(B20,'Origem '!$A$1:$H$1002,6,0)*'Mark Up '!$C$2),"X") -> 10034.64 | H20: =IFERROR((VLOOKUP(B20,'Origem '!$A$1:$H$1002,7,0)*'Mark Up '!$C$2),"X") -> 10723.02
A21: SICILIANO | B21: 7262-0 | C21: Gaveteiro Siciliano (2 gav.;c/ pux.cava), pés metal | D21: 0,50 x 0,45 x 0,59 | E21: =IFERROR((VLOOKUP(B21,'Origem '!$A$1:$H$1002,4,0)*'Mark Up '!$C$2),"X") -> 8339.1 | F21: =IFERROR((VLOOKUP(B21,'Origem '!$A$1:$H$1002,5,0)*'Mark Up '!$C$2),"X") -> 10450.44 | G21: =IFERROR((VLOOKUP(B21,'Origem '!$A$1:$H$1002,6,0)*'Mark Up '!$C$2),"X") -> 11933.46 | H21: =IFERROR((VLOOKUP(B21,'Origem '!$A$1:$H$1002,7,0)*'Mark Up '!$C$2),"X") -> 12446.28
B22: 7262-2 | C22: Gaveteiro Siciliano (2 gav.;c/ pux.cava), pés metal | D22: 0,70 x 0,45 x 0,59 | E22: =IFERROR((VLOOKUP(B22,'Origem '!$A$1:$H$1002,4,0)*'Mark Up '!$C$2),"X") -> 9512.58 | F22: =IFERROR((VLOOKUP(B22,'Origem '!$A$1:$H$1002,5,0)*'Mark Up '!$C$2),"X") -> 11720.94 | G22: =IFERROR((VLOOKUP(B22,'Origem '!$A$1:$H$1002,6,0)*'Mark Up '!$C$2),"X") -> 13970.88 | H22: =IFERROR((VLOOKUP(B22,'Origem '!$A$1:$H$1002,7,0)*'Mark Up '!$C$2),"X") -> 14492.94
A23: TÓQUIO | B23: 11032-0 | C23: Gaveteiro Tóquio (2 gav.;c/ puxador), pés metal | D23: 0,50 x 0,45 x 0,60 | E23: =IFERROR((VLOOKUP(B23,'Origem '!$A$1:$H$1002,4,0)*'Mark Up '!$C$2),"X") -> 7040.88 | F23: =IFERROR((VLOOKUP(B23,'Origem '!$A$1:$H$1002,5,0)*'Mark Up '!$C$2),"X") -> 8713.32 | G23: =IFERROR((VLOOKUP(B23,'Origem '!$A$1:$H$1002,6,0)*'Mark Up '!$C$2),"X") -> 9535.68 | H23: =IFERROR((VLOOKUP(B23,'Origem '!$A$1:$H$1002,7,0)*'Mark Up '!$C$2),"X") -> 9886.8
B24: 11032-2 | C24: Gaveteiro Tóquio (2 gav.;c/ puxador), pés metal | D24: 0,70 x 0,45 x 0,60 | E24: =IFERROR((VLOOKUP(B24,'Origem '!$A$1:$H$1002,4,0)*'Mark Up '!$C$2),"X") -> 7743.12 | F24: =IFERROR((VLOOKUP(B24,'Origem '!$A$1:$H$1002,5,0)*'Mark Up '!$C$2),"X") -> 10113.18 | G24: =IFERROR((VLOOKUP(B24,'Origem '!$A$1:$H$1002,6,0)*'Mark Up '!$C$2),"X") -> 11069.52 | H24: =IFERROR((VLOOKUP(B24,'Origem '!$A$1:$H$1002,7,0)*'Mark Up '!$C$2),"X") -> 11568.48
A25: TRENTO | B25: 10742-5 | C25: Gaveteiro Trento (1 gav. c/ pux.), pés mad. (se laca brilho somente c/ VD) | D25: 0,45 Ø 0,61 | E25: =IFERROR((VLOOKUP(B25,'Origem '!$A$1:$H$1002,4,0)*'Mark Up '!$C$2),"X") -> 6735.96 | F25: =IFERROR((VLOOKUP(B25,'Origem '!$A$1:$H$1002,5,0)*'Mark Up '!$C$2),"X") -> 8052.66 | G25: =IFERROR((VLOOKUP(B25,'Origem '!$A$1:$H$1002,6,0)*'Mark Up '!$C$2),"X") -> 8898.12 | H25: =IFERROR((VLOOKUP(B25,'Origem '!$A$1:$H$1002,7,0)*'Mark Up '!$C$2),"X") -> X
B26: 10742-6 | C26: Gaveteiro Trento (1 gav. c/ pux.), pés mad. (se laca brilho somente c/ VD) | D26: 0,54 Ø 0,61 | E26: =IFERROR((VLOOKUP(B26,'Origem '!$A$1:$H$1002,4,0)*'Mark Up '!$C$2),"X") -> 6860.7 | F26: =IFERROR((VLOOKUP(B26,'Origem '!$A$1:$H$1002,5,0)*'Mark Up '!$C$2),"X") -> 8195.88 | G26: =IFERROR((VLOOKUP(B26,'Origem '!$A$1:$H$1002,6,0)*'Mark Up '!$C$2),"X") -> 9152.22 | H26: =IFERROR((VLOOKUP(B26,'Origem '!$A$1:$H$1002,7,0)*'Mark Up '!$C$2),"X") -> X

Sheet Complementos
C1: COMPLEMENTOS | I1: AMBIENTADAS
A2: COLEÇÃO | B2: REF | C2: DESCRIÇÃO | D2: COMP X PROF X ALT | E2: Em caso de cores diferentes Base ou Tampo, utilizar preço de maior valor
E3: COLUNA 1 | F3: COLUNA 2 | G3: COLUNA 3 | H3: COLUNA 4
E4: LACA LISA BRAZIL ( COM OU SEM VIDRO PINTADO) | F4: - CARVALHO CLARO - CARVALHO NATURAL - CARVALHO LAVADO - CARV. EBANIZADO - IMBUIA CLARA * ACRESCENTAR 12% SE COM VIDRO PINTADO | G4: - NOGUEIRA - NOGUEIRA NATURAL - LOURO FREIJÓ - LOURO FREIJÓ NATURAL - CANELA - LACA METALIZADA BRAZIL - CARV. ÔNIX METALIZADO - CARV. N109 METALIZADO - CARV. ALBANIZADO - CARV. H155 FOSCO - CONCRETO (SOMENTE SEM VIDRO) | H4: - PAU FERRO
E5: OBS. O ACABAMENTO DO METAL NÃO INFLUENCIARÁ NO VALOR DO MÓVEL
A6: CARTAGENA | B6: 1410-0 | C6: Cristaleira Cartagena (4 prat;2 luminárias) | D6: 0,82 x 0,37 x 1,82 | E6: =IFERROR((VLOOKUP(B6,'Origem '!$A$1:$H$1002,4,0)*'Mark Up '!$C$2),"X") -> 21529.2 | F6: =IFERROR((VLOOKUP(B6,'Origem '!$A$1:$H$1002,5,0)*'Mark Up '!$C$2),"X") -> 22328.46 | G6: =IFERROR((VLOOKUP(B6,'Origem '!$A$1:$H$1002,6,0)*'Mark Up '!$C$2),"X") -> 26116.86 | H6: =IFERROR((VLOOKUP(B6,'Origem '!$A$1:$H$1002,7,0)*'Mark Up '!$C$2),"X") -> 29018.22
B7: 1410-0Sl | C7: Cristaleira Cartagena (4 prat;s/iluminação) | D7: 0,82 x 0,37 x 1,82 | E7: =IFERROR((VLOOKUP(B7,'Origem '!$A$1:$H$1002,4,0)*'Mark Up '!$C$2),"X") -> 20281.8 | F7: =IFERROR((VLOOKUP(B7,'Origem '!$A$1:$H$1002,5,0)*'Mark Up '!$C$2),"X") -> 22152.9 | G7: =IFERROR((VLOOKUP(B7,'Origem '!$A$1:$H$1002,6,0)*'Mark Up '!$C$2),"X") -> 25252.92 | H7: =IFERROR((VLOOKUP(B7,'Origem '!$A$1:$H$1002,7,0)*'Mark Up '!$C$2),"X") -> 28061.88
B8: 1410-2SI | C8: Cristaleira Cartagena (2 prat;s/iluminação) | D8: 0,82 x 0,37 x 1,29 | E8: =IFERROR((VLOOKUP(B8,'Origem '!$A$1:$H$1002,4,0)*'Mark Up '!$C$2),"X") -> 15070.44 | F8: =IFERROR((VLOOKUP(B8,'Origem '!$A$1:$H$1002,5,0)*'Mark Up '!$C$2),"X") -> 16936.92 | G8: =IFERROR((VLOOKUP(B8,'Origem '!$A$1:$H$1002,6,0)*'Mark Up '!$C$2),"X") -> 19417.86 | H8: =IFERROR((VLOOKUP(B8,'Origem '!$A$1:$H$1002,7,0)*'Mark Up '!$C$2),"X") -> 21570.78
B9: 1411-0 | C9: Cristaleira Cartagena (1 porta/4 prat;1 luminária) | D9: 0,42 x 0,37 x 1,82 | E9: =IFERROR((VLOOKUP(B9,'Origem '!$A$1:$H$1002,4,0)*'Mark Up '!$C$2),"X") -> 15712.62 | F9: =IFERROR((VLOOKUP(B9,'Origem '!$A$1:$H$1002,5,0)*'Mark Up '!$C$2),"X") -> 16253.16 | G9: =IFERROR((VLOOKUP(B9,'Origem '!$A$1:$H$1002,6,0)*'Mark Up '!$C$2),"X") -> 18581.64 | H9: =IFERROR((VLOOKUP(B9,'Origem '!$A$1:$H$1002,7,0)*'Mark Up '!$C$2),"X") -> 20642.16
B10: 1411-0Sl | C10: Cristaleira Cartagena (1 porta/4 prat;s/iluminação) | D10: 0,42 x 0,37 x 1,82 | E10: =IFERROR((VLOOKUP(B10,'Origem '!$A$1:$H$1002,4,0)*'Mark Up '!$C$2),"X") -> 14885.64 | F10: =IFERROR((VLOOKUP(B10,'Origem '!$A$1:$H$1002,5,0)*'Mark Up '!$C$2),"X") -> 15430.8 | G10: =IFERROR((VLOOKUP(B10,'Origem '!$A$1:$H$1002,6,0)*'Mark Up '!$C$2),"X") -> 17726.94 | H10: =IFERROR((VLOOKUP(B10,'Origem '!$A$1:$H$1002,7,0)*'Mark Up '!$C$2),"X") -> 19690.44
A11: CLAUS | B11: 10440-2 | C11: Bandeja Café Claus, Tp Garrafa (se laca brilho somente c/ VD) | D11: 0,51 x 0,31 x 0,05 | E11: =IFERROR((VLOOKUP(B11,'Origem '!$A$1:$H$1002,4,0)*'Mark Up '!$C$2),"X") -> 2245.32 | F11: =IFERROR((VLOOKUP(B11,'Origem '!$A$1:$H$1002,5,0)*'Mark Up '!$C$2),"X") -> 2273.04 | G11: =IFERROR((VLOOKUP(B11,'Origem '!$A$1:$H$1002,6,0)*'Mark Up '!$C$2),"X") -> 2785.86 | H11: =IFERROR((VLOOKUP(B11,'Origem '!$A$1:$H$1002,7,0)*'Mark Up '!$C$2),"X") -> 3072.3
A12: ESPARTA | B12: 9705-0 | C12: Cabideiro Esparta | D12: 0,40 X 0,40 X 1,70 | E12: =IFERROR((VLOOKUP(B12,'Origem '!$A$1:$H$1002,4,0)*'Mark Up '!$C$2),"X") -> 5026.56 | F12: =IFERROR((VLOOKUP(B12,'Origem '!$A$1:$H$1002,5,0)*'Mark Up '!$C$2),"X") -> 5169.78 | G12: =IFERROR((VLOOKUP(B12,'Origem '!$A$1:$H$1002,6,0)*'Mark Up '!$C$2),"X") -> 5465.46 | H12: =IFERROR((VLOOKUP(B12,'Origem '!$A$1:$H$1002,7,0)*'Mark Up '!$C$2),"X") -> X
