Workbook

Sheet Mark Up 
A1: MARK UP
A2: COLUNA 1 | B2: 4.62
A3: COLUNA 2 | B3: 4.62
A4: COLUNA 3 | B4: 4.62

Sheet Venda
A1: LANÇAMENTOS 2023
A2: 09 de Janeiro de 2023
C3: APARADORES - LANÇAMENTOS
A4: *Qualquer móvel com ou sem vidro comum pintado e colado no tampo permanecerá o mesmo valor;
A5: *Informar no pedido quando for com ou sem vidro;
E6: COLUNA 1 | F6: COLUNA 2 | G6: COLUNA 3
A7: COLEÇÃO | B7: REF | C7: DESCRIÇÃO | D7: COMP X PROF X ALT | E7: TODO LACA PADRÃO | F7: TODO: - AMÊNDOA - CARVALHO - IMBUIA | G7: TODO NOGUEIRA OU TODO LOURO FREIJÓ E BASE METAL EM LACA PADRÃO
F8: TAMPO: - LACA PADRÃO - AMÊNDOA - IMBUIA - CARVALHO C/ BASE: - AMÊNDOA - IMBUIA - CARVALHO - LOURO FREIJÓ - NOGUEIRA - LACA METALIZADA PADRÃO
G9: CARVALHO N 109 METALIZADO CARVALHO ÔNIX METALIZADO
G10: CONCRETO
G11: TODO METALIZADO: - BRONZE - CHUMBO - NEW GOLDEN - ÔNIX METALIZADO - N 109 METALIZADO
A13: BADEN | B13: 10984-1 | C13: Aparador Baden ,tp e bandeja canto garrafa, pés metal (se laca brilho somente c/ VD) | D13: 1,40 x 0,40 x 0,76 | E13: =Fábrica!E13*'Mark Up '!$B$2 -> 9304.68 | F13: =Fábrica!F13*'Mark Up '!$B$3 -> 9623.46 | G13: =Fábrica!G13*'Mark Up '!$B$4 -> 11129.58
B14: 10984-2 | C14: Aparador Baden ,tp e bandeja canto garrafa, pés metal (se laca brilho somente c/ VD) | D14: 1,60 x 0,40 x 0,76 | E14: =Fábrica!E14*'Mark Up '!$B$2 -> 9554.16 | F14: =Fábrica!F14*'Mark Up '!$B$3 -> 9993.06 | G14: =Fábrica!G14*'Mark Up '!$B$4 -> 11697.84
B15: 10984-3 | C15: Aparador Baden ,tp e bandeja canto garrafa, pés metal (se laca brilho somente c/ VD) | D15: 1,80 x 0,40 x 0,76 | E15: =Fábrica!E15*'Mark Up '!$B$2 -> 10339.56 | F15: =Fábrica!F15*'Mark Up '!$B$3 -> 10690.68 | G15: =Fábrica!G15*'Mark Up '!$B$4 -> 12575.64
B16: 10984-4 | C16: Aparador Baden ,tp e bandeja canto garrafa, pés metal (se laca brilho somente c/ VD) | D16: 2,00 x 0,40 x 0,76 | E16: =Fábrica!E16*'Mark Up '!$B$2 -> 10963.26 | F16: =Fábrica!F16*'Mark Up '!$B$3 -> 11480.7 | G16: =Fábrica!G16*'Mark Up '!$B$4 -> 13559.7
A17: BRUXELAS | B17: 10504-1 | C17: Aparador Bruxelas (tp oblongo), pés metal (se laca brilho somente c/ VD) | D17: 1,35 x 0,45 x 0,76 | E17: =Fábrica!E17*'Mark Up '!$B$2 -> 7826.28 | F17: =Fábrica!F17*'Mark Up '!$B$3 -> 7974.12 | G17: =Fábrica!G17*'Mark Up '!$B$4 -> 8510.04
B18: 10504-2 | C18: Aparador Bruxelas (tp oblongo), pés metal (se laca brilho somente c/ VD) | D18: 1,60 x 0,45 x 0,76 | E18: =Fábrica!E18*'Mark Up '!$B$2 -> 8168.16 | F18: =Fábrica!F18*'Mark Up '!$B$3 -> 8436.12 | G18: =Fábrica!G18*'Mark Up '!$B$4 -> 8990.52
B19: 10504-3 | C19: Aparador Bruxelas (tp oblongo), pés metal (se laca brilho somente c/ VD) | D19: 1,80 x 0,45 x 0,76 | E19: =Fábrica!E19*'Mark Up '!$B$2 -> 8630.16 | F19: =Fábrica!F19*'Mark Up '!$B$3 -> 8879.64 | G19: =Fábrica!G19*'Mark Up '!$B$4 -> 9577.26
B20: 10504-4 | C20: Aparador Bruxelas (tp oblongo), pés metal (se laca brilho somente c/ VD) | D20: 2,00 x 0,45 x 0,76 | E20: =Fábrica!E20*'Mark Up '!$B$2 -> 8972.04 | F20: =Fábrica!F20*'Mark Up '!$B$3 -> 9526.44 | G20: =Fábrica!G20*'Mark Up '!$B$4 -> 10713.78
A21: GRANADA | B21: 11034-1 | C21: Aparador Granada (tp oblongo), pés mad. (se laca brilho somente c/ VD) | D21: 1,46 x 0,45 x 0,76 | E21: =Fábrica!E21*'Mark Up '!$B$2 -> 6842.22 | F21: =Fábrica!F21*'Mark Up '!$B$3 -> 7304.22 | G21: =Fábrica!G21*'Mark Up '!$B$4 -> 8468.46
B22: 11034-2 | C22: Aparador Granada (tp oblongo), pés mad. (se laca brilho somente c/ VD) | D22: 1,66 x 0,45 x 0,76 | E22: =Fábrica!E22*'Mark Up '!$B$2 -> 7355.04 | F22: =Fábrica!F22*'Mark Up '!$B$3 -> 7890.96 | G22: =Fábrica!G22*'Mark Up '!$B$4 -> 9041.34
B23: 11034-3 | C23: Aparador Granada (tp oblongo), pés mad. (se laca brilho somente c/ VD) | D23: 1,86 x 0,45 x 0,76 | E23: =Fábrica!E23*'Mark Up '!$B$2 -> 7669.2 | F23: =Fábrica!F23*'Mark Up '!$B$3 -> 8283.66 | G23: =Fábrica!G23*'Mark Up '!$B$4 -> 9577.26
B24: 11034-4 | C24: Aparador Granada (tp oblongo), pés mad. (se laca brilho somente c/ VD) | D24: 2,06 x 0,45 x 0,76 | E24: =Fábrica!E24*'Mark Up '!$B$2 -> 8339.1 | F24: =Fábrica!F24*'Mark Up '!$B$3 -> 9022.86 | G24: =Fábrica!G24*'Mark Up '!$B$4 -> 10422.72
A25: MADAGASCAR | B25: 10484-1 | C25: Aparador Madagascar (tp oblongo), pés metal; (com tampo sobreposto) | D25: 1,40 x 0,41 x 0,76 | E25: =Fábrica!E25*'Mark Up '!$B$2 -> 7720.02 | F25: =Fábrica!F25*'Mark Up '!$B$3 -> 8154.3 | G25: =Fábrica!G25*'Mark Up '!$B$4 -> 9087.54
B26: 10484-2 | C26: Aparador Madagascar (tp oblongo), pés metal; (com tampo sobreposto) | D26: 1,60 x 0,41 x 0,76 | E26: =Fábrica!E26*'Mark Up '!$B$2 -> 8255.94 | F26: =Fábrica!F26*'Mark Up '!$B$3 -> 9290.82 | G26: =Fábrica!G26*'Mark Up '!$B$4 -> 9872.94
B27: 10484-3 | C27: Aparador Madagascar (tp oblongo), pés metal; (com tampo sobreposto) | D27: 1,80 x 0,41 x 0,76 | E27: =Fábrica!E27*'Mark Up '!$B$2 -> 8676.36 | F27: =Fábrica!F27*'Mark Up '!$B$3 -> 9817.5 | G27: =Fábrica!G27*'Mark Up '!$B$4 -> 10334.94
B28: 10484-4 | C28: Aparador Madagascar (tp oblongo), pés metal; (com tampo sobreposto) | D28: 2,00 x 0,41 x 0,76 | E28: =Fábrica!E28*'Mark Up '!$B$2 -> 8985.9 | F28: =Fábrica!F28*'Mark Up '!$B$3 -> 10205.58 | G28: =Fábrica!G28*'Mark Up '!$B$4 -> 10750.74
A29: MARACATU | B29: 11294-1 | C29: Aparador Maracatu, c/ 2 gavetas (se laca brilho somente c/ VD) | D29: 1,51 x 0,46 x 0,78 | E29: =Fábrica!E29*'Mark Up '!$B$2 -> 11988.9 | F29: =Fábrica!F29*'Mark Up '!$B$3 -> 13069.98 | G29: =Fábrica!G29*'Mark Up '!$B$4 -> 15370.74
B30: 11294-2 | C30: Aparador Maracatu, c/ 2 gavetas (se laca brilho somente c/ VD) | D30: 1,71 x 0,46 x 0,78 | E30: =Fábrica!E30*'Mark Up '!$B$2 -> 13314.84 | F30: =Fábrica!F30*'Mark Up '!$B$3 -> 14469.84 | G30: =Fábrica!G30*'Mark Up '!$B$4 -> 17107.86
B31: 11294-3 | C31: Aparador Maracatu, c/ 2 gavetas (se laca brilho somente c/ VD) | D31: 1,91 x 0,46 x 0,78 | E31: =Fábrica!E31*'Mark Up '!$B$2 -> 14936.46 | F31: =Fábrica!F31*'Mark Up '!$B$3 -> 16096.08 | G31: =Fábrica!G31*'Mark Up '!$B$4 -> 18641.7
B32: 11294-4 | C32: Aparador Maracatu, c/ 2 gavetas (se laca brilho somente c/ VD) | D32: 2,11 x 0,46 x 0,78 | E32: =Fábrica!E32*'Mark Up '!$B$2 -> 15550.92 | F32: =Fábrica!F32*'Mark Up '!$B$3 -> 16987.74 | G32: =Fábrica!G32*'Mark Up '!$B$4 -> 20115.48
A33: PALERMO | B33: 10634-1 | C33: Aparador Palermo (tp oblongo, c/ 3 gav.) pés metal (se laca brilho somente c/ VD) | D33: 1,41 x 0,46 x 0,77 | E33: =Fábrica!E33*'Mark Up '!$B$2 -> 11129.58 | F33: =Fábrica!F33*'Mark Up '!$B$3 -> 12681.9 | G33: =Fábrica!G33*'Mark Up '!$B$4 -> 14271.18
B34: 10634-2 | C34: Aparador Palermo (tp oblongo, c/ 3 gav.) pés metal (se laca brilho somente c/ VD) | D34: 1,61 x 0,46 x 0,77 | E34: =Fábrica!E34*'Mark Up '!$B$2 -> 11563.86 | F34: =Fábrica!F34*'Mark Up '!$B$3 -> 13079.22 | G34: =Fábrica!G34*'Mark Up '!$B$4 -> 14853.3
B35: 10634-3 | C35: Aparador Palermo (tp oblongo, c/ 3 gav.) pés metal (se laca brilho somente c/ VD) | D35: 1,81 x 0,46 x 0,77 | E35: =Fábrica!E35*'Mark Up '!$B$2 -> 12187.56 | F35: =Fábrica!F35*'Mark Up '!$B$3 -> 13892.34 | G35: =Fábrica!G35*'Mark Up '!$B$4 -> 15883.56
B36: 10634-4 | C36: Aparador Palermo (tp oblongo, c/ 3 gav.) pés metal (se laca brilho somente c/ VD) | D36: 2,01 x 0,46 x 0,77 | E36: =Fábrica!E36*'Mark Up '!$B$2 -> 12986.82 | F36: =Fábrica!F36*'Mark Up '!$B$3 -> 14576.1 | G36: =Fábrica!G36*'Mark Up '!$B$4 -> 16932.3
A37: PRINCETON | B37: 10644-1 | C37: Aparador Princeton ( c/ 3 gavetas), pés metal | D37: 1,40 x 0,45 x 0,76 | E37: =Fábrica!E37*'Mark Up '!$B$2 -> 10967.88 | F37: =Fábrica!F37*'Mark Up '!$B$3 -> 12058.2 | G37: =Fábrica!G37*'Mark Up '!$B$4 -> 13296.36
B38: 10644-2 | C38: Aparador Princeton ( c/ 3 gavetas), pés metal | D38: 1,60 x 0,45 x 0,76 | E38: =Fábrica!E38*'Mark Up '!$B$2 -> 11757.9 | F38: =Fábrica!F38*'Mark Up '!$B$3 -> 12996.06 | G38: =Fábrica!G38*'Mark Up '!$B$4 -> 14363.58
B39: 10644-3 | C39: Aparador Princeton ( c/ 3 gavetas), pés metal | D39: 1,80 x 0,45 x 0,76 | E39: =Fábrica!E39*'Mark Up '!$B$2 -> 12534.06 | F39: =Fábrica!F39*'Mark Up '!$B$3 -> 13998.6 | G39: =Fábrica!G39*'Mark Up '!$B$4 -> 15513.96
B40: 10644-4 | C40: Aparador Princeton ( c/ 3 gavetas), pés metal | D40: 2,00 x 0,45 x 0,76 | E40: =Fábrica!E40*'Mark Up '!$B$2 -> 13273.26 | F40: =Fábrica!F40*'Mark Up '!$B$3 -> 14913.36 | G40: =Fábrica!G40*'Mark Up '!$B$4 -> 16525.74
C41: BUFFET - LANÇAMENTOS
...

Sheet Fábrica
A1: LANÇAMENTOS 2023
A2: 09 de Janeiro de 2023
C3: APARADORES - LANÇAMENTOS
A4: *Qualquer móvel com ou sem vidro comum pintado e colado no tampo permanecerá o mesmo valor;
A5: *Informar no pedido quando for com ou sem vidro;
E6: COLUNA 1 | F6: COLUNA 2 | G6: COLUNA 3
A7: COLEÇÃO | B7: REF | C7: DESCRIÇÃO | D7: COMP X PROF X ALT | E7: TODO LACA PADRÃO | F7: TODO: - AMÊNDOA - CARVALHO - IMBUIA | G7: TODO NOGUEIRA OU TODO LOURO FREIJÓ E BASE METAL EM LACA PADRÃO
F8: TAMPO: - LACA PADRÃO - AMÊNDOA - IMBUIA - CARVALHO C/ BASE: - AMÊNDOA - IMBUIA - CARVALHO - LOURO FREIJÓ - NOGUEIRA - LACA METALIZADA PADRÃO
G9: CARVALHO N 109 METALIZADO CARVALHO ÔNIX METALIZADO
G10: CONCRETO
G11: TODO METALIZADO: - BRONZE - CHUMBO - NEW GOLDEN - ÔNIX METALIZADO - N 109 METALIZADO
A13: BADEN | B13: 10984-1 | C13: Aparador Baden ,tp e bandeja canto garrafa, pés metal (se laca brilho somente c/ VD) | D13: 1,40 x 0,40 x 0,76 | E13: 2014 | F13: 2083 | G13: 2409
B14: 10984-2 | C14: Aparador Baden ,tp e bandeja canto garrafa, pés metal (se laca brilho somente c/ VD) | D14: 1,60 x 0,40 x 0,76 | E14: 2068 | F14: 2163 | G14: 2532
B15: 10984-3 | C15: Aparador Baden ,tp e bandeja canto garrafa, pés metal (se laca brilho somente c/ VD) | D15: 1,80 x 0,40 x 0,76 | E15: 2238 | F15: 2314 | G15: 2722
B16: 10984-4 | C16: Aparador Baden ,tp e bandeja canto garrafa, pés metal (se laca brilho somente c/ VD) | D16: 2,00 x 0,40 x 0,76 | E16: 2373 | F16: 2485 | G16: 2935
A17: BRUXELAS | B17: 10504-1 | C17: Aparador Bruxelas (tp oblongo), pés metal (se laca brilho somente c/ VD) | D17: 1,35 x 0,45 x 0,76 | E17: 1694 | F17: 1726 | G17: 1842
B18: 10504-2 | C18: Aparador Bruxelas (tp oblongo), pés metal (se laca brilho somente c/ VD) | D18: 1,60 x 0,45 x 0,76 | E18: 1768 | F18: 1826 | G18: 1946
B19: 10504-3 | C19: Aparador Bruxelas (tp oblongo), pés metal (se laca brilho somente c/ VD) | D19: 1,80 x 0,45 x 0,76 | E19: 1868 | F19: 1922 | G19: 2073
B20: 10504-4 | C20: Aparador Bruxelas (tp oblongo), pés metal (se laca brilho somente c/ VD) | D20: 2,00 x 0,45 x 0,76 | E20: 1942 | F20: 2062 | G20: 2319
A21: GRANADA | B21: 11034-1 | C21: Aparador Granada (tp oblongo), pés mad. (se laca brilho somente c/ VD) | D21: 1,46 x 0,45 x 0,76 | E21: 1481 | F21: 1581 | G21: 1833
B22: 11034-2 | C22: Aparador Granada (tp oblongo), pés mad. (se laca brilho somente c/ VD) | D22: 1,66 x 0,45 x 0,76 | E22: 1592 | F22: 1708 | G22: 1957
B23: 11034-3 | C23: Aparador Granada (tp oblongo), pés mad. (se laca brilho somente c/ VD) | D23: 1,86 x 0,45 x 0,76 | E23: 1660 | F23: 1793 | G23: 2073
B24: 11034-4 | C24: Aparador Granada (tp oblongo), pés mad. (se laca brilho somente c/ VD) | D24: 2,06 x 0,45 x 0,76 | E24: 1805 | F24: 1953 | G24: 2256
A25: MADAGASCAR | B25: 10484-1 | C25: Aparador Madagascar (tp oblongo), pés metal; (com tampo sobreposto) | D25: 1,40 x 0,41 x 0,76 | E25: 1671 | F25: 1765 | G25: 1967
B26: 10484-2 | C26: Aparador Madagascar (tp oblongo), pés metal; (com tampo sobreposto) | D26: 1,60 x 0,41 x 0,76 | E26: 1787 | F26: 2011 | G26: 2137
B27: 10484-3 | C27: Aparador Madagascar (tp oblongo), pés metal; (com tampo sobreposto) | D27: 1,80 x 0,41 x 0,76 | E27: 1878 | F27: 2125 | G27: 2237
B28: 10484-4 | C28: Aparador Madagascar (tp oblongo), pés metal; (com tampo sobreposto) | D28: 2,00 x 0,41 x 0,76 | E28: 1945 | F28: 2209 | G28: 2327
A29: MARACATU | B29: 11294-1 | C29: Aparador Maracatu, c/ 3 gavetas (se laca brilho somente c/ VD) | D29: 1,51 x 0,46 x 0,78 | E29: 2595 | F29: 2829 | G29: 3327
B30: 11294-2 | C30: Aparador Maracatu, c/ 3 gavetas (se laca brilho somente c/ VD) | D30: 1,71 x 0,46 x 0,78 | E30: 2882 | F30: 3132 | G30: 3703
B31: 11294-3 | C31: Aparador Maracatu, c/ 3 gavetas (se laca brilho somente c/ VD) | D31: 1,91 x 0,46 x 0,78 | E31: 3233 | F31: 3484 | G31: 4035
B32: 11294-4 | C32: Aparador Maracatu, c/ 3 gavetas (se laca brilho somente c/ VD) | D32: 2,11 x 0,46 x 0,78 | E32: 3366 | F32: 3677 | G32: 4354
A33: PALERMO | B33: 10634-1 | C33: Aparador Palermo (tp oblongo, c/ 3 gav.) pés metal (se laca brilho somente c/ VD) | D33: 1,41 x 0,46 x 0,77 | E33: 2409 | F33: 2745 | G33: 3089
B34: 10634-2 | C34: Aparador Palermo (tp oblongo, c/ 3 gav.) pés metal (se laca brilho somente c/ VD) | D34: 1,61 x 0,46 x 0,77 | E34: 2503 | F34: 2831 | G34: 3215
B35: 10634-3 | C35: Aparador Palermo (tp oblongo, c/ 3 gav.) pés metal (se laca brilho somente c/ VD) | D35: 1,81 x 0,46 x 0,77 | E35: 2638 | F35: 3007 | G35: 3438
B36: 10634-4 | C36: Aparador Palermo (tp oblongo, c/ 3 gav.) pés metal (se laca brilho somente c/ VD) | D36: 2,01 x 0,46 x 0,77 | E36: 2811 | F36: 3155 | G36: 3665
A37: PRINCETON | B37: 10644-1 | C37: Aparador Princeton ( c/ 3 gavetas), pés metal | D37: 1,40 x 0,45 x 0,76 | E37: 2374 | F37: 2610 | G37: 2878
B38: 10644-2 | C38: Aparador Princeton ( c/ 3 gavetas), pés metal | D38: 1,60 x 0,45 x 0,76 | E38: 2545 | F38: 2813 | G38: 3109
B39: 10644-3 | C39: Aparador Princeton ( c/ 3 gavetas), pés metal | D39: 1,80 x 0,45 x 0,76 | E39: 2713 | F39: 3030 | G39: 3358
B40: 10644-4 | C40: Aparador Princeton ( c/ 3 gavetas), pés metal | D40: 2,00 x 0,45 x 0,76 | E40: 2873 | F40: 3228 | G40: 3577
C41: BUFFET - LANÇAMENTOS
...
