Workbook

Sheet Inf. Gerais

Sheet Fernando.Motta
A5: TABELA 06/2022 - LINHA FERNANDO MOTTA | J5: 0.08
F6: 4.42
A7: BANCO LINN | B7: SUPREMA NOG/CAST/PTO | C7: BANCO
C8: LINN
A9: TECIDO | B9: MEDIDA (LxPxA): 160 X 50 x 48
A10: LINHA 400 | B10: =I10*$F$6 -> 12482.08 | H10: LINHA 400 | I10: 2824 | N10: LINHA 400 | O10: 2615
A11: LINHA 600 | B11: =I11*$F$6 -> 12623.52 | H11: LINHA 600 | I11: 2856 | N11: LINHA 600 | O11: 2644
A12: LINHA 800 | B12: =I12*$F$6 -> 12760.54 | H12: LINHA 800 | I12: 2887 | N12: LINHA 800 | O12: 2673
A13: LINHA 1000 | B13: =I13*$F$6 -> 12906.4 | H13: LINHA 1000 | I13: 2920 | N13: LINHA 1000 | O13: 2704
A14: LINHA 1500 | B14: =I14*$F$6 -> 13043.42 | H14: LINHA 1500 | I14: 2951 | N14: LINHA 1500 | O14: 2732
A15: LINHA 2000 | B15: =I15*$F$6 -> 13184.86 | H15: LINHA 2000 | I15: 2983 | N15: LINHA 2000 | O15: 2762
A16: COURO NATURAL | B16: =I16*$F$6 -> 15425.8 | H16: COURO NATURAL | I16: 3490 | N16: COURO NATURAL | O16: 5269
A17: TECIDO | B17: MEDIDA (LxPxA): 180 X 50 x 48 | O17: 180
A18: LINHA 400 | B18: =I18*$F$6 -> 12689.82 | H18: LINHA 400 | I18: 2871 | N18: LINHA 400 | O18: 2658
A19: LINHA 600 | B19: =I19*$F$6 -> 12844.52 | H19: LINHA 600 | I19: 2906 | N19: LINHA 600 | O19: 2691
A20: LINHA 800 | B20: =I20*$F$6 -> 13008.06 | H20: LINHA 800 | I20: 2943 | N20: LINHA 800 | O20: 2725
A21: LINHA 1000 | B21: =I21*$F$6 -> 13180.44 | H21: LINHA 1000 | I21: 2982 | N21: LINHA 1000 | O21: 2761
A22: LINHA 1500 | B22: =I22*$F$6 -> 13330.72 | H22: LINHA 1500 | I22: 3016 | N22: LINHA 1500 | O22: 2793
A23: LINHA 2000 | B23: =I23*$F$6 -> 13494.26 | H23: LINHA 2000 | I23: 3053 | N23: LINHA 2000 | O23: 2827
A24: COURO NATURAL | B24: =I24*$F$6 -> 16641.3 | H24: COURO NATURAL | I24: 3765 | N24: COURO NATURAL | O24: 5562
A25: TECIDO | B25: MEDIDA (LxPxA): 200 X 50 x 48 | O25: 200
A26: LINHA 400 | B26: =I26*$F$6 -> 13211.38 | H26: LINHA 400 | I26: 2989 | N26: LINHA 400 | O26: 2768
A27: LINHA 600 | B27: =I27*$F$6 -> 13405.86 | H27: LINHA 600 | I27: 3033 | N27: LINHA 600 | O27: 2808
A28: LINHA 800 | B28: =I28*$F$6 -> 13587.08 | H28: LINHA 800 | I28: 3074 | N28: LINHA 800 | O28: 2846
A29: LINHA 1000 | B29: =I29*$F$6 -> 13772.72 | H29: LINHA 1000 | I29: 3116 | N29: LINHA 1000 | O29: 2885
A30: LINHA 1500 | B30: =I30*$F$6 -> 13953.94 | H30: LINHA 1500 | I30: 3157 | N30: LINHA 1500 | O30: 2923
A31: LINHA 2000 | B31: =I31*$F$6 -> 14152.84 | H31: LINHA 2000 | I31: 3202 | N31: LINHA 2000 | O31: 2965
A32: COURO NATURAL | B32: =I32*$F$6 -> 18241.34 | H32: COURO NATURAL | I32: 4127 | N32: COURO NATURAL | O32: 6089
A33: TECIDO | B33: MEDIDA (LxPxA): 220 X 50 x 48 | O33: 220
A34: LINHA 400 | B34: =I34*$F$6 -> 13419.12 | H34: LINHA 400 | I34: 3036 | N34: LINHA 400 | O34: 2811
A35: LINHA 600 | B35: =I35*$F$6 -> 13816.92 | H35: LINHA 600 | I35: 3126 | N35: LINHA 600 | O35: 2894
A36: LINHA 800 | B36: =I36*$F$6 -> 14024.66 | H36: LINHA 800 | I36: 3173 | N36: LINHA 800 | O36: 2938
A37: LINHA 1000 | B37: =I37*$F$6 -> 14223.56 | H37: LINHA 1000 | I37: 3218 | N37: LINHA 1000 | O37: 2980
A38: LINHA 1500 | B38: =I38*$F$6 -> 14440.14 | H38: LINHA 1500 | I38: 3267 | N38: LINHA 1500 | O38: 3025
A39: LINHA 2000 | B39: =I39*$F$6 -> 14652.3 | H39: LINHA 2000 | I39: 3315 | N39: LINHA 2000 | O39: 3069
A40: COURO NATURAL | B40: =I40*$F$6 -> 19474.52 | H40: COURO NATURAL | I40: 4406 | N40: COURO NATURAL | O40: 6586
A42: MESA LINN | B42: OPÇÃO TAMPO | C42: PÉ | D42: MESA
C43: SUPREMA NOGUEIRA/ CAST. OU PRETO | D43: LINN | I43: SUPREMA NOG/CAST/PTO | O43: SUPREMA NOG/CAST/PTO
A44: MEDIDA (LxPxA):
A45: 180X100X76 | B45: WALNUT SEM VIDRO | C45: =I45*$F$6 -> 22157.46 | H45: 180X100X76 | I45: 5013 | N45: 180X100X76 | O45: 4642
...

Sheet Luia.Mantelli
A5: TABELA 06/2022 - LINHA LUIA MANTELLI
A7: POLTRONA IDEM | B7: LOURO FREIJO NATURAL OU EBANIZADO | C7: A- 74 P-63 L-76
A8: ARES | C8: POLTRONA
A9: TECIDO | C9: IDEM
A10: LINHA 400 | B10: =J10*Fernando.Motta!$F$6 -> 5083 | I10: LINHA 400 | J10: 1150
E11: Opção de Acabamento Natural ou Preto, com ampla variedade de revestimentos. Acompanha almofadas revestidas no tecido do assento. Assento e encosto no mesmo revestimento.
A13: LINHA 600 | B13: =J13*Fernando.Motta!$F$6 -> 5268.64 | I13: linha 600 | J13: 1192
A16: LINHA 800 | B16: =J16*Fernando.Motta!$F$6 -> 5595.72 | I16: LINHA 800 | J16: 1266
A19: LINHA 1000 | B19: =J19*Fernando.Motta!$F$6 -> 5706.22 | I19: LINHA 1000 | J19: 1291
A22: LINHA 1500 | B22: =J22*Fernando.Motta!$F$6 -> 6112.86 | I22: LINHA 1500 | J22: 1383
A25: LINHA 2000 | B25: =J25*Fernando.Motta!$F$6 -> 6696.3 | I25: LINHA 2000 | J25: 1515
A28: COURO NATURAL | B28: =J28*Fernando.Motta!$F$6 -> 11337.3 | I28: COURO NATURAL | J28: 2565
A32: BANQUETA IDEM | B32: LOURO FREIJO NATURAL OU EBANIZADO | C32: A- 87 P-47 L-49
A33: ARES | C33: BANQUETA
A34: TECIDO | C34: IDEM
A35: LINHA 400 | B35: =J35*Fernando.Motta!$F$6 -> 3597.88 | I35: LINHA 400 | J35: 814
E36: Opção de Acabamento Natural ou Preto, com ampla variedade de revestimentos.
A38: LINHA 600 | B38: =J38*Fernando.Motta!$F$6 -> 3664.18 | I38: LINHA 600 | J38: 829
A41: LINHA 800 | B41: =J41*Fernando.Motta!$F$6 -> 3779.1 | I41: LINHA 800 | J41: 855
A44: LINHA 1000 | B44: =J44*Fernando.Motta!$F$6 -> 3818.88 | I44: LINHA 1000 | J44: 864
A47: LINHA 1500 | B47: =J47*Fernando.Motta!$F$6 -> 3960.32 | I47: LINHA 1500 | J47: 896
A50: LINHA 2000 | B50: =J50*Fernando.Motta!$F$6 -> 4168.06 | I50: LINHA 2000 | J50: 943
A53: COURO NATURAL | B53: =J53*Fernando.Motta!$F$6 -> 6510.66 | I53: COURO NATURAL | J53: 1473
B57: MESA X | C57: LOURO FREIJO | D57: 1800 x 1000 x H 750 | E57: =I57*Fernando.Motta!$F$6 -> 16278.86 | F57: Pés em madeira maciça e tampo em MDF revestido em lâmina Louro Freijó. Opção de Acabamento Natural ou Preto. Detalhe e fixação dos pés em Latão polido com proteção em verniz. | I57: 3683
D58: 2000 x 1100 x H 750 | E58: =I58*Fernando.Motta!$F$6 -> 17728.62 | I58: 4011
D59: 2200 x 1100 x H 750 | E59: =I59*Fernando.Motta!$F$6 -> 18325.32 | I59: 4146
D60: 2400 x 1100 x H 750 | E60: =I60*Fernando.Motta!$F$6 -> 18992.74 | I60: 4297
D61: 2600 x 1150 x H 750 | E61: =I61*Fernando.Motta!$F$6 -> 19611.54 | I61: 4437
D62: 2800 x 1200 x H 750 | E62: =I62*Fernando.Motta!$F$6 -> 24738.74 | I62: 5597
D63: 3000 x 1200 x H 750 | E63: =I63*Fernando.Motta!$F$6 -> 25733.24 | I63: 5822
B65: MESA REDONDA TRAMA | C65: LOURO FREIJO | D65: Ø 1100 x H 750 | E65: =I65*Fernando.Motta!$F$6 -> 13511.94 | F65: Pés em madeira maciça e tampo em MDF revestido em lâmina Louro Freijó. Opção de Acabamento Natural ou Preto. | I65: 3057
D66: Ø 1200 X H 750 | E66: =I66*Fernando.Motta!$F$6 -> 14378.26 | I66: 3253
D67: Ø 1400 X H 750 | E67: =I67*Fernando.Motta!$F$6 -> 16345.16 | I67: 3698
D68: Ø 1600 X H 750 | E68: =I68*Fernando.Motta!$F$6 -> 19262.36 | I68: 4358
D69: Ø 1800 X H 750 | E69: =I69*Fernando.Motta!$F$6 -> 21865.74 | I69: 4947
B71: APARADOR X | C71: LOURO FREIJO | D71: 1800 x 480 x H 750 | E71: =I71*Fernando.Motta!$F$6 -> 21180.64 | F71: Pés em madeira maciça e caixa em MDF revestido em lâmina Louro Freijó. Opção de Acabamento Natural ou Preto. Puxador, detalhe e fixação dos pés em Latão polido com proteção em verniz. | I71: 4792
D72: 2000 x 480 x H 750 | E72: =I72*Fernando.Motta!$F$6 -> 22776.26 | I72: 5153
D73: 2200 x 480 x H 750 | E73: =I73*Fernando.Motta!$F$6 -> 24212.76 | I73: 5478
D74: 2400 x 480 x H 750 | E74: =I74*Fernando.Motta!$F$6 -> 25534.34 | I74: 5777
D75: 2600 x 480 x H 750 | E75: =I75*Fernando.Motta!$F$6 -> 27015.04 | I75: 6112
...

Sheet Daniel.Kroth
A5: TABELA 06/2022 - LINHA DANIEL KROTH
A6: POLTRONA BRISE | B6: SUPREMA NOG/CAST/PTO | C6: LACA FOSCA | D6: LACA BRILHO OU MET./ SUP NAT OU ROSE NAT | E6: A-79 P-80 L-65
E7: POLTRONA
A8: TECIDO | E8: BRISE
A9: LINHA 400 | B9: =J9*Fernando.Motta!$F$6 -> 5418.92 | C9: =K9*Fernando.Motta!$F$6 -> 8367.06 | D9: =L9*Fernando.Motta!$F$6 -> 10245.56 | I9: LINHA 400 | J9: 1226 | K9: 1893 | L9: 2318 | P9: 1026 | Q9: 1502 | R9: 1795
B10: #REF! | C10: #REF! | D10: #REF!
B11: #REF! | C11: #REF! | D11: #REF!
A12: LINHA 600 | B12: =J12*Fernando.Motta!$F$6 -> 5538.26 | C12: =K12*Fernando.Motta!$F$6 -> 8486.4 | D12: =L12*Fernando.Motta!$F$6 -> 10369.32 | I12: LINHA 600 | J12: 1253 | K12: 1920 | L12: 2346 | P12: 1072 | Q12: 1537 | R12: 1829
B13: #REF! | C13: #REF! | D13: #REF!
B14: #REF! | C14: #REF! | D14: #REF!
A15: LINHA 800 | B15: =J15*Fernando.Motta!$F$6 -> 5754.84 | C15: =K15*Fernando.Motta!$F$6 -> 8702.98 | D15: =L15*Fernando.Motta!$F$6 -> 10585.9 | I15: LINHA 800 | J15: 1302 | K15: 1969 | L15: 2395 | P15: 1128 | Q15: 1569 | R15: 1863
B16: #REF! | C16: #REF! | D16: #REF!
B17: #REF! | C17: #REF! | D17: #REF!
A18: LINHA 1000 | B18: =J18*Fernando.Motta!$F$6 -> 5825.56 | C18: =K18*Fernando.Motta!$F$6 -> 8778.12 | D18: =L18*Fernando.Motta!$F$6 -> 10656.62 | I18: LINHA 1000 | J18: 1318 | K18: 1986 | L18: 2411 | P18: 1183 | Q18: 1617 | R18: 1896
B19: #REF! | C19: #REF! | D19: #REF!
B20: #REF! | C20: #REF! | D20: #REF!
A21: LINHA 1500 | B21: =J21*Fernando.Motta!$F$6 -> 6090.76 | C21: =K21*Fernando.Motta!$F$6 -> 9043.32 | D21: =L21*Fernando.Motta!$F$6 -> 10921.82 | I21: LINHA 1500 | J21: 1378 | K21: 2046 | L21: 2471 | P21: 1238 | Q21: 1672 | R21: 1930
B22: #REF! | C22: #REF! | D22: #REF!
B23: #REF! | C23: #REF! | D23: #REF!
A24: LINHA 2000 | B24: =J24*Fernando.Motta!$F$6 -> 6479.72 | C24: =K24*Fernando.Motta!$F$6 -> 9427.86 | D24: =L24*Fernando.Motta!$F$6 -> 11306.36 | I24: LINHA 2000 | J24: 1466 | K24: 2133 | L24: 2558 | P24: 1294 | Q24: 1728 | R24: 1980
B25: #REF! | C25: #REF! | D25: #REF!
B26: #REF! | C26: #REF! | D26: #REF!
A27: COURO NATURAL | B27: =J27*Fernando.Motta!$F$6 -> 13193.7 | C27: =K27*Fernando.Motta!$F$6 -> 16062.28 | D27: =L27*Fernando.Motta!$F$6 -> 17940.78 | I27: COURO NATURAL | J27: 2985 | K27: 3634 | L27: 4059 | P27: 3956 | Q27: 4432 | R27: 4950
B28: #REF! | C28: #REF! | D28: #REF!
B29: #REF! | C29: #REF! | D29: #REF!
A31: BANCO BRISE | B31: SUPREMA NOG/CAST/PTO | C31: SUPREMA NAT/ROSE NAT | E31: A-42 P-45 L-65
E32: BANCO
A33: TECIDO | E33: BRISE
A34: LINHA 400 | B34: =J34*Fernando.Motta!$F$6 -> 2594.54 | C34: =K34*Fernando.Motta!$F$6 -> 2903.94 | I34: LINHA 400 | J34: 587 | K34: 657 | P34: 502 | Q34: 562
B35: #REF! | C35: #REF!
B36: #REF! | C36: #REF!
A37: LINHA 600 | B37: =J37*Fernando.Motta!$F$6 -> 2638.74 | C37: =K37*Fernando.Motta!$F$6 -> 2956.98 | I37: LINHA 600 | J37: 597 | K37: 669 | P37: 514 | Q37: 575
B38: #REF! | C38: #REF!
B39: #REF! | C39: #REF!
A40: LINHA 800 | B40: =J40*Fernando.Motta!$F$6 -> 2713.88 | C40: =K40*Fernando.Motta!$F$6 -> 3040.96 | I40: LINHA 800 | J40: 614 | K40: 688 | P40: 524 | Q40: 587
B41: #REF! | C41: #REF!
B42: #REF! | C42: #REF!
A43: LINHA 1000 | B43: =J43*Fernando.Motta!$F$6 -> 2740.4 | C43: =K43*Fernando.Motta!$F$6 -> 3067.48 | I43: LINHA 1000 | J43: 620 | K43: 694 | P43: 536 | Q43: 643
B44: #REF! | C44: #REF!
B45: #REF! | C45: #REF!
...

Sheet Fabricio.Ronca
A7: TABELA 06/2022 - LINHA FABRICIO RONCCA
A8: POLTRONA SILLA | B8: SUPREMA NOG/CAST/PTO | C8: LACA FOSCA | D8: LACA BRILHO OU METALIZADO/ SUP NAT OU ROSE NAT | E8: A- 74 P- 71 L- 85
E9: POLTRONA
A10: TECIDO | E10: SILLA
A11: LINHA 400 | B11: =J11*Fernando.Motta!$F$6 -> 8605.74 | C11: =K11*Fernando.Motta!$F$6 -> 11514.1 | D11: =L11*Fernando.Motta!$F$6 -> 14029.08 | I11: LINHA 400 | J11: 1947 | K11: 2605 | L11: 3174
B12: #REF! | C12: #REF! | D12: #REF!
B13: #REF! | C13: #REF! | D13: #REF! | E13: ROLINHO:
A14: LINHA 600 | B14: =J14*Fernando.Motta!$F$6 -> 8725.08 | C14: =K14*Fernando.Motta!$F$6 -> 11633.44 | D14: =L14*Fernando.Motta!$F$6 -> 14148.42 | E14: QUALQUER TECIDO/COURO EM LINHA | I14: LINHA 600 | J14: 1974 | K14: 2632 | L14: 3201
B15: #REF! | C15: #REF! | D15: #REF!
B16: #REF! | C16: #REF! | D16: #REF! | E16: DETALHE:
A17: LINHA 800 | B17: =J17*Fernando.Motta!$F$6 -> 8937.24 | C17: =K17*Fernando.Motta!$F$6 -> 11845.6 | D17: =L17*Fernando.Motta!$F$6 -> 14360.58 | E17: LACA FOSCA/ LACA BRILHO OU METALIZADA | I17: LINHA 800 | J17: 2022 | K17: 2680 | L17: 3249
B18: #REF! | C18: #REF! | D18: #REF!
B19: #REF! | C19: #REF! | D19: #REF!
A20: LINHA 1000 | B20: =J20*Fernando.Motta!$F$6 -> 9007.96 | C20: =K20*Fernando.Motta!$F$6 -> 11916.32 | D20: =L20*Fernando.Motta!$F$6 -> 14435.72 | I20: LINHA 1000 | J20: 2038 | K20: 2696 | L20: 3266
B21: #REF! | C21: #REF! | D21: #REF!
B22: #REF! | C22: #REF! | D22: #REF!
A23: LINHA 1500 | B23: =J23*Fernando.Motta!$F$6 -> 9268.74 | C23: =K23*Fernando.Motta!$F$6 -> 12177.1 | D23: =L23*Fernando.Motta!$F$6 -> 14692.08 | I23: LINHA 1500 | J23: 2097 | K23: 2755 | L23: 3324
B24: #REF! | C24: #REF! | D24: #REF!
B25: #REF! | C25: #REF! | D25: #REF!
A26: LINHA 2000 | B26: =J26*Fernando.Motta!$F$6 -> 9648.86 | C26: =K26*Fernando.Motta!$F$6 -> 12557.22 | D26: =L26*Fernando.Motta!$F$6 -> 15072.2 | I26: LINHA 2000 | J26: 2183 | K26: 2841 | L26: 3410
B27: #REF! | C27: #REF! | D27: #REF!
B28: #REF! | C28: #REF! | D28: #REF!
A29: COURO NATURAL | B29: =J29*Fernando.Motta!$F$6 -> 13507.52 | C29: =K29*Fernando.Motta!$F$6 -> 16415.88 | D29: =L29*Fernando.Motta!$F$6 -> 18930.86 | I29: COURO NATURAL | J29: 3056 | K29: 3714 | L29: 4283
B30: #REF! | C30: #REF! | D30: #REF!
B31: #REF! | C31: #REF! | D31: #REF!
A33: BANCO SILLA | B33: TAMPO | I33: BANCO SILLA | J33: TAMPO
B34: CARVALHO NOG/CAST/PTO/NAT/ROSE NAT | C34: WALNUT NATURAL | D34: LACA FOSCA | E34: LACA BRILHO OU METALIZADA | F34: BANCO | J34: CARVALHO NOG/CAST/PTO/NAT/ROSE NAT | K34: WALNUT NATURAL | L34: LACA FOSCA | M34: LACA BRILHO OU METALIZADA/ SUP NAT OU ROSE NAT
F35: SILLA
A36: TECIDO | B36: MEDIDA: | C36: 140X45x56 | I36: TECIDO | J36: MEDIDA: | K36: 140X45x48
A37: LINHA 400 | B37: =J37*Fernando.Motta!$F$6 -> 9264.32 | C37: =K37*Fernando.Motta!$F$6 -> 9653.28 | D37: =L37*Fernando.Motta!$F$6 -> 10979.28 | E37: =M37*Fernando.Motta!$F$6 -> 10820.16 | G37: LINHA 400 | I37: LINHA 400 | J37: 2096 | K37: 2184 | L37: 2484 | M37: 2448
A38: LINHA 600 | B38: =J38*Fernando.Motta!$F$6 -> 9326.2 | C38: =K38*Fernando.Motta!$F$6 -> 9715.16 | D38: =L38*Fernando.Motta!$F$6 -> 11041.16 | E38: =M38*Fernando.Motta!$F$6 -> 10886.46 | F38: PÉ SUPREMA: | I38: LINHA 600 | J38: 2110 | K38: 2198 | L38: 2498 | M38: 2463
A39: LINHA 800 | B39: =J39*Fernando.Motta!$F$6 -> 9441.12 | C39: =K39*Fernando.Motta!$F$6 -> 9830.08 | D39: =L39*Fernando.Motta!$F$6 -> 11156.08 | E39: =M39*Fernando.Motta!$F$6 -> 10996.96 | F39: NOG/CAST/PTO/ | I39: LINHA 800 | J39: 2136 | K39: 2224 | L39: 2524 | M39: 2488
A40: LINHA 1000 | B40: =J40*Fernando.Motta!$F$6 -> 9476.48 | C40: =K40*Fernando.Motta!$F$6 -> 9865.44 | D40: =L40*Fernando.Motta!$F$6 -> 11191.44 | E40: =M40*Fernando.Motta!$F$6 -> 11036.74 | F40: ROSE NAT/NAT | I40: LINHA 1000 | J40: 2144 | K40: 2232 | L40: 2532 | M40: 2497
A41: LINHA 1500 | B41: =J41*Fernando.Motta!$F$6 -> 9613.5 | C41: =K41*Fernando.Motta!$F$6 -> 10002.46 | D41: =L41*Fernando.Motta!$F$6 -> 11332.88 | E41: =M41*Fernando.Motta!$F$6 -> 11173.76 | F41: LINHA 1500 | I41: LINHA 1500 | J41: 2175 | K41: 2263 | L41: 2564 | M41: 2528
A42: LINHA 2000 | B42: =J42*Fernando.Motta!$F$6 -> 9816.82 | C42: =K42*Fernando.Motta!$F$6 -> 10205.78 | D42: =L42*Fernando.Motta!$F$6 -> 11531.78 | E42: =M42*Fernando.Motta!$F$6 -> 11377.08 | F42: DETALHE: | I42: LINHA 2000 | J42: 2221 | K42: 2309 | L42: 2609 | M42: 2574
A43: COURO NATURAL | B43: =J43*Fernando.Motta!$F$6 -> 11858.86 | C43: =K43*Fernando.Motta!$F$6 -> 12247.82 | D43: =L43*Fernando.Motta!$F$6 -> 13573.82 | E43: =M43*Fernando.Motta!$F$6 -> 13414.7 | F43: LATÃO/ LACA FOSCA | I43: COURO NAT | J43: 2683 | K43: 2771 | L43: 3071 | M43: 3035
B44: MEDIDA: | C44: 160X45x56 | F44: LC BRILHO/ METALIZADA
A45: LINHA 400 | B45: =J45*Fernando.Motta!$F$6 -> 9759.36 | C45: =K45*Fernando.Motta!$F$6 -> 10205.78 | D45: =L45*Fernando.Motta!$F$6 -> 11527.36 | E45: =M45*Fernando.Motta!$F$6 -> 11452.22 | I45: LINHA 400 | J45: 2208 | K45: 2309 | L45: 2608 | M45: 2591
A46: LINHA 600 | B46: =J46*Fernando.Motta!$F$6 -> 9830.08 | C46: =K46*Fernando.Motta!$F$6 -> 10272.08 | D46: =L46*Fernando.Motta!$F$6 -> 11593.66 | E46: =M46*Fernando.Motta!$F$6 -> 11518.52 | F46: LINHA 600 | I46: LINHA 600 | J46: 2224 | K46: 2324 | L46: 2623 | M46: 2606
A47: LINHA 800 | B47: =J47*Fernando.Motta!$F$6 -> 9949.42 | C47: =K47*Fernando.Motta!$F$6 -> 10391.42 | D47: =L47*Fernando.Motta!$F$6 -> 11717.42 | E47: =M47*Fernando.Motta!$F$6 -> 11637.86 | I47: LINHA 800 | J47: 2251 | K47: 2351 | L47: 2651 | M47: 2633
...
